Uploading blueprint cloudify/gcp.yaml...
 gcp.yaml |############################################################| 100.0%
Blueprint uploaded. The blueprint's id is cloudify-wordpress-blueprint-gcp
Creating new deployment from blueprint cloudify-wordpress-blueprint-gcp...
Deployment created. The deployment's id is gcp
Executing workflow `install` on deployment `gcp` [timeout=900 seconds]
Deployment environment creation is pending...
2019-08-08 08:17:33.318  CFY <gcp> Starting 'create_deployment_environment' workflow execution
2019-08-08 08:17:33.323  CFY <gcp> Installing deployment and workflow plugins
2019-08-08 08:17:33.423  CFY <gcp> Sending task 'cloudify_agent.operations.install_plugins'
2019-08-08 08:17:33.440  CFY <gcp> Task started 'cloudify_agent.operations.install_plugins'
2019-08-08 08:17:33.799  LOG <gcp> INFO: Installing plugin: gcp_plugin
2019-08-08 08:17:34.969  LOG <gcp> INFO: Using existing installation of managed plugin: e0a99ba4-54d6-4741-a773-4ec378dc8634 [package_name: cloudify-gcp-plugin, package_version: 1.4.4, supported_platform: linux_x86_64, distribution: centos, distribution_release: core]
2019-08-08 08:17:34.969  LOG <gcp> INFO: Installing plugin: ansible
2019-08-08 08:17:36.075  LOG <gcp> INFO: Using existing installation of managed plugin: 7142c593-6e52-429a-8a71-55266c022e02 [package_name: cloudify-ansible-plugin, package_version: 2.4.0, supported_platform: linux_x86_64, distribution: centos, distribution_release: core]
2019-08-08 08:17:36.076  LOG <gcp> INFO: Installing plugin: suspend
2019-08-08 08:17:36.983  LOG <gcp> INFO: Using existing installation of managed plugin: 62c3cd35-5a18-49fd-a670-48f9ad207b05 [package_name: cloudify-utilities-plugin, package_version: 1.14.0, supported_platform: linux_x86_64, distribution: centos, distribution_release: core]
2019-08-08 08:17:36.984  LOG <gcp> INFO: Installing plugin: scalelist
2019-08-08 08:17:37.877  LOG <gcp> INFO: Using existing installation of managed plugin: 62c3cd35-5a18-49fd-a670-48f9ad207b05 [package_name: cloudify-utilities-plugin, package_version: 1.14.0, supported_platform: linux_x86_64, distribution: centos, distribution_release: core]
2019-08-08 08:17:37.877  LOG <gcp> INFO: Installing plugin: configuration
2019-08-08 08:17:38.788  CFY <gcp> Task succeeded 'cloudify_agent.operations.install_plugins'
2019-08-08 08:17:38.788  LOG <gcp> INFO: Using existing installation of managed plugin: 62c3cd35-5a18-49fd-a670-48f9ad207b05 [package_name: cloudify-utilities-plugin, package_version: 1.14.0, supported_platform: linux_x86_64, distribution: centos, distribution_release: core]
2019-08-08 08:17:38.906  CFY <gcp> Creating deployment work directory
2019-08-08 08:17:39.340  CFY <gcp> 'create_deployment_environment' workflow execution succeeded
2019-08-08 08:17:44.578  CFY <gcp> Starting 'install' workflow execution
2019-08-08 08:17:46.304  CFY <gcp> [network_dcefjo] Validating node instance before creation: nothing to do
2019-08-08 08:17:46.408  CFY <gcp> [network_dcefjo] Precreating node instance: nothing to do
2019-08-08 08:17:46.503  CFY <gcp> [network_dcefjo] Creating node instance
2019-08-08 08:17:46.915  CFY <gcp> [network_dcefjo.create] Sending task 'cloudify_gcp.compute.network.create'
2019-08-08 08:17:49.078  LOG <gcp> [network_dcefjo.create] INFO: Create network network-dcefjo
2019-08-08 08:17:51.987  CFY <gcp> [network_dcefjo.create] Task rescheduled 'cloudify_gcp.compute.network.create' -> Operation started
Traceback (most recent call last):
  File "/opt/mgmtworker/env/lib/python2.7/site-packages/cloudify/dispatch.py", line 813, in main
    payload = handler.handle()
  File "/opt/mgmtworker/env/lib/python2.7/site-packages/cloudify/dispatch.py", line 464, in handle
    raise ctx.operation._operation_retry
OperationRetry: Operation started

2019-08-08 08:18:07.138  CFY <gcp> [network_dcefjo.create] Sending task 'cloudify_gcp.compute.network.create' [retry 1/60]
2019-08-08 08:18:10.154  LOG <gcp> [network_dcefjo.create] INFO: Get network network-dcefjo details
2019-08-08 08:18:11.807  CFY <gcp> [network_dcefjo.create] Task succeeded 'cloudify_gcp.compute.network.create' [retry 1/60]
2019-08-08 08:18:11.918  CFY <gcp> [network_dcefjo] Node instance created
2019-08-08 08:18:12.210  CFY <gcp> [network_dcefjo] Configuring node instance: nothing to do
2019-08-08 08:18:12.300  CFY <gcp> [network_dcefjo] Starting node instance: nothing to do
2019-08-08 08:18:12.420  CFY <gcp> [network_dcefjo] Poststarting node instance: nothing to do
2019-08-08 08:18:12.507  CFY <gcp> [network_dcefjo] Node instance started
2019-08-08 08:18:13.767  CFY <gcp> [firewall_dxpxp3] Validating node instance before creation: nothing to do
2019-08-08 08:18:13.832  CFY <gcp> [subnet_aifa0g] Validating node instance before creation
2019-08-08 08:18:13.993  CFY <gcp> [subnet_aifa0g.create] Sending task 'cloudify_gcp.compute.subnetwork.creation_validation'
2019-08-08 08:18:14.837  CFY <gcp> [firewall_dxpxp3] Precreating node instance: nothing to do
2019-08-08 08:18:15.327  CFY <gcp> [firewall_dxpxp3] Creating node instance
2019-08-08 08:18:15.672  CFY <gcp> [firewall_dxpxp3.create] Sending task 'cloudify_gcp.compute.firewall.create'
2019-08-08 08:18:18.000  CFY <gcp> [subnet_aifa0g.create] Task succeeded 'cloudify_gcp.compute.subnetwork.creation_validation'
2019-08-08 08:18:18.129  CFY <gcp> [subnet_aifa0g] Node instance validated before creation
2019-08-08 08:18:18.308  CFY <gcp> [subnet_aifa0g] Precreating node instance: nothing to do
2019-08-08 08:18:18.472  LOG <gcp> [firewall_dxpxp3.create] INFO: Create firewall rule firewall-dxpxp3 in network https://www.googleapis.com/compute/v1/projects/node2faas-248113/global/networks/network-dcefjo
2019-08-08 08:18:18.562  CFY <gcp> [subnet_aifa0g] Creating node instance
2019-08-08 08:18:19.082  CFY <gcp> [subnet_aifa0g.create] Sending task 'cloudify_gcp.compute.subnetwork.create'
2019-08-08 08:18:21.711  LOG <gcp> [subnet_aifa0g.create] INFO: Create subnetwork subnet-aifa0g
2019-08-08 08:18:21.802  CFY <gcp> [firewall_dxpxp3.create] Task succeeded 'cloudify_gcp.compute.firewall.create'
2019-08-08 08:18:21.907  CFY <gcp> [firewall_dxpxp3] Node instance created
2019-08-08 08:18:22.428  CFY <gcp> [firewall_dxpxp3] Configuring node instance: nothing to do
2019-08-08 08:18:22.667  CFY <gcp> [firewall_dxpxp3] Starting node instance: nothing to do
2019-08-08 08:18:22.852  CFY <gcp> [firewall_dxpxp3] Poststarting node instance: nothing to do
2019-08-08 08:18:23.035  CFY <gcp> [firewall_dxpxp3] Node instance started
2019-08-08 08:18:24.939  CFY <gcp> [subnet_aifa0g.create] Task rescheduled 'cloudify_gcp.compute.subnetwork.create' -> Operation started
Traceback (most recent call last):
  File "/opt/mgmtworker/env/lib/python2.7/site-packages/cloudify/dispatch.py", line 813, in main
    payload = handler.handle()
  File "/opt/mgmtworker/env/lib/python2.7/site-packages/cloudify/dispatch.py", line 464, in handle
    raise ctx.operation._operation_retry
OperationRetry: Operation started

2019-08-08 08:18:40.074  CFY <gcp> [subnet_aifa0g.create] Sending task 'cloudify_gcp.compute.subnetwork.create' [retry 1/60]
2019-08-08 08:18:43.526  LOG <gcp> [subnet_aifa0g.create] INFO: Get subnetwork subnet-aifa0g details
2019-08-08 08:18:45.145  CFY <gcp> [subnet_aifa0g.create] Task succeeded 'cloudify_gcp.compute.subnetwork.create' [retry 1/60]
2019-08-08 08:18:45.421  CFY <gcp> [subnet_aifa0g] Node instance created
2019-08-08 08:18:45.588  CFY <gcp> [subnet_aifa0g] Configuring node instance: nothing to do
2019-08-08 08:18:45.650  CFY <gcp> [subnet_aifa0g] Starting node instance: nothing to do
2019-08-08 08:18:45.768  CFY <gcp> [subnet_aifa0g] Poststarting node instance: nothing to do
2019-08-08 08:18:46.088  CFY <gcp> [subnet_aifa0g] Node instance started
2019-08-08 08:18:46.665  CFY <gcp> [vm-database_cdljyw] Validating node instance before creation: nothing to do
2019-08-08 08:18:46.779  CFY <gcp> [vm-database_cdljyw] Precreating node instance: nothing to do
2019-08-08 08:18:46.865  CFY <gcp> [vm-database_cdljyw] Creating node instance
2019-08-08 08:18:47.433  CFY <gcp> [vm-database_cdljyw.create] Sending task 'script_runner.tasks.run'
2019-08-08 08:18:49.275  LOG <gcp> [vm-database_cdljyw.create] INFO: Downloaded scripts/gcp/key.py to /tmp/086EK/key.py
2019-08-08 08:18:49.890  CFY <gcp> [vm-database_cdljyw.create] Task succeeded 'script_runner.tasks.run'
2019-08-08 08:18:50.174  CFY <gcp> [vm-database_cdljyw] Node instance created
2019-08-08 08:18:50.372  CFY <gcp> [vm-database_cdljyw] Configuring node instance
2019-08-08 08:18:50.871  CFY <gcp> [vm-database_cdljyw.configure] Sending task 'cloudify_gcp.compute.instance.create'
2019-08-08 08:18:52.999  LOG <gcp> [vm-database_cdljyw.configure] INFO: The script is 
2019-08-08 08:18:53.384  LOG <gcp> [vm-database_cdljyw.configure] INFO: Adding bucket to metadata
2019-08-08 08:18:53.384  LOG <gcp> [vm-database_cdljyw.configure] INFO: Adding sshKeys to metadata
2019-08-08 08:18:55.301  LOG <gcp> [vm-database_cdljyw.configure] ERROR: Error traceback Traceback (most recent call last):
  File "/opt/mgmtworker/env/plugins/default_tenant/cloudify-gcp-plugin-1.4.4/lib/python2.7/site-packages/cloudify_gcp/utils.py", line 262, in _decorator
    return func(*args, **kwargs)
  File "/opt/mgmtworker/env/plugins/default_tenant/cloudify-gcp-plugin-1.4.4/lib/python2.7/site-packages/cloudify_gcp/compute/instance.py", line 422, in create
    utils.create(instance)
  File "/opt/mgmtworker/env/plugins/default_tenant/cloudify-gcp-plugin-1.4.4/lib/python2.7/site-packages/cloudify_gcp/utils.py", line 163, in _decorator
    return func(resource, *args, **kwargs)
  File "/opt/mgmtworker/env/plugins/default_tenant/cloudify-gcp-plugin-1.4.4/lib/python2.7/site-packages/cloudify_gcp/utils.py", line 170, in create
    return resource.create()
  File "/opt/mgmtworker/env/plugins/default_tenant/cloudify-gcp-plugin-1.4.4/lib/python2.7/site-packages/cloudify_gcp/utils.py", line 233, in wrapper
    response = func(self, *args, **kwargs)
  File "/opt/mgmtworker/env/plugins/default_tenant/cloudify-gcp-plugin-1.4.4/lib/python2.7/site-packages/cloudify_gcp/gcp.py", line 34, in _decorator
    response = func(self, *args, **kwargs)
  File "/opt/mgmtworker/env/plugins/default_tenant/cloudify-gcp-plugin-1.4.4/lib/python2.7/site-packages/cloudify_gcp/compute/instance.py", line 117, in create
    body=self.to_dict()).execute()
  File "/opt/mgmtworker/env/plugins/default_tenant/cloudify-gcp-plugin-1.4.4/lib/python2.7/site-packages/oauth2client/util.py", line 137, in positional_wrapper
    return wrapped(*args, **kwargs)
  File "/opt/mgmtworker/env/plugins/default_tenant/cloudify-gcp-plugin-1.4.4/lib/python2.7/site-packages/googleapiclient/http.py", line 832, in execute
    raise HttpError(resp, content, uri=self.uri)
HttpError: <HttpError 400 when requesting https://www.googleapis.com/compute/v1/projects/node2faas-248113/zones/us-east4-a/instances?alt=json returned "Invalid value for field 'resource.networkInterfaces[0].subnetwork': 'https://www.googleapis.com/compute/v1/projects/node2faas-248113/regions/southamerica-east1/subnetworks/subnet-aifa0g'. Instance must be in the same region as the subnetwork.">
 with message <HttpError 400 when requesting https://www.googleapis.com/compute/v1/projects/node2faas-248113/zones/us-east4-a/instances?alt=json returned "Invalid value for field 'resource.networkInterfaces[0].subnetwork': 'https://www.googleapis.com/compute/v1/projects/node2faas-248113/regions/southamerica-east1/subnetworks/subnet-aifa0g'. Instance must be in the same region as the subnetwork.">
2019-08-08 08:18:55.301  LOG <gcp> [vm-database_cdljyw.configure] ERROR: Error Message 
2019-08-08 08:18:56.028  CFY <gcp> [vm-database_cdljyw.configure] Task failed 'cloudify_gcp.compute.instance.create'
Traceback (most recent call last):
  File "/opt/mgmtworker/env/lib/python2.7/site-packages/cloudify/dispatch.py", line 813, in main
    payload = handler.handle()
  File "/opt/mgmtworker/env/lib/python2.7/site-packages/cloudify/dispatch.py", line 461, in handle
    result = self._run_operation_func(ctx, kwargs)
  File "/opt/mgmtworker/env/lib/python2.7/site-packages/cloudify/dispatch.py", line 519, in _run_operation_func
    return self.func(*self.args, **kwargs)
  File "/opt/mgmtworker/env/plugins/default_tenant/cloudify-gcp-plugin-1.4.4/lib/python2.7/site-packages/cloudify_gcp/utils.py", line 277, in _decorator
    raise NonRecoverableError(error.message)
NonRecoverableError

2019-08-08 08:18:56.309  CFY <gcp> 'install' workflow execution failed: RuntimeError: Workflow failed: Task failed 'cloudify_gcp.compute.instance.create'
Execution of workflow install for deployment gcp failed. [error=Traceback (most recent call last):
  File "/opt/mgmtworker/env/lib/python2.7/site-packages/cloudify/dispatch.py", line 664, in _remote_workflow_child_thread
    workflow_result = self._execute_workflow_function()
  File "/opt/mgmtworker/env/lib/python2.7/site-packages/cloudify/dispatch.py", line 693, in _execute_workflow_function
    result = self.func(*self.args, **self.kwargs)
  File "/opt/mgmtworker/env/lib/python2.7/site-packages/cloudify/plugins/workflows.py", line 31, in install
    node_instances=set(ctx.node_instances))
  File "/opt/mgmtworker/env/lib/python2.7/site-packages/cloudify/plugins/lifecycle.py", line 29, in install_node_instances
    processor.install()
  File "/opt/mgmtworker/env/lib/python2.7/site-packages/cloudify/plugins/lifecycle.py", line 102, in install
    graph.execute()
  File "/opt/mgmtworker/env/lib/python2.7/site-packages/cloudify/workflows/tasks_graph.py", line 237, in execute
    raise self._error
RuntimeError: Workflow failed: Task failed 'cloudify_gcp.compute.instance.create'
]
* Run 'cfy events list aa26cff1-fa25-49b4-b02d-e01c07cb49ec' to retrieve the execution's events/logs
'Executing workflow `uninstall` on deployment `gcp` [timeout=900 seconds] 2019-08-08 08:15:11.780 CFY <gcp> Starting 'uninstall' workflow execution 2019-08-08 08:15:12.665 CFY <gcp> [config-wordpress_7ojcvx] Validating node instance after deletion: nothing to do 2019-08-08 08:15:12.939 CFY <gcp> [config-wordpress_7ojcvx->vm-app2_1885tw|unlink] Sending task 'cloudify_ansible.tasks.ansible_remove_host' 2019-08-08 08:15:13.896 CFY <gcp> [firewall_l7gyu4] Stopping node instance 2019-08-08 08:15:14.283 CFY <gcp> [config-database_kgi4zm] Validating node instance after deletion: nothing to do 2019-08-08 08:15:14.498 CFY <gcp> [config-database_kgi4zm->vm-database_k7mun3|unlink] Sending task 'cloudify_ansible.tasks.ansible_remove_host' 2019-08-08 08:15:15.505 CFY <gcp> [config-database_kgi4zm] Stop: instance already uninitialized 2019-08-08 08:15:15.643 CFY <gcp> [firewall_l7gyu4] Validating node instance after deletion: nothing to do 2019-08-08 08:15:15.760 CFY <gcp> [config-wordpress_7ojcvx] Stop: instance already uninitialized 2019-08-08 08:15:16.359 CFY <gcp> [firewall_l7gyu4] Stopped node instance: nothing to do 2019-08-08 08:15:16.779 CFY <gcp> [config-wordpress_7ojcvx->vm-app2_1885tw|unlink] Task succeeded 'cloudify_ansible.tasks.ansible_remove_host' 2019-08-08 08:15:16.837 CFY <gcp> [config-database_kgi4zm] Delete: instance already uninitialized 2019-08-08 08:15:17.007 CFY <gcp> [config-wordpress_7ojcvx->vm-app1_oho999|unlink] Sending task 'cloudify_ansible.tasks.ansible_remove_host' 2019-08-08 08:15:18.036 CFY <gcp> [config-database_kgi4zm] Deleted node instance 2019-08-08 08:15:18.215 CFY <gcp> [config-wordpress_7ojcvx] Delete: instance already uninitialized 2019-08-08 08:15:18.360 CFY <gcp> [firewall_l7gyu4] Unlinking relationships 2019-08-08 08:15:18.716 CFY <gcp> [config-database_kgi4zm->vm-database_k7mun3|unlink] Task succeeded 'cloudify_ansible.tasks.ansible_remove_host' 2019-08-08 08:15:18.950 CFY <gcp> [config-wordpress_7ojcvx] Deleted node instance 2019-08-08 08:15:19.445 CFY <gcp> [firewall_l7gyu4] Relationships unlinked 2019-08-08 08:15:19.647 CFY <gcp> [firewall_l7gyu4] Deleting node instance 2019-08-08 08:15:20.332 CFY <gcp> [firewall_l7gyu4.delete] Sending task 'cloudify_gcp.compute.firewall.delete' 2019-08-08 08:15:21.370 CFY <gcp> [config-wordpress_7ojcvx->vm-app1_oho999|unlink] Task succeeded 'cloudify_ansible.tasks.ansible_remove_host' 2019-08-08 08:15:22.280 CFY <gcp> [vm-app2_1885tw] Validating node instance after deletion: nothing to do 2019-08-08 08:15:22.429 CFY <gcp> [vm-app1_oho999] Validating node instance after deletion: nothing to do 2019-08-08 08:15:22.554 CFY <gcp> [vm-app1_oho999] Stop: instance already uninitialized 2019-08-08 08:15:22.652 CFY <gcp> [vm-app2_1885tw] Stop: instance already uninitialized 2019-08-08 08:15:23.215 CFY <gcp> [vm-app1_oho999] Delete: instance already uninitialized 2019-08-08 08:15:23.333 CFY <gcp> [vm-app2_1885tw] Delete: instance already uninitialized 2019-08-08 08:15:23.787 CFY <gcp> [vm-app1_oho999] Deleted node instance 2019-08-08 08:15:23.824 LOG <gcp> [firewall_l7gyu4.delete] INFO: Delete firewall rule firewall-l7gyu4 from network https://www.googleapis.com/compute/v1/projects/node2faas-248113/global/networks/network-xispf2 2019-08-08 08:15:23.893 CFY <gcp> [vm-app2_1885tw] Deleted node instance 2019-08-08 08:15:24.577 CFY <gcp> [vm-database_k7mun3] Stopping node instance 2019-08-08 08:15:24.946 CFY <gcp> [vm-database_k7mun3] Validating node instance after deletion: nothing to do 2019-08-08 08:15:25.285 CFY <gcp> [vm-database_k7mun3] Stopped node instance: nothing to do 2019-08-08 08:15:25.667 CFY <gcp> [vm-database_k7mun3] Unlinking relationships 2019-08-08 08:15:25.938 CFY <gcp> [vm-database_k7mun3] Relationships unlinked 2019-08-08 08:15:26.027 CFY <gcp> [vm-database_k7mun3] Deleting node instance 2019-08-08 08:15:26.536 CFY <gcp> [vm-database_k7mun3.delete] Sending task 'cloudify_gcp.compute.instance.delete' 2019-08-08 08:15:26.650 CFY <gcp> [firewall_l7gyu4.delete] Task succeeded 'cloudify_gcp.compute.firewall.delete' 2019-08-08 08:15:27.780 CFY <gcp> [firewall_l7gyu4] Deleted node instance 2019-08-08 08:15:28.995 LOG <gcp> [vm-database_k7mun3.delete] INFO: Delete instance wordpressdatabase 2019-08-08 08:15:30.536 LOG <gcp> [vm-database_k7mun3.delete] ERROR: Error traceback Traceback (most recent call last): File "/opt/mgmtworker/env/plugins/default_tenant/cloudify-gcp-plugin-1.4.4/lib/python2.7/site-packages/cloudify_gcp/utils.py", line 262, in _decorator return func(*args, **kwargs) File "/opt/mgmtworker/env/plugins/default_tenant/cloudify-gcp-plugin-1.4.4/lib/python2.7/site-packages/cloudify_gcp/compute/instance.py", line 457, in delete utils.delete_if_not_external(instance) File "/opt/mgmtworker/env/plugins/default_tenant/cloudify-gcp-plugin-1.4.4/lib/python2.7/site-packages/cloudify_gcp/utils.py", line 175, in delete_if_not_external return resource.delete() File "/opt/mgmtworker/env/plugins/default_tenant/cloudify-gcp-plugin-1.4.4/lib/python2.7/site-packages/cloudify_gcp/utils.py", line 233, in wrapper response = func(self, *args, **kwargs) File "/opt/mgmtworker/env/plugins/default_tenant/cloudify-gcp-plugin-1.4.4/lib/python2.7/site-packages/cloudify_gcp/gcp.py", line 34, in _decorator response = func(self, *args, **kwargs) File "/opt/mgmtworker/env/plugins/default_tenant/cloudify-gcp-plugin-1.4.4/lib/python2.7/site-packages/cloudify_gcp/compute/instance.py", line 133, in delete instance=self.name).execute() File "/opt/mgmtworker/env/plugins/default_tenant/cloudify-gcp-plugin-1.4.4/lib/python2.7/site-packages/oauth2client/util.py", line 137, in positional_wrapper return wrapped(*args, **kwargs) File "/opt/mgmtworker/env/plugins/default_tenant/cloudify-gcp-plugin-1.4.4/lib/python2.7/site-packages/googleapiclient/http.py", line 832, in execute raise HttpError(resp, content, uri=self.uri) HttpError: <HttpError 404 when requesting https://www.googleapis.com/compute/v1/projects/node2faas-248113/zones/us-east4-a/instances/wordpressdatabase?alt=json returned "The resource 'projects/node2faas-248113/zones/us-east4-a/instances/wordpressdatabase' was not found"> with message <HttpError 404 when requesting https://www.googleapis.com/compute/v1/projects/node2faas-248113/zones/us-east4-a/instances/wordpressdatabase?alt=json returned "The resource 'projects/node2faas-248113/zones/us-east4-a/instances/wordpressdatabase' was not found"> 2019-08-08 08:15:30.536 LOG <gcp> [vm-database_k7mun3.delete] ERROR: Error Message 2019-08-08 08:15:31.084 CFY <gcp> [vm-database_k7mun3.delete] Task failed 'cloudify_gcp.compute.instance.delete' Traceback (most recent call last): File "/opt/mgmtworker/env/lib/python2.7/site-packages/cloudify/dispatch.py", line 813, in main payload = handler.handle() File "/opt/mgmtworker/env/lib/python2.7/site-packages/cloudify/dispatch.py", line 461, in handle result = self._run_operation_func(ctx, kwargs) File "/opt/mgmtworker/env/lib/python2.7/site-packages/cloudify/dispatch.py", line 519, in _run_operation_func return self.func(*self.args, **kwargs) File "/opt/mgmtworker/env/plugins/default_tenant/cloudify-gcp-plugin-1.4.4/lib/python2.7/site-packages/cloudify_gcp/utils.py", line 277, in _decorator raise NonRecoverableError(error.message) NonRecoverableError 2019-08-08 08:15:31.134 CFY <gcp> [vm-database_k7mun3] Deleted node instance 2019-08-08 08:15:31.772 CFY <gcp> [subnet_b7fveq] Stopping node instance 2019-08-08 08:15:31.964 CFY <gcp> [subnet_b7fveq] Validating node instance after deletion: nothing to do 2019-08-08 08:15:32.209 CFY <gcp> [subnet_b7fveq] Stopped node instance: nothing to do 2019-08-08 08:15:32.483 CFY <gcp> [subnet_b7fveq] Unlinking relationships 2019-08-08 08:15:32.764 CFY <gcp> [subnet_b7fveq] Relationships unlinked 2019-08-08 08:15:33.045 CFY <gcp> [subnet_b7fveq] Deleting node instance 2019-08-08 08:15:33.213 CFY <gcp> [subnet_b7fveq.delete] Sending task 'cloudify_gcp.compute.subnetwork.delete' 2019-08-08 08:15:35.330 LOG <gcp> [subnet_b7fveq.delete] INFO: Delete subnetwork subnet-b7fveq 2019-08-08 08:15:37.878 CFY <gcp> [subnet_b7fveq.delete] Task rescheduled 'cloudify_gcp.compute.subnetwork.delete' -> Operation started Traceback (most recent call last): File "/opt/mgmtworker/env/lib/python2.7/site-packages/cloudify/dispatch.py", line 813, in main payload = handler.handle() File "/opt/mgmtworker/env/lib/python2.7/site-packages/cloudify/dispatch.py", line 464, in handle raise ctx.operation._operation_retry OperationRetry: Operation started 2019-08-08 08:15:52.998 CFY <gcp> [subnet_b7fveq.delete] Sending task 'cloudify_gcp.compute.subnetwork.delete' [retry 1/60] 2019-08-08 08:15:57.051 CFY <gcp> [subnet_b7fveq.delete] Task succeeded 'cloudify_gcp.compute.subnetwork.delete' [retry 1/60] 2019-08-08 08:15:57.101 CFY <gcp> [subnet_b7fveq] Deleted node instance 2019-08-08 08:15:57.515 CFY <gcp> [network_xispf2] Stopping node instance 2019-08-08 08:15:57.851 CFY <gcp> [network_xispf2] Validating node instance after deletion: nothing to do 2019-08-08 08:15:58.061 CFY <gcp> [network_xispf2] Stopped node instance: nothing to do 2019-08-08 08:15:58.454 CFY <gcp> [network_xispf2] Unlinking relationships 2019-08-08 08:15:58.740 CFY <gcp> [network_xispf2] Relationships unlinked 2019-08-08 08:15:58.966 CFY <gcp> [network_xispf2] Deleting node instance 2019-08-08 08:15:59.165 CFY <gcp> [network_xispf2.delete] Sending task 'cloudify_gcp.compute.network.delete' 2019-08-08 08:16:01.123 LOG <gcp> [network_xispf2.delete] INFO: Delete network network-xispf2 2019-08-08 08:16:04.112 CFY <gcp> [network_xispf2.delete] Task rescheduled 'cloudify_gcp.compute.network.delete' -> Operation started Traceback (most recent call last): File "/opt/mgmtworker/env/lib/python2.7/site-packages/cloudify/dispatch.py", line 813, in main payload = handler.handle() File "/opt/mgmtworker/env/lib/python2.7/site-packages/cloudify/dispatch.py", line 464, in handle raise ctx.operation._operation_retry OperationRetry: Operation started 2019-08-08 08:16:19.255 CFY <gcp> [network_xispf2.delete] Sending task 'cloudify_gcp.compute.network.delete' [retry 1/60] 2019-08-08 08:16:23.786 CFY <gcp> [network_xispf2.delete] Task rescheduled 'cloudify_gcp.compute.network.delete' -> Operation not completed yet: RUNNING [retry_after=30] [retry 1/60] Traceback (most recent call last): File "/opt/mgmtworker/env/lib/python2.7/site-packages/cloudify/dispatch.py", line 813, in main payload = handler.handle() File "/opt/mgmtworker/env/lib/python2.7/site-packages/cloudify/dispatch.py", line 464, in handle raise ctx.operation._operation_retry OperationRetry: Operation not completed yet: RUNNING [retry_after=30] 2019-08-08 08:16:53.880 CFY <gcp> [network_xispf2.delete] Sending task 'cloudify_gcp.compute.network.delete' [retry 2/60] 2019-08-08 08:16:57.943 CFY <gcp> [network_xispf2.delete] Task succeeded 'cloudify_gcp.compute.network.delete' [retry 2/60] 2019-08-08 08:16:58.034 CFY <gcp> [network_xispf2] Deleted node instance 2019-08-08 08:16:58.552 CFY <gcp> 'uninstall' workflow execution succeeded Finished executing workflow uninstall on deployment gcp cloudify common logs monitors play_test.sh README.md reset_test.sh results stop_test.sh temp_count temp_cpu_amount temp_io_amount temp_mem_amount temp_mem_initial temp_mem_total temp_monitor_pid temp_net_amount terraform Run 'cfy events list a91a7e1d-5fd2-4783-85eb-4d08e68b9c5e' to retrieve the execution's events/logs Trying to delete deployment gcp... Deployment deleted Deleting blueprint cloudify-wordpress-blueprint-gcp... Blueprint deleted Trying to delete deployment gcp... An error occurred on the server: 404: Requested `Deployment` with ID `gcp` was not found Deleting blueprint cloudify-wordpress-blueprint-gcp... An error occurred on the server: 404: Requested `Blueprint` with ID `cloudify-wordpress-blueprint-gcp` was not found'
