Uploading blueprint cloudify/gcp.yaml...
 gcp.yaml |############################################################| 100.0%
Blueprint uploaded. The blueprint's id is cloudify-wordpress-blueprint-gcp
Creating new deployment from blueprint cloudify-wordpress-blueprint-gcp...
Deployment created. The deployment's id is gcp
Executing workflow `install` on deployment `gcp` [timeout=900 seconds]
Deployment environment creation is pending...
2019-08-10 17:09:08.909  CFY <gcp> Starting 'create_deployment_environment' workflow execution
2019-08-10 17:09:08.912  CFY <gcp> Installing deployment and workflow plugins
2019-08-10 17:09:09.014  CFY <gcp> Sending task 'cloudify_agent.operations.install_plugins'
2019-08-10 17:09:09.037  CFY <gcp> Task started 'cloudify_agent.operations.install_plugins'
2019-08-10 17:09:09.598  LOG <gcp> INFO: Installing plugin: gcp_plugin
2019-08-10 17:09:11.052  LOG <gcp> INFO: Using existing installation of managed plugin: e0a99ba4-54d6-4741-a773-4ec378dc8634 [package_name: cloudify-gcp-plugin, package_version: 1.4.4, supported_platform: linux_x86_64, distribution: centos, distribution_release: core]
2019-08-10 17:09:11.053  LOG <gcp> INFO: Installing plugin: ansible
2019-08-10 17:09:12.467  LOG <gcp> INFO: Using existing installation of managed plugin: 7142c593-6e52-429a-8a71-55266c022e02 [package_name: cloudify-ansible-plugin, package_version: 2.4.0, supported_platform: linux_x86_64, distribution: centos, distribution_release: core]
2019-08-10 17:09:12.467  LOG <gcp> INFO: Installing plugin: suspend
2019-08-10 17:09:13.432  LOG <gcp> INFO: Using existing installation of managed plugin: 62c3cd35-5a18-49fd-a670-48f9ad207b05 [package_name: cloudify-utilities-plugin, package_version: 1.14.0, supported_platform: linux_x86_64, distribution: centos, distribution_release: core]
2019-08-10 17:09:13.432  LOG <gcp> INFO: Installing plugin: configuration
2019-08-10 17:09:14.659  LOG <gcp> INFO: Using existing installation of managed plugin: 62c3cd35-5a18-49fd-a670-48f9ad207b05 [package_name: cloudify-utilities-plugin, package_version: 1.14.0, supported_platform: linux_x86_64, distribution: centos, distribution_release: core]
2019-08-10 17:09:14.659  LOG <gcp> INFO: Installing plugin: scalelist
2019-08-10 17:09:15.923  LOG <gcp> INFO: Using existing installation of managed plugin: 62c3cd35-5a18-49fd-a670-48f9ad207b05 [package_name: cloudify-utilities-plugin, package_version: 1.14.0, supported_platform: linux_x86_64, distribution: centos, distribution_release: core]
2019-08-10 17:09:15.924  CFY <gcp> Task succeeded 'cloudify_agent.operations.install_plugins'
2019-08-10 17:09:15.990  CFY <gcp> Creating deployment work directory
2019-08-10 17:09:16.291  CFY <gcp> 'create_deployment_environment' workflow execution succeeded
2019-08-10 17:09:20.612  CFY <gcp> Starting 'install' workflow execution
2019-08-10 17:09:22.279  CFY <gcp> [network_88atub] Validating node instance before creation: nothing to do
2019-08-10 17:09:22.372  CFY <gcp> [network_88atub] Precreating node instance: nothing to do
2019-08-10 17:09:22.652  CFY <gcp> [network_88atub] Creating node instance
2019-08-10 17:09:22.885  CFY <gcp> [network_88atub.create] Sending task 'cloudify_gcp.compute.network.create'
2019-08-10 17:09:24.782  LOG <gcp> [network_88atub.create] INFO: Create network network-88atub
2019-08-10 17:09:27.263  CFY <gcp> [network_88atub.create] Task rescheduled 'cloudify_gcp.compute.network.create' -> Operation started
Traceback (most recent call last):
  File "/opt/mgmtworker/env/lib/python2.7/site-packages/cloudify/dispatch.py", line 813, in main
    payload = handler.handle()
  File "/opt/mgmtworker/env/lib/python2.7/site-packages/cloudify/dispatch.py", line 464, in handle
    raise ctx.operation._operation_retry
OperationRetry: Operation started

2019-08-10 17:09:42.505  CFY <gcp> [network_88atub.create] Sending task 'cloudify_gcp.compute.network.create' [retry 1/60]
2019-08-10 17:09:46.604  LOG <gcp> [network_88atub.create] INFO: Get network network-88atub details
2019-08-10 17:09:49.406  CFY <gcp> [network_88atub.create] Task succeeded 'cloudify_gcp.compute.network.create' [retry 1/60]
2019-08-10 17:09:49.483  CFY <gcp> [network_88atub] Node instance created
2019-08-10 17:09:49.887  CFY <gcp> [network_88atub] Configuring node instance: nothing to do
2019-08-10 17:09:49.992  CFY <gcp> [network_88atub] Starting node instance: nothing to do
2019-08-10 17:09:50.092  CFY <gcp> [network_88atub] Poststarting node instance: nothing to do
2019-08-10 17:09:50.498  CFY <gcp> [network_88atub] Node instance started
2019-08-10 17:09:51.486  CFY <gcp> [firewall_wvthhe] Validating node instance before creation: nothing to do
2019-08-10 17:09:51.567  CFY <gcp> [subnet_kamdan] Validating node instance before creation
2019-08-10 17:09:51.649  CFY <gcp> [firewall_wvthhe] Precreating node instance: nothing to do
2019-08-10 17:09:51.817  CFY <gcp> [subnet_kamdan.create] Sending task 'cloudify_gcp.compute.subnetwork.creation_validation'
2019-08-10 17:09:53.011  CFY <gcp> [firewall_wvthhe] Creating node instance
2019-08-10 17:09:54.043  CFY <gcp> [firewall_wvthhe.create] Sending task 'cloudify_gcp.compute.firewall.create'
2019-08-10 17:09:56.964  CFY <gcp> [subnet_kamdan.create] Task succeeded 'cloudify_gcp.compute.subnetwork.creation_validation'
2019-08-10 17:09:57.063  CFY <gcp> [subnet_kamdan] Node instance validated before creation
2019-08-10 17:09:57.240  CFY <gcp> [subnet_kamdan] Precreating node instance: nothing to do
2019-08-10 17:09:57.814  CFY <gcp> [subnet_kamdan] Creating node instance
2019-08-10 17:09:57.982  LOG <gcp> [firewall_wvthhe.create] INFO: Create firewall rule firewall-wvthhe in network https://www.googleapis.com/compute/v1/projects/node2faas-248113/global/networks/network-88atub
2019-08-10 17:09:58.082  CFY <gcp> [subnet_kamdan.create] Sending task 'cloudify_gcp.compute.subnetwork.create'
2019-08-10 17:10:01.122  CFY <gcp> [firewall_wvthhe.create] Task succeeded 'cloudify_gcp.compute.firewall.create'
2019-08-10 17:10:01.157  CFY <gcp> [firewall_wvthhe] Node instance created
2019-08-10 17:10:02.082  CFY <gcp> [firewall_wvthhe] Configuring node instance: nothing to do
2019-08-10 17:10:02.286  LOG <gcp> [subnet_kamdan.create] INFO: Create subnetwork subnet-kamdan
2019-08-10 17:10:02.384  CFY <gcp> [firewall_wvthhe] Starting node instance: nothing to do
2019-08-10 17:10:02.588  CFY <gcp> [firewall_wvthhe] Poststarting node instance: nothing to do
2019-08-10 17:10:03.099  CFY <gcp> [firewall_wvthhe] Node instance started
2019-08-10 17:10:05.198  CFY <gcp> [subnet_kamdan.create] Task rescheduled 'cloudify_gcp.compute.subnetwork.create' -> Operation started
Traceback (most recent call last):
  File "/opt/mgmtworker/env/lib/python2.7/site-packages/cloudify/dispatch.py", line 813, in main
    payload = handler.handle()
  File "/opt/mgmtworker/env/lib/python2.7/site-packages/cloudify/dispatch.py", line 464, in handle
    raise ctx.operation._operation_retry
OperationRetry: Operation started

2019-08-10 17:10:20.305  CFY <gcp> [subnet_kamdan.create] Sending task 'cloudify_gcp.compute.subnetwork.create' [retry 1/60]
2019-08-10 17:10:24.112  LOG <gcp> [subnet_kamdan.create] INFO: Get subnetwork subnet-kamdan details
2019-08-10 17:10:26.234  CFY <gcp> [subnet_kamdan.create] Task succeeded 'cloudify_gcp.compute.subnetwork.create' [retry 1/60]
2019-08-10 17:10:26.845  CFY <gcp> [subnet_kamdan] Node instance created
2019-08-10 17:10:27.088  CFY <gcp> [subnet_kamdan] Configuring node instance: nothing to do
2019-08-10 17:10:27.295  CFY <gcp> [subnet_kamdan] Starting node instance: nothing to do
2019-08-10 17:10:27.516  CFY <gcp> [subnet_kamdan] Poststarting node instance: nothing to do
2019-08-10 17:10:27.948  CFY <gcp> [subnet_kamdan] Node instance started
2019-08-10 17:10:28.595  CFY <gcp> [vm-database_wjvznt] Validating node instance before creation: nothing to do
2019-08-10 17:10:28.817  CFY <gcp> [vm-database_wjvznt] Precreating node instance: nothing to do
2019-08-10 17:10:29.005  CFY <gcp> [vm-database_wjvznt] Creating node instance
2019-08-10 17:10:29.637  CFY <gcp> [vm-database_wjvznt.create] Sending task 'script_runner.tasks.run'
2019-08-10 17:10:31.943  LOG <gcp> [vm-database_wjvznt.create] INFO: Downloaded scripts/gcp/key.py to /tmp/Q8FOE/key.py
2019-08-10 17:10:32.714  CFY <gcp> [vm-database_wjvznt.create] Task succeeded 'script_runner.tasks.run'
2019-08-10 17:10:33.069  CFY <gcp> [vm-database_wjvznt] Node instance created
2019-08-10 17:10:33.618  CFY <gcp> [vm-database_wjvznt] Configuring node instance
2019-08-10 17:10:33.879  CFY <gcp> [vm-database_wjvznt.configure] Sending task 'cloudify_gcp.compute.instance.create'
2019-08-10 17:10:36.393  LOG <gcp> [vm-database_wjvznt.configure] INFO: The script is 
2019-08-10 17:10:36.737  LOG <gcp> [vm-database_wjvznt.configure] INFO: Adding bucket to metadata
2019-08-10 17:10:36.737  LOG <gcp> [vm-database_wjvznt.configure] INFO: Adding sshKeys to metadata
2019-08-10 17:10:39.668  CFY <gcp> [vm-database_wjvznt.configure] Task rescheduled 'cloudify_gcp.compute.instance.create' -> Operation started
Traceback (most recent call last):
  File "/opt/mgmtworker/env/lib/python2.7/site-packages/cloudify/dispatch.py", line 813, in main
    payload = handler.handle()
  File "/opt/mgmtworker/env/lib/python2.7/site-packages/cloudify/dispatch.py", line 464, in handle
    raise ctx.operation._operation_retry
OperationRetry: Operation started

2019-08-10 17:10:54.817  CFY <gcp> [vm-database_wjvznt.configure] Sending task 'cloudify_gcp.compute.instance.create' [retry 1/60]
2019-08-10 17:10:57.595  LOG <gcp> [vm-database_wjvznt.configure] INFO: The script is 
2019-08-10 17:10:58.999  LOG <gcp> [vm-database_wjvznt.configure] ERROR: Response with error {u'errors': [{u'message': u"The resource '482761649285-compute@developer.gserviceaccount.com' of type 'serviceAccount' was not found.", u'code': u'EXTERNAL_RESOURCE_NOT_FOUND'}]}
2019-08-10 17:10:58.999  LOG <gcp> [vm-database_wjvznt.configure] ERROR: Error Message {u'errors': [{u'message': u"The resource '482761649285-compute@developer.gserviceaccount.com' of type 'serviceAccount' was not found.", u'code': u'EXTERNAL_RESOURCE_NOT_FOUND'}]}
2019-08-10 17:10:59.830  CFY <gcp> [vm-database_wjvznt.configure] Task failed 'cloudify_gcp.compute.instance.create' -> {u'errors': [{u'message': u"The resource '482761649285-compute@developer.gserviceaccount.com' of type 'serviceAccount' was not found.", u'code': u'EXTERNAL_RESOURCE_NOT_FOUND'}]} [retry 1/60]
Traceback (most recent call last):
  File "/opt/mgmtworker/env/lib/python2.7/site-packages/cloudify/dispatch.py", line 813, in main
    payload = handler.handle()
  File "/opt/mgmtworker/env/lib/python2.7/site-packages/cloudify/dispatch.py", line 461, in handle
    result = self._run_operation_func(ctx, kwargs)
  File "/opt/mgmtworker/env/lib/python2.7/site-packages/cloudify/dispatch.py", line 519, in _run_operation_func
    return self.func(*self.args, **kwargs)
  File "/opt/mgmtworker/env/plugins/default_tenant/cloudify-gcp-plugin-1.4.4/lib/python2.7/site-packages/cloudify_gcp/utils.py", line 267, in _decorator
    raise NonRecoverableError(e.message)
NonRecoverableError: {u'errors': [{u'message': u"The resource '482761649285-compute@developer.gserviceaccount.com' of type 'serviceAccount' was not found.", u'code': u'EXTERNAL_RESOURCE_NOT_FOUND'}]}

2019-08-10 17:11:00.496  CFY <gcp> 'install' workflow execution failed: RuntimeError: Workflow failed: Task failed 'cloudify_gcp.compute.instance.create' -> {u'errors': [{u'message': u"The resource '482761649285-compute@developer.gserviceaccount.com' of type 'serviceAccount' was not found.", u'code': u'EXTERNAL_RESOURCE_NOT_FOUND'}]}
Execution of workflow install for deployment gcp failed. [error=Traceback (most recent call last):
  File "/opt/mgmtworker/env/lib/python2.7/site-packages/cloudify/dispatch.py", line 664, in _remote_workflow_child_thread
    workflow_result = self._execute_workflow_function()
  File "/opt/mgmtworker/env/lib/python2.7/site-packages/cloudify/dispatch.py", line 693, in _execute_workflow_function
    result = self.func(*self.args, **self.kwargs)
  File "/opt/mgmtworker/env/lib/python2.7/site-packages/cloudify/plugins/workflows.py", line 31, in install
    node_instances=set(ctx.node_instances))
  File "/opt/mgmtworker/env/lib/python2.7/site-packages/cloudify/plugins/lifecycle.py", line 29, in install_node_instances
    processor.install()
  File "/opt/mgmtworker/env/lib/python2.7/site-packages/cloudify/plugins/lifecycle.py", line 102, in install
    graph.execute()
  File "/opt/mgmtworker/env/lib/python2.7/site-packages/cloudify/workflows/tasks_graph.py", line 237, in execute
    raise self._error
RuntimeError: Workflow failed: Task failed 'cloudify_gcp.compute.instance.create' -> {u'errors': [{u'message': u"The resource '482761649285-compute@developer.gserviceaccount.com' of type 'serviceAccount' was not found.", u'code': u'EXTERNAL_RESOURCE_NOT_FOUND'}]}
]
* Run 'cfy events list f1f73590-38d4-42b9-89d8-dc12a903bd63' to retrieve the execution's events/logs
