Uploading blueprint cloudify/gcp.yaml...
 gcp.yaml |############################################################| 100.0%
Blueprint uploaded. The blueprint's id is cloudify-wordpress-blueprint-gcp
Creating new deployment from blueprint cloudify-wordpress-blueprint-gcp...
Deployment created. The deployment's id is gcp
Executing workflow `install` on deployment `gcp` [timeout=900 seconds]
Deployment environment creation is pending...
2019-08-08 09:35:30.779  CFY <gcp> Starting 'create_deployment_environment' workflow execution
2019-08-08 09:35:30.783  CFY <gcp> Installing deployment and workflow plugins
2019-08-08 09:35:30.883  CFY <gcp> Sending task 'cloudify_agent.operations.install_plugins'
2019-08-08 09:35:30.906  CFY <gcp> Task started 'cloudify_agent.operations.install_plugins'
2019-08-08 09:35:31.240  LOG <gcp> INFO: Installing plugin: gcp_plugin
2019-08-08 09:35:32.416  LOG <gcp> INFO: Using existing installation of managed plugin: e0a99ba4-54d6-4741-a773-4ec378dc8634 [package_name: cloudify-gcp-plugin, package_version: 1.4.4, supported_platform: linux_x86_64, distribution: centos, distribution_release: core]
2019-08-08 09:35:32.416  LOG <gcp> INFO: Installing plugin: ansible
2019-08-08 09:35:33.683  LOG <gcp> INFO: Using existing installation of managed plugin: 7142c593-6e52-429a-8a71-55266c022e02 [package_name: cloudify-ansible-plugin, package_version: 2.4.0, supported_platform: linux_x86_64, distribution: centos, distribution_release: core]
2019-08-08 09:35:33.683  LOG <gcp> INFO: Installing plugin: suspend
2019-08-08 09:35:34.519  LOG <gcp> INFO: Using existing installation of managed plugin: 62c3cd35-5a18-49fd-a670-48f9ad207b05 [package_name: cloudify-utilities-plugin, package_version: 1.14.0, supported_platform: linux_x86_64, distribution: centos, distribution_release: core]
2019-08-08 09:35:34.519  LOG <gcp> INFO: Installing plugin: scalelist
2019-08-08 09:35:35.482  LOG <gcp> INFO: Using existing installation of managed plugin: 62c3cd35-5a18-49fd-a670-48f9ad207b05 [package_name: cloudify-utilities-plugin, package_version: 1.14.0, supported_platform: linux_x86_64, distribution: centos, distribution_release: core]
2019-08-08 09:35:35.482  LOG <gcp> INFO: Installing plugin: configuration
2019-08-08 09:35:36.888  CFY <gcp> Task succeeded 'cloudify_agent.operations.install_plugins'
2019-08-08 09:35:36.888  LOG <gcp> INFO: Using existing installation of managed plugin: 62c3cd35-5a18-49fd-a670-48f9ad207b05 [package_name: cloudify-utilities-plugin, package_version: 1.14.0, supported_platform: linux_x86_64, distribution: centos, distribution_release: core]
2019-08-08 09:35:36.890  CFY <gcp> Creating deployment work directory
2019-08-08 09:35:37.196  CFY <gcp> 'create_deployment_environment' workflow execution succeeded
2019-08-08 09:35:41.847  CFY <gcp> Starting 'install' workflow execution
2019-08-08 09:35:43.679  CFY <gcp> [network_brka82] Validating node instance before creation: nothing to do
2019-08-08 09:35:43.805  CFY <gcp> [network_brka82] Precreating node instance: nothing to do
2019-08-08 09:35:43.876  CFY <gcp> [network_brka82] Creating node instance
2019-08-08 09:35:44.397  CFY <gcp> [network_brka82.create] Sending task 'cloudify_gcp.compute.network.create'
2019-08-08 09:35:46.548  LOG <gcp> [network_brka82.create] INFO: Create network network-brka82
2019-08-08 09:35:49.351  CFY <gcp> [network_brka82.create] Task rescheduled 'cloudify_gcp.compute.network.create' -> Operation started
Traceback (most recent call last):
  File "/opt/mgmtworker/env/lib/python2.7/site-packages/cloudify/dispatch.py", line 813, in main
    payload = handler.handle()
  File "/opt/mgmtworker/env/lib/python2.7/site-packages/cloudify/dispatch.py", line 464, in handle
    raise ctx.operation._operation_retry
OperationRetry: Operation started

2019-08-08 09:36:04.494  CFY <gcp> [network_brka82.create] Sending task 'cloudify_gcp.compute.network.create' [retry 1/60]
2019-08-08 09:36:07.939  LOG <gcp> [network_brka82.create] INFO: Get network network-brka82 details
2019-08-08 09:36:09.576  CFY <gcp> [network_brka82.create] Task succeeded 'cloudify_gcp.compute.network.create' [retry 1/60]
2019-08-08 09:36:09.844  CFY <gcp> [network_brka82] Node instance created
2019-08-08 09:36:09.979  CFY <gcp> [network_brka82] Configuring node instance: nothing to do
2019-08-08 09:36:10.071  CFY <gcp> [network_brka82] Starting node instance: nothing to do
2019-08-08 09:36:10.174  CFY <gcp> [network_brka82] Poststarting node instance: nothing to do
2019-08-08 09:36:10.437  CFY <gcp> [network_brka82] Node instance started
2019-08-08 09:36:11.434  CFY <gcp> [firewall_kivy4f] Validating node instance before creation: nothing to do
2019-08-08 09:36:11.526  CFY <gcp> [subnet_w0qhim] Validating node instance before creation
2019-08-08 09:36:11.621  CFY <gcp> [firewall_kivy4f] Precreating node instance: nothing to do
2019-08-08 09:36:11.824  CFY <gcp> [subnet_w0qhim.create] Sending task 'cloudify_gcp.compute.subnetwork.creation_validation'
2019-08-08 09:36:13.052  CFY <gcp> [firewall_kivy4f] Creating node instance
2019-08-08 09:36:13.386  CFY <gcp> [firewall_kivy4f.create] Sending task 'cloudify_gcp.compute.firewall.create'
2019-08-08 09:36:16.157  CFY <gcp> [subnet_w0qhim.create] Task succeeded 'cloudify_gcp.compute.subnetwork.creation_validation'
2019-08-08 09:36:16.179  CFY <gcp> [subnet_w0qhim] Node instance validated before creation
2019-08-08 09:36:16.405  CFY <gcp> [subnet_w0qhim] Precreating node instance: nothing to do
2019-08-08 09:36:16.783  CFY <gcp> [subnet_w0qhim] Creating node instance
2019-08-08 09:36:16.783  CFY <gcp> [subnet_w0qhim] Creating node instance
2019-08-08 09:36:16.971  CFY <gcp> [subnet_w0qhim.create] Sending task 'cloudify_gcp.compute.subnetwork.create'
2019-08-08 09:36:19.184  LOG <gcp> [subnet_w0qhim.create] INFO: Create subnetwork subnet-w0qhim
2019-08-08 09:36:19.658  CFY <gcp> [firewall_kivy4f.create] Task succeeded 'cloudify_gcp.compute.firewall.create'
2019-08-08 09:36:19.764  CFY <gcp> [firewall_kivy4f] Node instance created
2019-08-08 09:36:20.186  CFY <gcp> [firewall_kivy4f] Configuring node instance: nothing to do
2019-08-08 09:36:20.365  CFY <gcp> [firewall_kivy4f] Starting node instance: nothing to do
2019-08-08 09:36:20.540  CFY <gcp> [firewall_kivy4f] Poststarting node instance: nothing to do
2019-08-08 09:36:20.883  CFY <gcp> [firewall_kivy4f] Node instance started
2019-08-08 09:36:21.931  CFY <gcp> [subnet_w0qhim.create] Task rescheduled 'cloudify_gcp.compute.subnetwork.create' -> Operation started
Traceback (most recent call last):
  File "/opt/mgmtworker/env/lib/python2.7/site-packages/cloudify/dispatch.py", line 813, in main
    payload = handler.handle()
  File "/opt/mgmtworker/env/lib/python2.7/site-packages/cloudify/dispatch.py", line 464, in handle
    raise ctx.operation._operation_retry
OperationRetry: Operation started

2019-08-08 09:36:37.070  CFY <gcp> [subnet_w0qhim.create] Sending task 'cloudify_gcp.compute.subnetwork.create' [retry 1/60]
2019-08-08 09:36:40.245  LOG <gcp> [subnet_w0qhim.create] INFO: Get subnetwork subnet-w0qhim details
2019-08-08 09:36:41.956  CFY <gcp> [subnet_w0qhim.create] Task succeeded 'cloudify_gcp.compute.subnetwork.create' [retry 1/60]
2019-08-08 09:36:42.351  CFY <gcp> [subnet_w0qhim] Node instance created
2019-08-08 09:36:42.515  CFY <gcp> [subnet_w0qhim] Configuring node instance: nothing to do
2019-08-08 09:36:42.601  CFY <gcp> [subnet_w0qhim] Starting node instance: nothing to do
2019-08-08 09:36:42.732  CFY <gcp> [subnet_w0qhim] Poststarting node instance: nothing to do
2019-08-08 09:36:42.805  CFY <gcp> [subnet_w0qhim] Node instance started
2019-08-08 09:36:43.548  CFY <gcp> [vm-database_ubeh0s] Validating node instance before creation: nothing to do
2019-08-08 09:36:43.645  CFY <gcp> [vm-database_ubeh0s] Precreating node instance: nothing to do
2019-08-08 09:36:44.070  CFY <gcp> [vm-database_ubeh0s] Creating node instance
2019-08-08 09:36:44.212  CFY <gcp> [vm-database_ubeh0s.create] Sending task 'script_runner.tasks.run'
2019-08-08 09:36:46.004  LOG <gcp> [vm-database_ubeh0s.create] INFO: Downloaded scripts/gcp/key.py to /tmp/XKDOH/key.py
2019-08-08 09:36:46.481  CFY <gcp> [vm-database_ubeh0s.create] Task succeeded 'script_runner.tasks.run'
2019-08-08 09:36:46.537  CFY <gcp> [vm-database_ubeh0s] Node instance created
2019-08-08 09:36:47.234  CFY <gcp> [vm-database_ubeh0s] Configuring node instance
2019-08-08 09:36:47.477  CFY <gcp> [vm-database_ubeh0s.configure] Sending task 'cloudify_gcp.compute.instance.create'
2019-08-08 09:36:49.450  LOG <gcp> [vm-database_ubeh0s.configure] INFO: The script is 
2019-08-08 09:36:49.772  LOG <gcp> [vm-database_ubeh0s.configure] INFO: Adding bucket to metadata
2019-08-08 09:36:49.772  LOG <gcp> [vm-database_ubeh0s.configure] INFO: Adding sshKeys to metadata
2019-08-08 09:36:51.086  LOG <gcp> [vm-database_ubeh0s.configure] ERROR: Error traceback Traceback (most recent call last):
  File "/opt/mgmtworker/env/plugins/default_tenant/cloudify-gcp-plugin-1.4.4/lib/python2.7/site-packages/cloudify_gcp/utils.py", line 262, in _decorator
    return func(*args, **kwargs)
  File "/opt/mgmtworker/env/plugins/default_tenant/cloudify-gcp-plugin-1.4.4/lib/python2.7/site-packages/cloudify_gcp/compute/instance.py", line 422, in create
    utils.create(instance)
  File "/opt/mgmtworker/env/plugins/default_tenant/cloudify-gcp-plugin-1.4.4/lib/python2.7/site-packages/cloudify_gcp/utils.py", line 163, in _decorator
    return func(resource, *args, **kwargs)
  File "/opt/mgmtworker/env/plugins/default_tenant/cloudify-gcp-plugin-1.4.4/lib/python2.7/site-packages/cloudify_gcp/utils.py", line 170, in create
    return resource.create()
  File "/opt/mgmtworker/env/plugins/default_tenant/cloudify-gcp-plugin-1.4.4/lib/python2.7/site-packages/cloudify_gcp/utils.py", line 233, in wrapper
    response = func(self, *args, **kwargs)
  File "/opt/mgmtworker/env/plugins/default_tenant/cloudify-gcp-plugin-1.4.4/lib/python2.7/site-packages/cloudify_gcp/gcp.py", line 34, in _decorator
    response = func(self, *args, **kwargs)
  File "/opt/mgmtworker/env/plugins/default_tenant/cloudify-gcp-plugin-1.4.4/lib/python2.7/site-packages/cloudify_gcp/compute/instance.py", line 117, in create
    body=self.to_dict()).execute()
  File "/opt/mgmtworker/env/plugins/default_tenant/cloudify-gcp-plugin-1.4.4/lib/python2.7/site-packages/oauth2client/util.py", line 137, in positional_wrapper
    return wrapped(*args, **kwargs)
  File "/opt/mgmtworker/env/plugins/default_tenant/cloudify-gcp-plugin-1.4.4/lib/python2.7/site-packages/googleapiclient/http.py", line 832, in execute
    raise HttpError(resp, content, uri=self.uri)
HttpError: <HttpError 400 when requesting https://www.googleapis.com/compute/v1/projects/node2faas-248113/zones/us-east4-a/instances?alt=json returned "Invalid value for field 'resource.networkInterfaces[0].subnetwork': 'https://www.googleapis.com/compute/v1/projects/node2faas-248113/regions/southamerica-east1/subnetworks/subnet-w0qhim'. Instance must be in the same region as the subnetwork.">
 with message <HttpError 400 when requesting https://www.googleapis.com/compute/v1/projects/node2faas-248113/zones/us-east4-a/instances?alt=json returned "Invalid value for field 'resource.networkInterfaces[0].subnetwork': 'https://www.googleapis.com/compute/v1/projects/node2faas-248113/regions/southamerica-east1/subnetworks/subnet-w0qhim'. Instance must be in the same region as the subnetwork.">
2019-08-08 09:36:51.086  LOG <gcp> [vm-database_ubeh0s.configure] ERROR: Error Message 
2019-08-08 09:36:51.658  CFY <gcp> [vm-database_ubeh0s.configure] Task failed 'cloudify_gcp.compute.instance.create'
Traceback (most recent call last):
  File "/opt/mgmtworker/env/lib/python2.7/site-packages/cloudify/dispatch.py", line 813, in main
    payload = handler.handle()
  File "/opt/mgmtworker/env/lib/python2.7/site-packages/cloudify/dispatch.py", line 461, in handle
    result = self._run_operation_func(ctx, kwargs)
  File "/opt/mgmtworker/env/lib/python2.7/site-packages/cloudify/dispatch.py", line 519, in _run_operation_func
    return self.func(*self.args, **kwargs)
  File "/opt/mgmtworker/env/plugins/default_tenant/cloudify-gcp-plugin-1.4.4/lib/python2.7/site-packages/cloudify_gcp/utils.py", line 277, in _decorator
    raise NonRecoverableError(error.message)
NonRecoverableError

2019-08-08 09:36:52.007  CFY <gcp> 'install' workflow execution failed: RuntimeError: Workflow failed: Task failed 'cloudify_gcp.compute.instance.create'
Execution of workflow install for deployment gcp failed. [error=Traceback (most recent call last):
  File "/opt/mgmtworker/env/lib/python2.7/site-packages/cloudify/dispatch.py", line 664, in _remote_workflow_child_thread
    workflow_result = self._execute_workflow_function()
  File "/opt/mgmtworker/env/lib/python2.7/site-packages/cloudify/dispatch.py", line 693, in _execute_workflow_function
    result = self.func(*self.args, **self.kwargs)
  File "/opt/mgmtworker/env/lib/python2.7/site-packages/cloudify/plugins/workflows.py", line 31, in install
    node_instances=set(ctx.node_instances))
  File "/opt/mgmtworker/env/lib/python2.7/site-packages/cloudify/plugins/lifecycle.py", line 29, in install_node_instances
    processor.install()
  File "/opt/mgmtworker/env/lib/python2.7/site-packages/cloudify/plugins/lifecycle.py", line 102, in install
    graph.execute()
  File "/opt/mgmtworker/env/lib/python2.7/site-packages/cloudify/workflows/tasks_graph.py", line 237, in execute
    raise self._error
RuntimeError: Workflow failed: Task failed 'cloudify_gcp.compute.instance.create'
]
* Run 'cfy events list c24c3edf-d0c6-4989-877a-58d3ac3365f9' to retrieve the execution's events/logs
'Executing workflow `uninstall` on deployment `gcp` [timeout=900 seconds] 2019-08-08 09:33:09.679 CFY <gcp> Starting 'uninstall' workflow execution 2019-08-08 09:33:10.679 CFY <gcp> [config-database_qbiwls] Validating node instance after deletion: nothing to do 2019-08-08 09:33:10.860 CFY <gcp> [config-wordpress_j71g0m->vm-app2_twywl6|unlink] Sending task 'cloudify_ansible.tasks.ansible_remove_host' 2019-08-08 09:33:11.886 CFY <gcp> [config-database_qbiwls->vm-database_fguavw|unlink] Sending task 'cloudify_ansible.tasks.ansible_remove_host' 2019-08-08 09:33:13.296 CFY <gcp> [firewall_l3r7m0] Stopping node instance 2019-08-08 09:33:13.487 CFY <gcp> [config-wordpress_j71g0m] Validating node instance after deletion: nothing to do 2019-08-08 09:33:13.845 CFY <gcp> [config-wordpress_j71g0m] Stop: instance already uninitialized 2019-08-08 09:33:13.979 CFY <gcp> [firewall_l3r7m0] Validating node instance after deletion: nothing to do 2019-08-08 09:33:14.103 CFY <gcp> [config-database_qbiwls] Stop: instance already uninitialized 2019-08-08 09:33:14.638 CFY <gcp> [firewall_l3r7m0] Stopped node instance: nothing to do 2019-08-08 09:33:15.164 CFY <gcp> [config-wordpress_j71g0m] Delete: instance already uninitialized 2019-08-08 09:33:15.415 CFY <gcp> [config-wordpress_j71g0m->vm-app2_twywl6|unlink] Task failed 'cloudify_ansible.tasks.ansible_remove_host' -> 409: Node instance update conflict [current version=2, update version=1] Traceback (most recent call last): File "/opt/mgmtworker/env/lib/python2.7/site-packages/cloudify/dispatch.py", line 813, in main payload = handler.handle() File "/opt/mgmtworker/env/lib/python2.7/site-packages/cloudify/dispatch.py", line 461, in handle result = self._run_operation_func(ctx, kwargs) File "/opt/mgmtworker/env/lib/python2.7/site-packages/cloudify/dispatch.py", line 524, in _run_operation_func ctx.source.instance.update() File "/opt/mgmtworker/env/lib/python2.7/site-packages/cloudify/context.py", line 414, in update self._endpoint.update_node_instance(self._node_instance) File "/opt/mgmtworker/env/lib/python2.7/site-packages/cloudify/endpoint.py", line 177, in update_node_instance return manager.update_node_instance(node_instance) File "/opt/mgmtworker/env/lib/python2.7/site-packages/cloudify/manager.py", line 389, in update_node_instance version=node_instance.version) File "/opt/mgmtworker/env/lib/python2.7/site-packages/cloudify_rest_client/node_instances.py", line 141, in update response = self.api.patch(uri, data=data) File "/opt/mgmtworker/env/lib/python2.7/site-packages/cloudify_rest_client/client.py", line 311, in patch timeout=timeout) File "/opt/mgmtworker/env/lib/python2.7/site-packages/cloudify/cluster.py", line 57, in do_request **kwargs) File "/opt/mgmtworker/env/lib/python2.7/site-packages/cloudify_rest_client/client.py", line 257, in do_request verify=self.get_request_verify(), timeout=timeout) File "/opt/mgmtworker/env/lib/python2.7/site-packages/cloudify_rest_client/client.py", line 191, in _do_request self._raise_client_error(response, request_url) File "/opt/mgmtworker/env/lib/python2.7/site-packages/cloudify_rest_client/client.py", line 144, in _raise_client_error response=response) File "/opt/mgmtworker/env/lib/python2.7/site-packages/cloudify_rest_client/client.py", line 156, in _prepare_and_raise_exception status_code, error_code=error_code, response=response) CloudifyClientError: 409: Node instance update conflict [current version=2, update version=1] 2019-08-08 09:33:15.713 CFY <gcp> [config-database_qbiwls] Delete: instance already uninitialized 2019-08-08 09:33:15.716 CFY <gcp> [config-wordpress_j71g0m->vm-app1_ivnftt|unlink] Sending task 'cloudify_ansible.tasks.ansible_remove_host' 2019-08-08 09:33:16.321 CFY <gcp> [config-wordpress_j71g0m] Deleted node instance 2019-08-08 09:33:16.911 CFY <gcp> [firewall_l3r7m0] Unlinking relationships 2019-08-08 09:33:17.069 CFY <gcp> [config-database_qbiwls] Deleted node instance 2019-08-08 09:33:17.259 CFY <gcp> [config-database_qbiwls->vm-database_fguavw|unlink] Task succeeded 'cloudify_ansible.tasks.ansible_remove_host' 2019-08-08 09:33:17.612 CFY <gcp> [firewall_l3r7m0] Relationships unlinked 2019-08-08 09:33:17.969 CFY <gcp> [firewall_l3r7m0] Deleting node instance 2019-08-08 09:33:18.582 CFY <gcp> [firewall_l3r7m0.delete] Sending task 'cloudify_gcp.compute.firewall.delete' 2019-08-08 09:33:19.638 CFY <gcp> [config-wordpress_j71g0m->vm-app1_ivnftt|unlink] Task succeeded 'cloudify_ansible.tasks.ansible_remove_host' 2019-08-08 09:33:20.246 CFY <gcp> [vm-app1_ivnftt] Validating node instance after deletion: nothing to do 2019-08-08 09:33:20.432 CFY <gcp> [vm-app2_twywl6] Validating node instance after deletion: nothing to do 2019-08-08 09:33:20.659 CFY <gcp> [vm-app1_ivnftt] Stop: instance already uninitialized 2019-08-08 09:33:20.858 CFY <gcp> [vm-app2_twywl6] Stop: instance already uninitialized 2019-08-08 09:33:21.483 CFY <gcp> [vm-app2_twywl6] Delete: instance already uninitialized 2019-08-08 09:33:21.603 CFY <gcp> [vm-app1_ivnftt] Delete: instance already uninitialized 2019-08-08 09:33:22.048 CFY <gcp> [vm-app2_twywl6] Deleted node instance 2019-08-08 09:33:22.048 CFY <gcp> [vm-app2_twywl6] Deleted node instance 2019-08-08 09:33:22.552 CFY <gcp> [vm-app1_ivnftt] Deleted node instance 2019-08-08 09:33:23.187 CFY <gcp> [vm-database_fguavw] Stopping node instance 2019-08-08 09:33:23.265 CFY <gcp> [vm-database_fguavw] Validating node instance after deletion: nothing to do 2019-08-08 09:33:23.589 CFY <gcp> [vm-database_fguavw] Stopped node instance: nothing to do 2019-08-08 09:33:23.872 CFY <gcp> [vm-database_fguavw] Unlinking relationships 2019-08-08 09:33:24.148 CFY <gcp> [vm-database_fguavw] Relationships unlinked 2019-08-08 09:33:24.528 CFY <gcp> [vm-database_fguavw] Deleting node instance 2019-08-08 09:33:24.799 CFY <gcp> [vm-database_fguavw.delete] Sending task 'cloudify_gcp.compute.instance.delete' 2019-08-08 09:33:24.936 CFY <gcp> [firewall_l3r7m0.delete] Task succeeded 'cloudify_gcp.compute.firewall.delete' 2019-08-08 09:33:26.091 CFY <gcp> [firewall_l3r7m0] Deleted node instance 2019-08-08 09:33:27.282 LOG <gcp> [vm-database_fguavw.delete] INFO: Delete instance wordpressdatabase 2019-08-08 09:33:29.367 LOG <gcp> [vm-database_fguavw.delete] ERROR: Error traceback Traceback (most recent call last): File "/opt/mgmtworker/env/plugins/default_tenant/cloudify-gcp-plugin-1.4.4/lib/python2.7/site-packages/cloudify_gcp/utils.py", line 262, in _decorator return func(*args, **kwargs) File "/opt/mgmtworker/env/plugins/default_tenant/cloudify-gcp-plugin-1.4.4/lib/python2.7/site-packages/cloudify_gcp/compute/instance.py", line 457, in delete utils.delete_if_not_external(instance) File "/opt/mgmtworker/env/plugins/default_tenant/cloudify-gcp-plugin-1.4.4/lib/python2.7/site-packages/cloudify_gcp/utils.py", line 175, in delete_if_not_external return resource.delete() File "/opt/mgmtworker/env/plugins/default_tenant/cloudify-gcp-plugin-1.4.4/lib/python2.7/site-packages/cloudify_gcp/utils.py", line 233, in wrapper response = func(self, *args, **kwargs) File "/opt/mgmtworker/env/plugins/default_tenant/cloudify-gcp-plugin-1.4.4/lib/python2.7/site-packages/cloudify_gcp/gcp.py", line 34, in _decorator response = func(self, *args, **kwargs) File "/opt/mgmtworker/env/plugins/default_tenant/cloudify-gcp-plugin-1.4.4/lib/python2.7/site-packages/cloudify_gcp/compute/instance.py", line 133, in delete instance=self.name).execute() File "/opt/mgmtworker/env/plugins/default_tenant/cloudify-gcp-plugin-1.4.4/lib/python2.7/site-packages/oauth2client/util.py", line 137, in positional_wrapper return wrapped(*args, **kwargs) File "/opt/mgmtworker/env/plugins/default_tenant/cloudify-gcp-plugin-1.4.4/lib/python2.7/site-packages/googleapiclient/http.py", line 832, in execute raise HttpError(resp, content, uri=self.uri) HttpError: <HttpError 404 when requesting https://www.googleapis.com/compute/v1/projects/node2faas-248113/zones/us-east4-a/instances/wordpressdatabase?alt=json returned "The resource 'projects/node2faas-248113/zones/us-east4-a/instances/wordpressdatabase' was not found"> with message <HttpError 404 when requesting https://www.googleapis.com/compute/v1/projects/node2faas-248113/zones/us-east4-a/instances/wordpressdatabase?alt=json returned "The resource 'projects/node2faas-248113/zones/us-east4-a/instances/wordpressdatabase' was not found"> 2019-08-08 09:33:29.368 LOG <gcp> [vm-database_fguavw.delete] ERROR: Error Message 2019-08-08 09:33:29.999 CFY <gcp> [vm-database_fguavw.delete] Task failed 'cloudify_gcp.compute.instance.delete' Traceback (most recent call last): File "/opt/mgmtworker/env/lib/python2.7/site-packages/cloudify/dispatch.py", line 813, in main payload = handler.handle() File "/opt/mgmtworker/env/lib/python2.7/site-packages/cloudify/dispatch.py", line 461, in handle result = self._run_operation_func(ctx, kwargs) File "/opt/mgmtworker/env/lib/python2.7/site-packages/cloudify/dispatch.py", line 519, in _run_operation_func return self.func(*self.args, **kwargs) File "/opt/mgmtworker/env/plugins/default_tenant/cloudify-gcp-plugin-1.4.4/lib/python2.7/site-packages/cloudify_gcp/utils.py", line 277, in _decorator raise NonRecoverableError(error.message) NonRecoverableError 2019-08-08 09:33:30.005 CFY <gcp> [vm-database_fguavw] Deleted node instance 2019-08-08 09:33:30.957 CFY <gcp> [subnet_v908s0] Stopping node instance 2019-08-08 09:33:31.109 CFY <gcp> [subnet_v908s0] Validating node instance after deletion: nothing to do 2019-08-08 09:33:31.226 CFY <gcp> [subnet_v908s0] Stopped node instance: nothing to do 2019-08-08 09:33:31.513 CFY <gcp> [subnet_v908s0] Unlinking relationships 2019-08-08 09:33:31.787 CFY <gcp> [subnet_v908s0] Relationships unlinked 2019-08-08 09:33:31.883 CFY <gcp> [subnet_v908s0] Deleting node instance 2019-08-08 09:33:32.233 CFY <gcp> [subnet_v908s0.delete] Sending task 'cloudify_gcp.compute.subnetwork.delete' 2019-08-08 09:33:34.130 LOG <gcp> [subnet_v908s0.delete] INFO: Delete subnetwork subnet-v908s0 2019-08-08 09:33:36.767 CFY <gcp> [subnet_v908s0.delete] Task rescheduled 'cloudify_gcp.compute.subnetwork.delete' -> Operation started Traceback (most recent call last): File "/opt/mgmtworker/env/lib/python2.7/site-packages/cloudify/dispatch.py", line 813, in main payload = handler.handle() File "/opt/mgmtworker/env/lib/python2.7/site-packages/cloudify/dispatch.py", line 464, in handle raise ctx.operation._operation_retry OperationRetry: Operation started 2019-08-08 09:33:51.876 CFY <gcp> [subnet_v908s0.delete] Sending task 'cloudify_gcp.compute.subnetwork.delete' [retry 1/60] 2019-08-08 09:33:55.750 CFY <gcp> [subnet_v908s0.delete] Task succeeded 'cloudify_gcp.compute.subnetwork.delete' [retry 1/60] 2019-08-08 09:33:56.018 CFY <gcp> [subnet_v908s0] Deleted node instance 2019-08-08 09:33:56.395 CFY <gcp> [network_oi7w7q] Stopping node instance 2019-08-08 09:33:56.467 CFY <gcp> [network_oi7w7q] Validating node instance after deletion: nothing to do 2019-08-08 09:33:56.587 CFY <gcp> [network_oi7w7q] Stopped node instance: nothing to do 2019-08-08 09:33:56.881 CFY <gcp> [network_oi7w7q] Unlinking relationships 2019-08-08 09:33:57.153 CFY <gcp> [network_oi7w7q] Relationships unlinked 2019-08-08 09:33:57.415 CFY <gcp> [network_oi7w7q] Deleting node instance 2019-08-08 09:33:57.598 CFY <gcp> [network_oi7w7q.delete] Sending task 'cloudify_gcp.compute.network.delete' 2019-08-08 09:33:59.877 LOG <gcp> [network_oi7w7q.delete] INFO: Delete network network-oi7w7q 2019-08-08 09:34:02.143 CFY <gcp> [network_oi7w7q.delete] Task rescheduled 'cloudify_gcp.compute.network.delete' -> Operation started Traceback (most recent call last): File "/opt/mgmtworker/env/lib/python2.7/site-packages/cloudify/dispatch.py", line 813, in main payload = handler.handle() File "/opt/mgmtworker/env/lib/python2.7/site-packages/cloudify/dispatch.py", line 464, in handle raise ctx.operation._operation_retry OperationRetry: Operation started 2019-08-08 09:34:17.290 CFY <gcp> [network_oi7w7q.delete] Sending task 'cloudify_gcp.compute.network.delete' [retry 1/60] 2019-08-08 09:34:21.431 CFY <gcp> [network_oi7w7q.delete] Task rescheduled 'cloudify_gcp.compute.network.delete' -> Operation not completed yet: RUNNING [retry_after=30] [retry 1/60] Traceback (most recent call last): File "/opt/mgmtworker/env/lib/python2.7/site-packages/cloudify/dispatch.py", line 813, in main payload = handler.handle() File "/opt/mgmtworker/env/lib/python2.7/site-packages/cloudify/dispatch.py", line 464, in handle raise ctx.operation._operation_retry OperationRetry: Operation not completed yet: RUNNING [retry_after=30] 2019-08-08 09:34:51.521 CFY <gcp> [network_oi7w7q.delete] Sending task 'cloudify_gcp.compute.network.delete' [retry 2/60] 2019-08-08 09:34:55.385 CFY <gcp> [network_oi7w7q.delete] Task succeeded 'cloudify_gcp.compute.network.delete' [retry 2/60] 2019-08-08 09:34:55.474 CFY <gcp> [network_oi7w7q] Deleted node instance 2019-08-08 09:34:56.068 CFY <gcp> 'uninstall' workflow execution succeeded Finished executing workflow uninstall on deployment gcp cloudify common logs monitors play_test.sh README.md reset_test.sh results stop_test.sh temp_count temp_cpu_amount temp_io_amount temp_mem_amount temp_mem_initial temp_mem_total temp_monitor_pid temp_net_amount terraform Run 'cfy events list 04db6fdb-13f6-4b01-864f-8973cc1227c2' to retrieve the execution's events/logs Trying to delete deployment gcp... Deployment deleted Deleting blueprint cloudify-wordpress-blueprint-gcp... Blueprint deleted Trying to delete deployment gcp... An error occurred on the server: 404: Requested `Deployment` with ID `gcp` was not found Deleting blueprint cloudify-wordpress-blueprint-gcp... An error occurred on the server: 404: Requested `Blueprint` with ID `cloudify-wordpress-blueprint-gcp` was not found'
