Executing workflow `uninstall` on deployment `gcp` [timeout=900 seconds]
2019-08-09 04:27:20.269  CFY <gcp> Starting 'uninstall' workflow execution
2019-08-09 04:27:21.315  CFY <gcp> [config-wordpress_r0djso] Validating node instance after deletion: nothing to do
2019-08-09 04:27:21.537  CFY <gcp> [config-wordpress_r0djso->vm-app2_gpmnxi|unlink] Sending task 'cloudify_ansible.tasks.ansible_remove_host'
2019-08-09 04:27:22.455  CFY <gcp> [firewall_gvkww0] Validating node instance after deletion: nothing to do
2019-08-09 04:27:22.625  CFY <gcp> [config-database_y4x9ss->vm-database_pca2bh|unlink] Sending task 'cloudify_ansible.tasks.ansible_remove_host'
2019-08-09 04:27:23.500  CFY <gcp> [config-database_y4x9ss] Validating node instance after deletion: nothing to do
2019-08-09 04:27:23.735  CFY <gcp> [firewall_gvkww0] Stop: instance already uninitialized
2019-08-09 04:27:23.862  CFY <gcp> [config-wordpress_r0djso] Stop: instance already uninitialized
2019-08-09 04:27:24.012  CFY <gcp> [config-database_y4x9ss] Stop: instance already uninitialized
2019-08-09 04:27:24.966  CFY <gcp> Task failed '_SetNodeInstanceStateTask' -> 409: Node instance update conflict [current version=2, update version=1]
Traceback (most recent call last):
  File "/opt/mgmtworker/env/lib/python2.7/site-packages/cloudify/workflows/tasks.py", line 709, in local_task_wrapper
    result = self.local_task(**self.kwargs)
  File "/opt/mgmtworker/env/lib/python2.7/site-packages/cloudify/workflows/tasks.py", line 1019, in __call__
    return self.remote()
  File "/opt/mgmtworker/env/lib/python2.7/site-packages/cloudify/workflows/tasks.py", line 1055, in remote
    update_node_instance(node_instance)
  File "/opt/mgmtworker/env/lib/python2.7/site-packages/cloudify/manager.py", line 389, in update_node_instance
    version=node_instance.version)
  File "/opt/mgmtworker/env/lib/python2.7/site-packages/cloudify_rest_client/node_instances.py", line 141, in update
    response = self.api.patch(uri, data=data)
  File "/opt/mgmtworker/env/lib/python2.7/site-packages/cloudify_rest_client/client.py", line 311, in patch
    timeout=timeout)
  File "/opt/mgmtworker/env/lib/python2.7/site-packages/cloudify/cluster.py", line 57, in do_request
    **kwargs)
  File "/opt/mgmtworker/env/lib/python2.7/site-packages/cloudify_rest_client/client.py", line 257, in do_request
    verify=self.get_request_verify(), timeout=timeout)
  File "/opt/mgmtworker/env/lib/python2.7/site-packages/cloudify_rest_client/client.py", line 191, in _do_request
    self._raise_client_error(response, request_url)
  File "/opt/mgmtworker/env/lib/python2.7/site-packages/cloudify_rest_client/client.py", line 144, in _raise_client_error
    response=response)
  File "/opt/mgmtworker/env/lib/python2.7/site-packages/cloudify_rest_client/client.py", line 156, in _prepare_and_raise_exception
    status_code, error_code=error_code, response=response)
CloudifyClientError: 409: Node instance update conflict [current version=2, update version=1]

2019-08-09 04:27:25.333  CFY <gcp> [firewall_gvkww0] Delete: instance already uninitialized
2019-08-09 04:27:25.497  CFY <gcp> [config-wordpress_r0djso] Delete: instance already uninitialized
2019-08-09 04:27:25.625  CFY <gcp> [config-database_y4x9ss] Delete: instance already uninitialized
2019-08-09 04:27:25.744  CFY <gcp> [firewall_gvkww0] Deleted node instance
2019-08-09 04:27:25.896  CFY <gcp> [config-wordpress_r0djso->vm-app2_gpmnxi|unlink] Task succeeded 'cloudify_ansible.tasks.ansible_remove_host'
2019-08-09 04:27:26.325  CFY <gcp> [config-wordpress_r0djso->vm-app1_q27kgj|unlink] Sending task 'cloudify_ansible.tasks.ansible_remove_host'
2019-08-09 04:27:26.376  CFY <gcp> [config-wordpress_r0djso] Deleted node instance
2019-08-09 04:27:27.345  CFY <gcp> [config-database_y4x9ss] Deleted node instance
2019-08-09 04:27:27.991  CFY <gcp> [config-database_y4x9ss->vm-database_pca2bh|unlink] Task failed 'cloudify_ansible.tasks.ansible_remove_host' -> 409: Node instance update conflict [current version=3, update version=2]
Traceback (most recent call last):
  File "/opt/mgmtworker/env/lib/python2.7/site-packages/cloudify/dispatch.py", line 813, in main
    payload = handler.handle()
  File "/opt/mgmtworker/env/lib/python2.7/site-packages/cloudify/dispatch.py", line 461, in handle
    result = self._run_operation_func(ctx, kwargs)
  File "/opt/mgmtworker/env/lib/python2.7/site-packages/cloudify/dispatch.py", line 524, in _run_operation_func
    ctx.source.instance.update()
  File "/opt/mgmtworker/env/lib/python2.7/site-packages/cloudify/context.py", line 414, in update
    self._endpoint.update_node_instance(self._node_instance)
  File "/opt/mgmtworker/env/lib/python2.7/site-packages/cloudify/endpoint.py", line 177, in update_node_instance
    return manager.update_node_instance(node_instance)
  File "/opt/mgmtworker/env/lib/python2.7/site-packages/cloudify/manager.py", line 389, in update_node_instance
    version=node_instance.version)
  File "/opt/mgmtworker/env/lib/python2.7/site-packages/cloudify_rest_client/node_instances.py", line 141, in update
    response = self.api.patch(uri, data=data)
  File "/opt/mgmtworker/env/lib/python2.7/site-packages/cloudify_rest_client/client.py", line 311, in patch
    timeout=timeout)
  File "/opt/mgmtworker/env/lib/python2.7/site-packages/cloudify/cluster.py", line 57, in do_request
    **kwargs)
  File "/opt/mgmtworker/env/lib/python2.7/site-packages/cloudify_rest_client/client.py", line 257, in do_request
    verify=self.get_request_verify(), timeout=timeout)
  File "/opt/mgmtworker/env/lib/python2.7/site-packages/cloudify_rest_client/client.py", line 191, in _do_request
    self._raise_client_error(response, request_url)
  File "/opt/mgmtworker/env/lib/python2.7/site-packages/cloudify_rest_client/client.py", line 144, in _raise_client_error
    response=response)
  File "/opt/mgmtworker/env/lib/python2.7/site-packages/cloudify_rest_client/client.py", line 156, in _prepare_and_raise_exception
    status_code, error_code=error_code, response=response)
CloudifyClientError: 409: Node instance update conflict [current version=3, update version=2]

2019-08-09 04:27:29.242  CFY <gcp> [config-wordpress_r0djso->vm-app1_q27kgj|unlink] Task succeeded 'cloudify_ansible.tasks.ansible_remove_host'
2019-08-09 04:27:29.685  CFY <gcp> [vm-app1_q27kgj] Validating node instance after deletion: nothing to do
2019-08-09 04:27:29.817  CFY <gcp> [vm-app2_gpmnxi] Validating node instance after deletion: nothing to do
2019-08-09 04:27:30.170  CFY <gcp> [vm-app2_gpmnxi] Stop: instance already uninitialized
2019-08-09 04:27:30.258  CFY <gcp> [vm-app1_q27kgj] Stop: instance already uninitialized
2019-08-09 04:27:30.683  CFY <gcp> [vm-app1_q27kgj] Delete: instance already uninitialized
2019-08-09 04:27:30.750  CFY <gcp> [vm-app1_q27kgj] Deleted node instance
2019-08-09 04:27:30.809  CFY <gcp> [vm-app2_gpmnxi] Delete: instance already uninitialized
2019-08-09 04:27:31.027  CFY <gcp> [vm-app2_gpmnxi] Deleted node instance
2019-08-09 04:27:31.602  CFY <gcp> [vm-database_pca2bh] Validating node instance after deletion: nothing to do
2019-08-09 04:27:31.695  CFY <gcp> [vm-database_pca2bh] Stop: instance already uninitialized
2019-08-09 04:27:31.998  CFY <gcp> [vm-database_pca2bh] Delete: instance already uninitialized
2019-08-09 04:27:32.317  CFY <gcp> [vm-database_pca2bh] Deleted node instance
2019-08-09 04:27:32.643  CFY <gcp> [subnet_ld36lr] Validating node instance after deletion: nothing to do
2019-08-09 04:27:32.851  CFY <gcp> [subnet_ld36lr] Stop: instance already uninitialized
2019-08-09 04:27:33.154  CFY <gcp> [subnet_ld36lr] Delete: instance already uninitialized
2019-08-09 04:27:33.233  CFY <gcp> [subnet_ld36lr] Deleted node instance
2019-08-09 04:27:34.169  CFY <gcp> [network_5a649m] Stopping node instance
2019-08-09 04:27:34.339  CFY <gcp> [network_5a649m] Validating node instance after deletion: nothing to do
2019-08-09 04:27:34.414  CFY <gcp> [network_5a649m] Stopped node instance: nothing to do
2019-08-09 04:27:34.724  CFY <gcp> [network_5a649m] Unlinking relationships
2019-08-09 04:27:35.008  CFY <gcp> [network_5a649m] Relationships unlinked
2019-08-09 04:27:35.225  CFY <gcp> [network_5a649m] Deleting node instance
2019-08-09 04:27:35.444  CFY <gcp> [network_5a649m.delete] Sending task 'cloudify_gcp.compute.network.delete'
2019-08-09 04:27:37.615  LOG <gcp> [network_5a649m.delete] INFO: Delete network network-5a649m
2019-08-09 04:27:40.222  LOG <gcp> [network_5a649m.delete] ERROR: Error traceback Traceback (most recent call last):
  File "/opt/mgmtworker/env/plugins/default_tenant/cloudify-gcp-plugin-1.4.4/lib/python2.7/site-packages/cloudify_gcp/utils.py", line 262, in _decorator
    return func(*args, **kwargs)
  File "/opt/mgmtworker/env/plugins/default_tenant/cloudify-gcp-plugin-1.4.4/lib/python2.7/site-packages/cloudify_gcp/compute/network.py", line 215, in delete
    utils.delete_if_not_external(network)
  File "/opt/mgmtworker/env/plugins/default_tenant/cloudify-gcp-plugin-1.4.4/lib/python2.7/site-packages/cloudify_gcp/utils.py", line 175, in delete_if_not_external
    return resource.delete()
  File "/opt/mgmtworker/env/plugins/default_tenant/cloudify-gcp-plugin-1.4.4/lib/python2.7/site-packages/cloudify_gcp/utils.py", line 233, in wrapper
    response = func(self, *args, **kwargs)
  File "/opt/mgmtworker/env/plugins/default_tenant/cloudify-gcp-plugin-1.4.4/lib/python2.7/site-packages/cloudify_gcp/gcp.py", line 34, in _decorator
    response = func(self, *args, **kwargs)
  File "/opt/mgmtworker/env/plugins/default_tenant/cloudify-gcp-plugin-1.4.4/lib/python2.7/site-packages/cloudify_gcp/compute/network.py", line 80, in delete
    network=self.name).execute()
  File "/opt/mgmtworker/env/plugins/default_tenant/cloudify-gcp-plugin-1.4.4/lib/python2.7/site-packages/oauth2client/util.py", line 137, in positional_wrapper
    return wrapped(*args, **kwargs)
  File "/opt/mgmtworker/env/plugins/default_tenant/cloudify-gcp-plugin-1.4.4/lib/python2.7/site-packages/googleapiclient/http.py", line 832, in execute
    raise HttpError(resp, content, uri=self.uri)
HttpError: <HttpError 404 when requesting https://www.googleapis.com/compute/v1/projects/node2faas-248113/global/networks/network-5a649m?alt=json returned "The resource 'projects/node2faas-248113/global/networks/network-5a649m' was not found">
 with message <HttpError 404 when requesting https://www.googleapis.com/compute/v1/projects/node2faas-248113/global/networks/network-5a649m?alt=json returned "The resource 'projects/node2faas-248113/global/networks/network-5a649m' was not found">
2019-08-09 04:27:40.222  LOG <gcp> [network_5a649m.delete] ERROR: Error Message 
2019-08-09 04:27:40.881  CFY <gcp> [network_5a649m.delete] Task failed 'cloudify_gcp.compute.network.delete'
Traceback (most recent call last):
  File "/opt/mgmtworker/env/lib/python2.7/site-packages/cloudify/dispatch.py", line 813, in main
    payload = handler.handle()
  File "/opt/mgmtworker/env/lib/python2.7/site-packages/cloudify/dispatch.py", line 461, in handle
    result = self._run_operation_func(ctx, kwargs)
  File "/opt/mgmtworker/env/lib/python2.7/site-packages/cloudify/dispatch.py", line 519, in _run_operation_func
    return self.func(*self.args, **kwargs)
  File "/opt/mgmtworker/env/plugins/default_tenant/cloudify-gcp-plugin-1.4.4/lib/python2.7/site-packages/cloudify_gcp/utils.py", line 277, in _decorator
    raise NonRecoverableError(error.message)
NonRecoverableError

2019-08-09 04:27:41.054  CFY <gcp> [network_5a649m] Deleted node instance
2019-08-09 04:27:41.674  CFY <gcp> 'uninstall' workflow execution succeeded
Finished executing workflow uninstall on deployment gcp
* Run 'cfy events list ee6b2b8b-8f39-4583-9830-ae237cd3e5f0' to retrieve the execution's events/logs
Trying to delete deployment gcp...
Deployment deleted
Deleting blueprint cloudify-wordpress-blueprint-gcp...
Blueprint deleted
