Uploading blueprint cloudify/gcp.yaml...
 gcp.yaml |############################################################| 100.0%
Blueprint uploaded. The blueprint's id is cloudify-wordpress-blueprint-gcp
Creating new deployment from blueprint cloudify-wordpress-blueprint-gcp...
Deployment created. The deployment's id is gcp
Executing workflow `install` on deployment `gcp` [timeout=900 seconds]
Deployment environment creation is pending...
2019-08-10 15:54:43.040  CFY <gcp> Starting 'create_deployment_environment' workflow execution
2019-08-10 15:54:43.044  CFY <gcp> Installing deployment and workflow plugins
2019-08-10 15:54:43.144  CFY <gcp> Sending task 'cloudify_agent.operations.install_plugins'
2019-08-10 15:54:43.160  CFY <gcp> Task started 'cloudify_agent.operations.install_plugins'
2019-08-10 15:54:43.476  LOG <gcp> INFO: Installing plugin: gcp_plugin
2019-08-10 15:54:44.307  LOG <gcp> INFO: Using existing installation of managed plugin: e0a99ba4-54d6-4741-a773-4ec378dc8634 [package_name: cloudify-gcp-plugin, package_version: 1.4.4, supported_platform: linux_x86_64, distribution: centos, distribution_release: core]
2019-08-10 15:54:44.307  LOG <gcp> INFO: Installing plugin: ansible
2019-08-10 15:54:45.353  LOG <gcp> INFO: Using existing installation of managed plugin: 7142c593-6e52-429a-8a71-55266c022e02 [package_name: cloudify-ansible-plugin, package_version: 2.4.0, supported_platform: linux_x86_64, distribution: centos, distribution_release: core]
2019-08-10 15:54:45.353  LOG <gcp> INFO: Installing plugin: suspend
2019-08-10 15:54:46.342  LOG <gcp> INFO: Using existing installation of managed plugin: 62c3cd35-5a18-49fd-a670-48f9ad207b05 [package_name: cloudify-utilities-plugin, package_version: 1.14.0, supported_platform: linux_x86_64, distribution: centos, distribution_release: core]
2019-08-10 15:54:46.342  LOG <gcp> INFO: Installing plugin: configuration
2019-08-10 15:54:47.335  LOG <gcp> INFO: Using existing installation of managed plugin: 62c3cd35-5a18-49fd-a670-48f9ad207b05 [package_name: cloudify-utilities-plugin, package_version: 1.14.0, supported_platform: linux_x86_64, distribution: centos, distribution_release: core]
2019-08-10 15:54:47.335  LOG <gcp> INFO: Installing plugin: scalelist
2019-08-10 15:54:48.175  CFY <gcp> Task succeeded 'cloudify_agent.operations.install_plugins'
2019-08-10 15:54:48.175  LOG <gcp> INFO: Using existing installation of managed plugin: 62c3cd35-5a18-49fd-a670-48f9ad207b05 [package_name: cloudify-utilities-plugin, package_version: 1.14.0, supported_platform: linux_x86_64, distribution: centos, distribution_release: core]
2019-08-10 15:54:48.208  CFY <gcp> Creating deployment work directory
2019-08-10 15:54:48.487  CFY <gcp> 'create_deployment_environment' workflow execution succeeded
2019-08-10 15:54:54.281  CFY <gcp> Starting 'install' workflow execution
2019-08-10 15:54:55.786  CFY <gcp> [network_6wq3sh] Validating node instance before creation: nothing to do
2019-08-10 15:54:55.912  CFY <gcp> [network_6wq3sh] Precreating node instance: nothing to do
2019-08-10 15:54:56.163  CFY <gcp> [network_6wq3sh] Creating node instance
2019-08-10 15:54:56.358  CFY <gcp> [network_6wq3sh.create] Sending task 'cloudify_gcp.compute.network.create'
2019-08-10 15:54:58.215  LOG <gcp> [network_6wq3sh.create] INFO: Create network network-6wq3sh
2019-08-10 15:55:00.814  CFY <gcp> [network_6wq3sh.create] Task rescheduled 'cloudify_gcp.compute.network.create' -> Operation started
Traceback (most recent call last):
  File "/opt/mgmtworker/env/lib/python2.7/site-packages/cloudify/dispatch.py", line 813, in main
    payload = handler.handle()
  File "/opt/mgmtworker/env/lib/python2.7/site-packages/cloudify/dispatch.py", line 464, in handle
    raise ctx.operation._operation_retry
OperationRetry: Operation started

2019-08-10 15:55:15.945  CFY <gcp> [network_6wq3sh.create] Sending task 'cloudify_gcp.compute.network.create' [retry 1/60]
2019-08-10 15:55:20.405  CFY <gcp> [network_6wq3sh.create] Task rescheduled 'cloudify_gcp.compute.network.create' -> Operation not completed yet: RUNNING [retry_after=30] [retry 1/60]
Traceback (most recent call last):
  File "/opt/mgmtworker/env/lib/python2.7/site-packages/cloudify/dispatch.py", line 813, in main
    payload = handler.handle()
  File "/opt/mgmtworker/env/lib/python2.7/site-packages/cloudify/dispatch.py", line 464, in handle
    raise ctx.operation._operation_retry
OperationRetry: Operation not completed yet: RUNNING [retry_after=30]

2019-08-10 15:55:50.535  CFY <gcp> [network_6wq3sh.create] Sending task 'cloudify_gcp.compute.network.create' [retry 2/60]
2019-08-10 15:55:54.146  LOG <gcp> [network_6wq3sh.create] INFO: Get network network-6wq3sh details
2019-08-10 15:55:55.832  CFY <gcp> [network_6wq3sh.create] Task succeeded 'cloudify_gcp.compute.network.create' [retry 2/60]
2019-08-10 15:55:55.944  CFY <gcp> [network_6wq3sh] Node instance created
2019-08-10 15:55:56.284  CFY <gcp> [network_6wq3sh] Configuring node instance: nothing to do
2019-08-10 15:55:56.348  CFY <gcp> [network_6wq3sh] Starting node instance: nothing to do
2019-08-10 15:55:56.467  CFY <gcp> [network_6wq3sh] Poststarting node instance: nothing to do
2019-08-10 15:55:56.736  CFY <gcp> [network_6wq3sh] Node instance started
2019-08-10 15:55:57.354  CFY <gcp> [firewall_c5ar3h] Validating node instance before creation: nothing to do
2019-08-10 15:55:57.442  CFY <gcp> [firewall_c5ar3h] Precreating node instance: nothing to do
2019-08-10 15:55:57.520  CFY <gcp> [subnet_wu3d57] Validating node instance before creation
2019-08-10 15:55:57.572  CFY <gcp> [firewall_c5ar3h] Creating node instance
2019-08-10 15:55:57.793  CFY <gcp> [subnet_wu3d57.create] Sending task 'cloudify_gcp.compute.subnetwork.creation_validation'
2019-08-10 15:55:58.794  CFY <gcp> [firewall_c5ar3h.create] Sending task 'cloudify_gcp.compute.firewall.create'
2019-08-10 15:56:01.799  LOG <gcp> [firewall_c5ar3h.create] INFO: Create firewall rule firewall-c5ar3h in network https://www.googleapis.com/compute/v1/projects/node2faas-248113/global/networks/network-6wq3sh
2019-08-10 15:56:01.914  CFY <gcp> [subnet_wu3d57.create] Task succeeded 'cloudify_gcp.compute.subnetwork.creation_validation'
2019-08-10 15:56:02.001  CFY <gcp> [subnet_wu3d57] Node instance validated before creation
2019-08-10 15:56:02.236  CFY <gcp> [subnet_wu3d57] Precreating node instance: nothing to do
2019-08-10 15:56:02.312  CFY <gcp> [subnet_wu3d57] Creating node instance
2019-08-10 15:56:02.999  CFY <gcp> [subnet_wu3d57.create] Sending task 'cloudify_gcp.compute.subnetwork.create'
2019-08-10 15:56:04.635  CFY <gcp> [firewall_c5ar3h.create] Task succeeded 'cloudify_gcp.compute.firewall.create'
2019-08-10 15:56:04.968  CFY <gcp> [firewall_c5ar3h] Node instance created
2019-08-10 15:56:05.077  CFY <gcp> [firewall_c5ar3h] Configuring node instance: nothing to do
2019-08-10 15:56:05.282  CFY <gcp> [firewall_c5ar3h] Starting node instance: nothing to do
2019-08-10 15:56:05.397  CFY <gcp> [firewall_c5ar3h] Poststarting node instance: nothing to do
2019-08-10 15:56:05.555  LOG <gcp> [subnet_wu3d57.create] INFO: Create subnetwork subnet-wu3d57
2019-08-10 15:56:06.146  CFY <gcp> [firewall_c5ar3h] Node instance started
2019-08-10 15:56:07.970  CFY <gcp> [subnet_wu3d57.create] Task rescheduled 'cloudify_gcp.compute.subnetwork.create' -> Operation started
Traceback (most recent call last):
  File "/opt/mgmtworker/env/lib/python2.7/site-packages/cloudify/dispatch.py", line 813, in main
    payload = handler.handle()
  File "/opt/mgmtworker/env/lib/python2.7/site-packages/cloudify/dispatch.py", line 464, in handle
    raise ctx.operation._operation_retry
OperationRetry: Operation started

2019-08-10 15:56:23.053  CFY <gcp> [subnet_wu3d57.create] Sending task 'cloudify_gcp.compute.subnetwork.create' [retry 1/60]
2019-08-10 15:56:26.707  LOG <gcp> [subnet_wu3d57.create] INFO: Get subnetwork subnet-wu3d57 details
2019-08-10 15:56:28.366  CFY <gcp> [subnet_wu3d57.create] Task succeeded 'cloudify_gcp.compute.subnetwork.create' [retry 1/60]
2019-08-10 15:56:28.432  CFY <gcp> [subnet_wu3d57] Node instance created
2019-08-10 15:56:28.830  CFY <gcp> [subnet_wu3d57] Configuring node instance: nothing to do
2019-08-10 15:56:29.033  CFY <gcp> [subnet_wu3d57] Starting node instance: nothing to do
2019-08-10 15:56:29.117  CFY <gcp> [subnet_wu3d57] Poststarting node instance: nothing to do
2019-08-10 15:56:29.239  CFY <gcp> [subnet_wu3d57] Node instance started
2019-08-10 15:56:29.849  CFY <gcp> [vm-database_p62a6x] Validating node instance before creation: nothing to do
2019-08-10 15:56:29.965  CFY <gcp> [vm-database_p62a6x] Precreating node instance: nothing to do
2019-08-10 15:56:30.051  CFY <gcp> [vm-database_p62a6x] Creating node instance
2019-08-10 15:56:30.431  CFY <gcp> [vm-database_p62a6x.create] Sending task 'script_runner.tasks.run'
2019-08-10 15:56:32.144  LOG <gcp> [vm-database_p62a6x.create] INFO: Downloaded scripts/gcp/key.py to /tmp/ZSH62/key.py
2019-08-10 15:56:32.887  CFY <gcp> [vm-database_p62a6x.create] Task succeeded 'script_runner.tasks.run'
2019-08-10 15:56:33.266  CFY <gcp> [vm-database_p62a6x] Node instance created
2019-08-10 15:56:33.507  CFY <gcp> [vm-database_p62a6x] Configuring node instance
2019-08-10 15:56:33.707  CFY <gcp> [vm-database_p62a6x.configure] Sending task 'cloudify_gcp.compute.instance.create'
2019-08-10 15:56:35.677  LOG <gcp> [vm-database_p62a6x.configure] INFO: The script is 
2019-08-10 15:56:36.078  LOG <gcp> [vm-database_p62a6x.configure] INFO: Adding bucket to metadata
2019-08-10 15:56:36.079  LOG <gcp> [vm-database_p62a6x.configure] INFO: Adding sshKeys to metadata
2019-08-10 15:56:39.063  CFY <gcp> [vm-database_p62a6x.configure] Task rescheduled 'cloudify_gcp.compute.instance.create' -> Operation started
Traceback (most recent call last):
  File "/opt/mgmtworker/env/lib/python2.7/site-packages/cloudify/dispatch.py", line 813, in main
    payload = handler.handle()
  File "/opt/mgmtworker/env/lib/python2.7/site-packages/cloudify/dispatch.py", line 464, in handle
    raise ctx.operation._operation_retry
OperationRetry: Operation started

2019-08-10 15:56:54.168  CFY <gcp> [vm-database_p62a6x.configure] Sending task 'cloudify_gcp.compute.instance.create' [retry 1/60]
2019-08-10 15:56:56.533  LOG <gcp> [vm-database_p62a6x.configure] INFO: The script is 
2019-08-10 15:56:57.841  LOG <gcp> [vm-database_p62a6x.configure] ERROR: Response with error {u'errors': [{u'message': u"The resource '482761649285-compute@developer.gserviceaccount.com' of type 'serviceAccount' was not found.", u'code': u'EXTERNAL_RESOURCE_NOT_FOUND'}]}
2019-08-10 15:56:57.842  LOG <gcp> [vm-database_p62a6x.configure] ERROR: Error Message {u'errors': [{u'message': u"The resource '482761649285-compute@developer.gserviceaccount.com' of type 'serviceAccount' was not found.", u'code': u'EXTERNAL_RESOURCE_NOT_FOUND'}]}
2019-08-10 15:56:58.308  CFY <gcp> [vm-database_p62a6x.configure] Task failed 'cloudify_gcp.compute.instance.create' -> {u'errors': [{u'message': u"The resource '482761649285-compute@developer.gserviceaccount.com' of type 'serviceAccount' was not found.", u'code': u'EXTERNAL_RESOURCE_NOT_FOUND'}]} [retry 1/60]
Traceback (most recent call last):
  File "/opt/mgmtworker/env/lib/python2.7/site-packages/cloudify/dispatch.py", line 813, in main
    payload = handler.handle()
  File "/opt/mgmtworker/env/lib/python2.7/site-packages/cloudify/dispatch.py", line 461, in handle
    result = self._run_operation_func(ctx, kwargs)
  File "/opt/mgmtworker/env/lib/python2.7/site-packages/cloudify/dispatch.py", line 519, in _run_operation_func
    return self.func(*self.args, **kwargs)
  File "/opt/mgmtworker/env/plugins/default_tenant/cloudify-gcp-plugin-1.4.4/lib/python2.7/site-packages/cloudify_gcp/utils.py", line 267, in _decorator
    raise NonRecoverableError(e.message)
NonRecoverableError: {u'errors': [{u'message': u"The resource '482761649285-compute@developer.gserviceaccount.com' of type 'serviceAccount' was not found.", u'code': u'EXTERNAL_RESOURCE_NOT_FOUND'}]}

2019-08-10 15:56:58.531  CFY <gcp> 'install' workflow execution failed: RuntimeError: Workflow failed: Task failed 'cloudify_gcp.compute.instance.create' -> {u'errors': [{u'message': u"The resource '482761649285-compute@developer.gserviceaccount.com' of type 'serviceAccount' was not found.", u'code': u'EXTERNAL_RESOURCE_NOT_FOUND'}]}
Execution of workflow install for deployment gcp failed. [error=Traceback (most recent call last):
  File "/opt/mgmtworker/env/lib/python2.7/site-packages/cloudify/dispatch.py", line 664, in _remote_workflow_child_thread
    workflow_result = self._execute_workflow_function()
  File "/opt/mgmtworker/env/lib/python2.7/site-packages/cloudify/dispatch.py", line 693, in _execute_workflow_function
    result = self.func(*self.args, **self.kwargs)
  File "/opt/mgmtworker/env/lib/python2.7/site-packages/cloudify/plugins/workflows.py", line 31, in install
    node_instances=set(ctx.node_instances))
  File "/opt/mgmtworker/env/lib/python2.7/site-packages/cloudify/plugins/lifecycle.py", line 29, in install_node_instances
    processor.install()
  File "/opt/mgmtworker/env/lib/python2.7/site-packages/cloudify/plugins/lifecycle.py", line 102, in install
    graph.execute()
  File "/opt/mgmtworker/env/lib/python2.7/site-packages/cloudify/workflows/tasks_graph.py", line 237, in execute
    raise self._error
RuntimeError: Workflow failed: Task failed 'cloudify_gcp.compute.instance.create' -> {u'errors': [{u'message': u"The resource '482761649285-compute@developer.gserviceaccount.com' of type 'serviceAccount' was not found.", u'code': u'EXTERNAL_RESOURCE_NOT_FOUND'}]}
]
* Run 'cfy events list 97b5bff9-d635-4018-8ce1-bff45c989ebc' to retrieve the execution's events/logs
