Uploading blueprint cloudify/gcp.yaml...
 gcp.yaml |############################################################| 100.0%
Blueprint uploaded. The blueprint's id is cloudify-wordpress-blueprint-gcp
Creating new deployment from blueprint cloudify-wordpress-blueprint-gcp...
Deployment created. The deployment's id is gcp
Executing workflow `install` on deployment `gcp` [timeout=900 seconds]
Deployment environment creation is pending...
2019-08-08 07:08:02.497  CFY <gcp> Starting 'create_deployment_environment' workflow execution
2019-08-08 07:08:02.501  CFY <gcp> Installing deployment and workflow plugins
2019-08-08 07:08:02.602  CFY <gcp> Sending task 'cloudify_agent.operations.install_plugins'
2019-08-08 07:08:02.619  CFY <gcp> Task started 'cloudify_agent.operations.install_plugins'
2019-08-08 07:08:02.947  LOG <gcp> INFO: Installing plugin: gcp_plugin
2019-08-08 07:08:03.733  LOG <gcp> INFO: Using existing installation of managed plugin: e0a99ba4-54d6-4741-a773-4ec378dc8634 [package_name: cloudify-gcp-plugin, package_version: 1.4.4, supported_platform: linux_x86_64, distribution: centos, distribution_release: core]
2019-08-08 07:08:03.733  LOG <gcp> INFO: Installing plugin: ansible
2019-08-08 07:08:04.728  LOG <gcp> INFO: Using existing installation of managed plugin: 7142c593-6e52-429a-8a71-55266c022e02 [package_name: cloudify-ansible-plugin, package_version: 2.4.0, supported_platform: linux_x86_64, distribution: centos, distribution_release: core]
2019-08-08 07:08:04.729  LOG <gcp> INFO: Installing plugin: suspend
2019-08-08 07:08:05.743  LOG <gcp> INFO: Using existing installation of managed plugin: 62c3cd35-5a18-49fd-a670-48f9ad207b05 [package_name: cloudify-utilities-plugin, package_version: 1.14.0, supported_platform: linux_x86_64, distribution: centos, distribution_release: core]
2019-08-08 07:08:05.743  LOG <gcp> INFO: Installing plugin: configuration
2019-08-08 07:08:06.609  LOG <gcp> INFO: Using existing installation of managed plugin: 62c3cd35-5a18-49fd-a670-48f9ad207b05 [package_name: cloudify-utilities-plugin, package_version: 1.14.0, supported_platform: linux_x86_64, distribution: centos, distribution_release: core]
2019-08-08 07:08:06.609  LOG <gcp> INFO: Installing plugin: scalelist
2019-08-08 07:08:07.395  LOG <gcp> INFO: Using existing installation of managed plugin: 62c3cd35-5a18-49fd-a670-48f9ad207b05 [package_name: cloudify-utilities-plugin, package_version: 1.14.0, supported_platform: linux_x86_64, distribution: centos, distribution_release: core]
2019-08-08 07:08:07.396  CFY <gcp> Task succeeded 'cloudify_agent.operations.install_plugins'
2019-08-08 07:08:07.465  CFY <gcp> Creating deployment work directory
2019-08-08 07:08:07.773  CFY <gcp> 'create_deployment_environment' workflow execution succeeded
2019-08-08 07:08:10.690  CFY <gcp> Starting 'install' workflow execution
2019-08-08 07:08:12.200  CFY <gcp> [network_knvnrs] Validating node instance before creation: nothing to do
2019-08-08 07:08:12.260  CFY <gcp> [network_knvnrs] Precreating node instance: nothing to do
2019-08-08 07:08:12.378  CFY <gcp> [network_knvnrs] Creating node instance
2019-08-08 07:08:12.725  CFY <gcp> [network_knvnrs.create] Sending task 'cloudify_gcp.compute.network.create'
2019-08-08 07:08:14.782  LOG <gcp> [network_knvnrs.create] INFO: Create network network-knvnrs
2019-08-08 07:08:17.805  CFY <gcp> [network_knvnrs.create] Task rescheduled 'cloudify_gcp.compute.network.create' -> Operation started
Traceback (most recent call last):
  File "/opt/mgmtworker/env/lib/python2.7/site-packages/cloudify/dispatch.py", line 813, in main
    payload = handler.handle()
  File "/opt/mgmtworker/env/lib/python2.7/site-packages/cloudify/dispatch.py", line 464, in handle
    raise ctx.operation._operation_retry
OperationRetry: Operation started

2019-08-08 07:08:32.873  CFY <gcp> [network_knvnrs.create] Sending task 'cloudify_gcp.compute.network.create' [retry 1/60]
2019-08-08 07:08:36.119  LOG <gcp> [network_knvnrs.create] INFO: Get network network-knvnrs details
2019-08-08 07:08:37.567  CFY <gcp> [network_knvnrs.create] Task succeeded 'cloudify_gcp.compute.network.create' [retry 1/60]
2019-08-08 07:08:37.664  CFY <gcp> [network_knvnrs] Node instance created
2019-08-08 07:08:37.873  CFY <gcp> [network_knvnrs] Configuring node instance: nothing to do
2019-08-08 07:08:37.989  CFY <gcp> [network_knvnrs] Starting node instance: nothing to do
2019-08-08 07:08:38.074  CFY <gcp> [network_knvnrs] Poststarting node instance: nothing to do
2019-08-08 07:08:38.372  CFY <gcp> [network_knvnrs] Node instance started
2019-08-08 07:08:39.421  CFY <gcp> [firewall_2ntgwz] Validating node instance before creation: nothing to do
2019-08-08 07:08:39.493  CFY <gcp> [subnet_hlc0y2] Validating node instance before creation
2019-08-08 07:08:39.558  CFY <gcp> [firewall_2ntgwz] Precreating node instance: nothing to do
2019-08-08 07:08:39.687  CFY <gcp> [subnet_hlc0y2.create] Sending task 'cloudify_gcp.compute.subnetwork.creation_validation'
2019-08-08 07:08:40.635  CFY <gcp> [firewall_2ntgwz] Creating node instance
2019-08-08 07:08:41.137  CFY <gcp> [firewall_2ntgwz.create] Sending task 'cloudify_gcp.compute.firewall.create'
2019-08-08 07:08:42.441  CFY <gcp> [subnet_hlc0y2.create] Task succeeded 'cloudify_gcp.compute.subnetwork.creation_validation'
2019-08-08 07:08:42.456  CFY <gcp> [subnet_hlc0y2] Node instance validated before creation
2019-08-08 07:08:42.674  CFY <gcp> [subnet_hlc0y2] Precreating node instance: nothing to do
2019-08-08 07:08:43.164  CFY <gcp> [subnet_hlc0y2] Creating node instance
2019-08-08 07:08:43.395  CFY <gcp> [subnet_hlc0y2.create] Sending task 'cloudify_gcp.compute.subnetwork.create'
2019-08-08 07:08:43.816  LOG <gcp> [firewall_2ntgwz.create] INFO: Create firewall rule firewall-2ntgwz in network https://www.googleapis.com/compute/v1/projects/node2faas-248113/global/networks/network-knvnrs
2019-08-08 07:08:45.464  LOG <gcp> [subnet_hlc0y2.create] INFO: Create subnetwork subnet-hlc0y2
2019-08-08 07:08:46.460  CFY <gcp> [firewall_2ntgwz.create] Task succeeded 'cloudify_gcp.compute.firewall.create'
2019-08-08 07:08:46.719  CFY <gcp> [firewall_2ntgwz] Node instance created
2019-08-08 07:08:46.840  CFY <gcp> [firewall_2ntgwz] Configuring node instance: nothing to do
2019-08-08 07:08:46.958  CFY <gcp> [firewall_2ntgwz] Starting node instance: nothing to do
2019-08-08 07:08:47.070  CFY <gcp> [firewall_2ntgwz] Poststarting node instance: nothing to do
2019-08-08 07:08:47.620  CFY <gcp> [firewall_2ntgwz] Node instance started
2019-08-08 07:08:48.338  CFY <gcp> [subnet_hlc0y2.create] Task rescheduled 'cloudify_gcp.compute.subnetwork.create' -> Operation started
Traceback (most recent call last):
  File "/opt/mgmtworker/env/lib/python2.7/site-packages/cloudify/dispatch.py", line 813, in main
    payload = handler.handle()
  File "/opt/mgmtworker/env/lib/python2.7/site-packages/cloudify/dispatch.py", line 464, in handle
    raise ctx.operation._operation_retry
OperationRetry: Operation started

2019-08-08 07:09:03.575  CFY <gcp> [subnet_hlc0y2.create] Sending task 'cloudify_gcp.compute.subnetwork.create' [retry 1/60]
2019-08-08 07:09:07.092  LOG <gcp> [subnet_hlc0y2.create] INFO: Get subnetwork subnet-hlc0y2 details
2019-08-08 07:09:08.811  CFY <gcp> [subnet_hlc0y2.create] Task succeeded 'cloudify_gcp.compute.subnetwork.create' [retry 1/60]
2019-08-08 07:09:08.827  CFY <gcp> [subnet_hlc0y2] Node instance created
2019-08-08 07:09:09.242  CFY <gcp> [subnet_hlc0y2] Configuring node instance: nothing to do
2019-08-08 07:09:09.443  CFY <gcp> [subnet_hlc0y2] Starting node instance: nothing to do
2019-08-08 07:09:09.565  CFY <gcp> [subnet_hlc0y2] Poststarting node instance: nothing to do
2019-08-08 07:09:09.639  CFY <gcp> [subnet_hlc0y2] Node instance started
2019-08-08 07:09:10.365  CFY <gcp> [vm-database_6jdlr7] Validating node instance before creation: nothing to do
2019-08-08 07:09:10.456  CFY <gcp> [vm-database_6jdlr7] Precreating node instance: nothing to do
2019-08-08 07:09:10.575  CFY <gcp> [vm-database_6jdlr7] Creating node instance
2019-08-08 07:09:10.914  CFY <gcp> [vm-database_6jdlr7.create] Sending task 'script_runner.tasks.run'
2019-08-08 07:09:12.862  LOG <gcp> [vm-database_6jdlr7.create] INFO: Downloaded scripts/gcp/key.py to /tmp/A13LC/key.py
2019-08-08 07:09:13.380  CFY <gcp> [vm-database_6jdlr7.create] Task succeeded 'script_runner.tasks.run'
2019-08-08 07:09:13.458  CFY <gcp> [vm-database_6jdlr7] Node instance created
2019-08-08 07:09:13.954  CFY <gcp> [vm-database_6jdlr7] Configuring node instance
2019-08-08 07:09:14.115  CFY <gcp> [vm-database_6jdlr7.configure] Sending task 'cloudify_gcp.compute.instance.create'
2019-08-08 07:09:16.400  LOG <gcp> [vm-database_6jdlr7.configure] INFO: The script is 
2019-08-08 07:09:16.676  LOG <gcp> [vm-database_6jdlr7.configure] INFO: Adding bucket to metadata
2019-08-08 07:09:16.676  LOG <gcp> [vm-database_6jdlr7.configure] INFO: Adding sshKeys to metadata
2019-08-08 07:09:19.459  CFY <gcp> [vm-database_6jdlr7.configure] Task rescheduled 'cloudify_gcp.compute.instance.create' -> Operation started
Traceback (most recent call last):
  File "/opt/mgmtworker/env/lib/python2.7/site-packages/cloudify/dispatch.py", line 813, in main
    payload = handler.handle()
  File "/opt/mgmtworker/env/lib/python2.7/site-packages/cloudify/dispatch.py", line 464, in handle
    raise ctx.operation._operation_retry
OperationRetry: Operation started

2019-08-08 07:09:34.589  CFY <gcp> [vm-database_6jdlr7.configure] Sending task 'cloudify_gcp.compute.instance.create' [retry 1/60]
2019-08-08 07:09:37.072  LOG <gcp> [vm-database_6jdlr7.configure] INFO: The script is 
2019-08-08 07:09:38.638  LOG <gcp> [vm-database_6jdlr7.configure] ERROR: Response with error {u'errors': [{u'message': u"The resource '482761649285-compute@developer.gserviceaccount.com' of type 'serviceAccount' was not found.", u'code': u'EXTERNAL_RESOURCE_NOT_FOUND'}]}
2019-08-08 07:09:38.638  LOG <gcp> [vm-database_6jdlr7.configure] ERROR: Error Message {u'errors': [{u'message': u"The resource '482761649285-compute@developer.gserviceaccount.com' of type 'serviceAccount' was not found.", u'code': u'EXTERNAL_RESOURCE_NOT_FOUND'}]}
2019-08-08 07:09:39.718  CFY <gcp> [vm-database_6jdlr7.configure] Task failed 'cloudify_gcp.compute.instance.create' -> {u'errors': [{u'message': u"The resource '482761649285-compute@developer.gserviceaccount.com' of type 'serviceAccount' was not found.", u'code': u'EXTERNAL_RESOURCE_NOT_FOUND'}]} [retry 1/60]
Traceback (most recent call last):
  File "/opt/mgmtworker/env/lib/python2.7/site-packages/cloudify/dispatch.py", line 813, in main
    payload = handler.handle()
  File "/opt/mgmtworker/env/lib/python2.7/site-packages/cloudify/dispatch.py", line 461, in handle
    result = self._run_operation_func(ctx, kwargs)
  File "/opt/mgmtworker/env/lib/python2.7/site-packages/cloudify/dispatch.py", line 519, in _run_operation_func
    return self.func(*self.args, **kwargs)
  File "/opt/mgmtworker/env/plugins/default_tenant/cloudify-gcp-plugin-1.4.4/lib/python2.7/site-packages/cloudify_gcp/utils.py", line 267, in _decorator
    raise NonRecoverableError(e.message)
NonRecoverableError: {u'errors': [{u'message': u"The resource '482761649285-compute@developer.gserviceaccount.com' of type 'serviceAccount' was not found.", u'code': u'EXTERNAL_RESOURCE_NOT_FOUND'}]}

2019-08-08 07:09:40.254  CFY <gcp> 'install' workflow execution failed: RuntimeError: Workflow failed: Task failed 'cloudify_gcp.compute.instance.create' -> {u'errors': [{u'message': u"The resource '482761649285-compute@developer.gserviceaccount.com' of type 'serviceAccount' was not found.", u'code': u'EXTERNAL_RESOURCE_NOT_FOUND'}]}
Execution of workflow install for deployment gcp failed. [error=Traceback (most recent call last):
  File "/opt/mgmtworker/env/lib/python2.7/site-packages/cloudify/dispatch.py", line 664, in _remote_workflow_child_thread
    workflow_result = self._execute_workflow_function()
  File "/opt/mgmtworker/env/lib/python2.7/site-packages/cloudify/dispatch.py", line 693, in _execute_workflow_function
    result = self.func(*self.args, **self.kwargs)
  File "/opt/mgmtworker/env/lib/python2.7/site-packages/cloudify/plugins/workflows.py", line 31, in install
    node_instances=set(ctx.node_instances))
  File "/opt/mgmtworker/env/lib/python2.7/site-packages/cloudify/plugins/lifecycle.py", line 29, in install_node_instances
    processor.install()
  File "/opt/mgmtworker/env/lib/python2.7/site-packages/cloudify/plugins/lifecycle.py", line 102, in install
    graph.execute()
  File "/opt/mgmtworker/env/lib/python2.7/site-packages/cloudify/workflows/tasks_graph.py", line 237, in execute
    raise self._error
RuntimeError: Workflow failed: Task failed 'cloudify_gcp.compute.instance.create' -> {u'errors': [{u'message': u"The resource '482761649285-compute@developer.gserviceaccount.com' of type 'serviceAccount' was not found.", u'code': u'EXTERNAL_RESOURCE_NOT_FOUND'}]}
]
* Run 'cfy events list 499aa5cd-3e0d-4bde-bd85-5a3c867083cb' to retrieve the execution's events/logs
'Executing workflow `uninstall` on deployment `gcp` [timeout=900 seconds] An error occurred on the server: 404: Requested `Deployment` with ID `gcp` was not found Trying to delete deployment gcp... An error occurred on the server: 404: Requested `Deployment` with ID `gcp` was not found Deleting blueprint cloudify-wordpress-blueprint-gcp... An error occurred on the server: 404: Requested `Blueprint` with ID `cloudify-wordpress-blueprint-gcp` was not found'
