Uploading blueprint cloudify/gcp.yaml...
 gcp.yaml |############################################################| 100.0%
Blueprint uploaded. The blueprint's id is cloudify-wordpress-blueprint-gcp
Creating new deployment from blueprint cloudify-wordpress-blueprint-gcp...
Deployment created. The deployment's id is gcp
Executing workflow `install` on deployment `gcp` [timeout=900 seconds]
Deployment environment creation is pending...
2019-08-08 07:17:09.419  CFY <gcp> Starting 'create_deployment_environment' workflow execution
2019-08-08 07:17:09.437  CFY <gcp> Installing deployment and workflow plugins
2019-08-08 07:17:09.538  CFY <gcp> Sending task 'cloudify_agent.operations.install_plugins'
2019-08-08 07:17:09.574  CFY <gcp> Task started 'cloudify_agent.operations.install_plugins'
2019-08-08 07:17:09.912  LOG <gcp> INFO: Installing plugin: gcp_plugin
2019-08-08 07:17:10.693  LOG <gcp> INFO: Using existing installation of managed plugin: e0a99ba4-54d6-4741-a773-4ec378dc8634 [package_name: cloudify-gcp-plugin, package_version: 1.4.4, supported_platform: linux_x86_64, distribution: centos, distribution_release: core]
2019-08-08 07:17:10.693  LOG <gcp> INFO: Installing plugin: ansible
2019-08-08 07:17:11.482  LOG <gcp> INFO: Using existing installation of managed plugin: 7142c593-6e52-429a-8a71-55266c022e02 [package_name: cloudify-ansible-plugin, package_version: 2.4.0, supported_platform: linux_x86_64, distribution: centos, distribution_release: core]
2019-08-08 07:17:11.482  LOG <gcp> INFO: Installing plugin: suspend
2019-08-08 07:17:12.502  LOG <gcp> INFO: Using existing installation of managed plugin: 62c3cd35-5a18-49fd-a670-48f9ad207b05 [package_name: cloudify-utilities-plugin, package_version: 1.14.0, supported_platform: linux_x86_64, distribution: centos, distribution_release: core]
2019-08-08 07:17:12.502  LOG <gcp> INFO: Installing plugin: scalelist
2019-08-08 07:17:13.266  LOG <gcp> INFO: Using existing installation of managed plugin: 62c3cd35-5a18-49fd-a670-48f9ad207b05 [package_name: cloudify-utilities-plugin, package_version: 1.14.0, supported_platform: linux_x86_64, distribution: centos, distribution_release: core]
2019-08-08 07:17:13.267  LOG <gcp> INFO: Installing plugin: configuration
2019-08-08 07:17:14.199  LOG <gcp> INFO: Using existing installation of managed plugin: 62c3cd35-5a18-49fd-a670-48f9ad207b05 [package_name: cloudify-utilities-plugin, package_version: 1.14.0, supported_platform: linux_x86_64, distribution: centos, distribution_release: core]
2019-08-08 07:17:14.200  CFY <gcp> Task succeeded 'cloudify_agent.operations.install_plugins'
2019-08-08 07:17:14.266  CFY <gcp> Creating deployment work directory
2019-08-08 07:17:14.561  CFY <gcp> 'create_deployment_environment' workflow execution succeeded
2019-08-08 07:17:20.181  CFY <gcp> Starting 'install' workflow execution
2019-08-08 07:17:21.772  CFY <gcp> [network_jdrfjt] Validating node instance before creation: nothing to do
2019-08-08 07:17:21.895  CFY <gcp> [network_jdrfjt] Precreating node instance: nothing to do
2019-08-08 07:17:21.970  CFY <gcp> [network_jdrfjt] Creating node instance
2019-08-08 07:17:22.331  CFY <gcp> [network_jdrfjt.create] Sending task 'cloudify_gcp.compute.network.create'
2019-08-08 07:17:24.722  LOG <gcp> [network_jdrfjt.create] INFO: Create network network-jdrfjt
2019-08-08 07:17:27.338  CFY <gcp> [network_jdrfjt.create] Task rescheduled 'cloudify_gcp.compute.network.create' -> Operation started
Traceback (most recent call last):
  File "/opt/mgmtworker/env/lib/python2.7/site-packages/cloudify/dispatch.py", line 813, in main
    payload = handler.handle()
  File "/opt/mgmtworker/env/lib/python2.7/site-packages/cloudify/dispatch.py", line 464, in handle
    raise ctx.operation._operation_retry
OperationRetry: Operation started

2019-08-08 07:17:42.392  CFY <gcp> [network_jdrfjt.create] Sending task 'cloudify_gcp.compute.network.create' [retry 1/60]
2019-08-08 07:17:45.549  LOG <gcp> [network_jdrfjt.create] INFO: Get network network-jdrfjt details
2019-08-08 07:17:47.030  CFY <gcp> [network_jdrfjt.create] Task succeeded 'cloudify_gcp.compute.network.create' [retry 1/60]
2019-08-08 07:17:47.235  CFY <gcp> [network_jdrfjt] Node instance created
2019-08-08 07:17:47.350  CFY <gcp> [network_jdrfjt] Configuring node instance: nothing to do
2019-08-08 07:17:47.446  CFY <gcp> [network_jdrfjt] Starting node instance: nothing to do
2019-08-08 07:17:47.564  CFY <gcp> [network_jdrfjt] Poststarting node instance: nothing to do
2019-08-08 07:17:47.779  CFY <gcp> [network_jdrfjt] Node instance started
2019-08-08 07:17:48.881  CFY <gcp> [subnet_bomisy] Validating node instance before creation
2019-08-08 07:17:48.944  CFY <gcp> [firewall_trovi5] Validating node instance before creation: nothing to do
2019-08-08 07:17:49.118  CFY <gcp> [subnet_bomisy.create] Sending task 'cloudify_gcp.compute.subnetwork.creation_validation'
2019-08-08 07:17:49.980  CFY <gcp> [firewall_trovi5] Precreating node instance: nothing to do
2019-08-08 07:17:50.486  CFY <gcp> [firewall_trovi5] Creating node instance
2019-08-08 07:17:50.775  CFY <gcp> [firewall_trovi5.create] Sending task 'cloudify_gcp.compute.firewall.create'
2019-08-08 07:17:52.082  CFY <gcp> [subnet_bomisy.create] Task succeeded 'cloudify_gcp.compute.subnetwork.creation_validation'
2019-08-08 07:17:52.101  CFY <gcp> [subnet_bomisy] Node instance validated before creation
2019-08-08 07:17:52.309  CFY <gcp> [subnet_bomisy] Precreating node instance: nothing to do
2019-08-08 07:17:52.535  CFY <gcp> [subnet_bomisy] Creating node instance
2019-08-08 07:17:53.028  CFY <gcp> [subnet_bomisy.create] Sending task 'cloudify_gcp.compute.subnetwork.create'
2019-08-08 07:17:53.298  LOG <gcp> [firewall_trovi5.create] INFO: Create firewall rule firewall-trovi5 in network https://www.googleapis.com/compute/v1/projects/node2faas-248113/global/networks/network-jdrfjt
2019-08-08 07:17:55.310  LOG <gcp> [subnet_bomisy.create] INFO: Create subnetwork subnet-bomisy
2019-08-08 07:17:55.704  CFY <gcp> [firewall_trovi5.create] Task succeeded 'cloudify_gcp.compute.firewall.create'
2019-08-08 07:17:55.754  CFY <gcp> [firewall_trovi5] Node instance created
2019-08-08 07:17:56.078  CFY <gcp> [firewall_trovi5] Configuring node instance: nothing to do
2019-08-08 07:17:56.166  CFY <gcp> [firewall_trovi5] Starting node instance: nothing to do
2019-08-08 07:17:56.284  CFY <gcp> [firewall_trovi5] Poststarting node instance: nothing to do
2019-08-08 07:17:56.366  CFY <gcp> [firewall_trovi5] Node instance started
2019-08-08 07:17:57.972  CFY <gcp> [subnet_bomisy.create] Task rescheduled 'cloudify_gcp.compute.subnetwork.create' -> Operation started
Traceback (most recent call last):
  File "/opt/mgmtworker/env/lib/python2.7/site-packages/cloudify/dispatch.py", line 813, in main
    payload = handler.handle()
  File "/opt/mgmtworker/env/lib/python2.7/site-packages/cloudify/dispatch.py", line 464, in handle
    raise ctx.operation._operation_retry
OperationRetry: Operation started

2019-08-08 07:18:13.092  CFY <gcp> [subnet_bomisy.create] Sending task 'cloudify_gcp.compute.subnetwork.create' [retry 1/60]
2019-08-08 07:18:18.247  CFY <gcp> [subnet_bomisy.create] Task rescheduled 'cloudify_gcp.compute.subnetwork.create' -> Operation not completed yet: RUNNING [retry_after=30] [retry 1/60]
Traceback (most recent call last):
  File "/opt/mgmtworker/env/lib/python2.7/site-packages/cloudify/dispatch.py", line 813, in main
    payload = handler.handle()
  File "/opt/mgmtworker/env/lib/python2.7/site-packages/cloudify/dispatch.py", line 464, in handle
    raise ctx.operation._operation_retry
OperationRetry: Operation not completed yet: RUNNING [retry_after=30]

2019-08-08 07:18:48.342  CFY <gcp> [subnet_bomisy.create] Sending task 'cloudify_gcp.compute.subnetwork.create' [retry 2/60]
2019-08-08 07:18:52.037  LOG <gcp> [subnet_bomisy.create] INFO: Get subnetwork subnet-bomisy details
2019-08-08 07:18:53.799  CFY <gcp> [subnet_bomisy.create] Task succeeded 'cloudify_gcp.compute.subnetwork.create' [retry 2/60]
2019-08-08 07:18:53.846  CFY <gcp> [subnet_bomisy] Node instance created
2019-08-08 07:18:54.174  CFY <gcp> [subnet_bomisy] Configuring node instance: nothing to do
2019-08-08 07:18:54.264  CFY <gcp> [subnet_bomisy] Starting node instance: nothing to do
2019-08-08 07:18:54.350  CFY <gcp> [subnet_bomisy] Poststarting node instance: nothing to do
2019-08-08 07:18:54.696  CFY <gcp> [subnet_bomisy] Node instance started
2019-08-08 07:18:55.195  CFY <gcp> [vm-database_0vin48] Validating node instance before creation: nothing to do
2019-08-08 07:18:55.276  CFY <gcp> [vm-database_0vin48] Precreating node instance: nothing to do
2019-08-08 07:18:55.399  CFY <gcp> [vm-database_0vin48] Creating node instance
2019-08-08 07:18:55.736  CFY <gcp> [vm-database_0vin48.create] Sending task 'script_runner.tasks.run'
2019-08-08 07:18:58.272  LOG <gcp> [vm-database_0vin48.create] INFO: Downloaded scripts/gcp/key.py to /tmp/LYJQI/key.py
2019-08-08 07:18:58.763  CFY <gcp> [vm-database_0vin48.create] Task succeeded 'script_runner.tasks.run'
2019-08-08 07:18:59.034  CFY <gcp> [vm-database_0vin48] Node instance created
2019-08-08 07:18:59.297  CFY <gcp> [vm-database_0vin48] Configuring node instance
2019-08-08 07:18:59.481  CFY <gcp> [vm-database_0vin48.configure] Sending task 'cloudify_gcp.compute.instance.create'
2019-08-08 07:19:01.711  LOG <gcp> [vm-database_0vin48.configure] INFO: The script is 
2019-08-08 07:19:01.971  LOG <gcp> [vm-database_0vin48.configure] INFO: Adding bucket to metadata
2019-08-08 07:19:01.971  LOG <gcp> [vm-database_0vin48.configure] INFO: Adding sshKeys to metadata
2019-08-08 07:19:03.387  LOG <gcp> [vm-database_0vin48.configure] ERROR: Error traceback Traceback (most recent call last):
  File "/opt/mgmtworker/env/plugins/default_tenant/cloudify-gcp-plugin-1.4.4/lib/python2.7/site-packages/cloudify_gcp/utils.py", line 262, in _decorator
    return func(*args, **kwargs)
  File "/opt/mgmtworker/env/plugins/default_tenant/cloudify-gcp-plugin-1.4.4/lib/python2.7/site-packages/cloudify_gcp/compute/instance.py", line 422, in create
    utils.create(instance)
  File "/opt/mgmtworker/env/plugins/default_tenant/cloudify-gcp-plugin-1.4.4/lib/python2.7/site-packages/cloudify_gcp/utils.py", line 163, in _decorator
    return func(resource, *args, **kwargs)
  File "/opt/mgmtworker/env/plugins/default_tenant/cloudify-gcp-plugin-1.4.4/lib/python2.7/site-packages/cloudify_gcp/utils.py", line 170, in create
    return resource.create()
  File "/opt/mgmtworker/env/plugins/default_tenant/cloudify-gcp-plugin-1.4.4/lib/python2.7/site-packages/cloudify_gcp/utils.py", line 233, in wrapper
    response = func(self, *args, **kwargs)
  File "/opt/mgmtworker/env/plugins/default_tenant/cloudify-gcp-plugin-1.4.4/lib/python2.7/site-packages/cloudify_gcp/gcp.py", line 34, in _decorator
    response = func(self, *args, **kwargs)
  File "/opt/mgmtworker/env/plugins/default_tenant/cloudify-gcp-plugin-1.4.4/lib/python2.7/site-packages/cloudify_gcp/compute/instance.py", line 117, in create
    body=self.to_dict()).execute()
  File "/opt/mgmtworker/env/plugins/default_tenant/cloudify-gcp-plugin-1.4.4/lib/python2.7/site-packages/oauth2client/util.py", line 137, in positional_wrapper
    return wrapped(*args, **kwargs)
  File "/opt/mgmtworker/env/plugins/default_tenant/cloudify-gcp-plugin-1.4.4/lib/python2.7/site-packages/googleapiclient/http.py", line 832, in execute
    raise HttpError(resp, content, uri=self.uri)
HttpError: <HttpError 400 when requesting https://www.googleapis.com/compute/v1/projects/node2faas-248113/zones/us-east4-a/instances?alt=json returned "Invalid value for field 'resource.networkInterfaces[0].subnetwork': 'https://www.googleapis.com/compute/v1/projects/node2faas-248113/regions/southamerica-east1/subnetworks/subnet-bomisy'. Instance must be in the same region as the subnetwork.">
 with message <HttpError 400 when requesting https://www.googleapis.com/compute/v1/projects/node2faas-248113/zones/us-east4-a/instances?alt=json returned "Invalid value for field 'resource.networkInterfaces[0].subnetwork': 'https://www.googleapis.com/compute/v1/projects/node2faas-248113/regions/southamerica-east1/subnetworks/subnet-bomisy'. Instance must be in the same region as the subnetwork.">
2019-08-08 07:19:03.387  LOG <gcp> [vm-database_0vin48.configure] ERROR: Error Message 
2019-08-08 07:19:03.925  CFY <gcp> [vm-database_0vin48.configure] Task failed 'cloudify_gcp.compute.instance.create'
Traceback (most recent call last):
  File "/opt/mgmtworker/env/lib/python2.7/site-packages/cloudify/dispatch.py", line 813, in main
    payload = handler.handle()
  File "/opt/mgmtworker/env/lib/python2.7/site-packages/cloudify/dispatch.py", line 461, in handle
    result = self._run_operation_func(ctx, kwargs)
  File "/opt/mgmtworker/env/lib/python2.7/site-packages/cloudify/dispatch.py", line 519, in _run_operation_func
    return self.func(*self.args, **kwargs)
  File "/opt/mgmtworker/env/plugins/default_tenant/cloudify-gcp-plugin-1.4.4/lib/python2.7/site-packages/cloudify_gcp/utils.py", line 277, in _decorator
    raise NonRecoverableError(error.message)
NonRecoverableError

2019-08-08 07:19:04.298  CFY <gcp> 'install' workflow execution failed: RuntimeError: Workflow failed: Task failed 'cloudify_gcp.compute.instance.create'
Execution of workflow install for deployment gcp failed. [error=Traceback (most recent call last):
  File "/opt/mgmtworker/env/lib/python2.7/site-packages/cloudify/dispatch.py", line 664, in _remote_workflow_child_thread
    workflow_result = self._execute_workflow_function()
  File "/opt/mgmtworker/env/lib/python2.7/site-packages/cloudify/dispatch.py", line 693, in _execute_workflow_function
    result = self.func(*self.args, **self.kwargs)
  File "/opt/mgmtworker/env/lib/python2.7/site-packages/cloudify/plugins/workflows.py", line 31, in install
    node_instances=set(ctx.node_instances))
  File "/opt/mgmtworker/env/lib/python2.7/site-packages/cloudify/plugins/lifecycle.py", line 29, in install_node_instances
    processor.install()
  File "/opt/mgmtworker/env/lib/python2.7/site-packages/cloudify/plugins/lifecycle.py", line 102, in install
    graph.execute()
  File "/opt/mgmtworker/env/lib/python2.7/site-packages/cloudify/workflows/tasks_graph.py", line 237, in execute
    raise self._error
RuntimeError: Workflow failed: Task failed 'cloudify_gcp.compute.instance.create'
]
* Run 'cfy events list 204a3595-52cb-48d2-97fa-2963b2ca805b' to retrieve the execution's events/logs
'Executing workflow `uninstall` on deployment `gcp` [timeout=900 seconds] 2019-08-08 07:14:15.648 CFY <gcp> Starting 'uninstall' workflow execution 2019-08-08 07:14:16.486 CFY <gcp> [config-wordpress_ksizxg] Validating node instance after deletion: nothing to do 2019-08-08 07:14:16.726 CFY <gcp> [config-database_x7f5pa->vm-database_8ncghy|unlink] Sending task 'cloudify_ansible.tasks.ansible_remove_host' 2019-08-08 07:14:16.823 CFY <gcp> [firewall_0l8474] Stopping node instance 2019-08-08 07:14:17.707 CFY <gcp> [config-wordpress_ksizxg->vm-app2_ctjfzs|unlink] Sending task 'cloudify_ansible.tasks.ansible_remove_host' 2019-08-08 07:14:18.967 CFY <gcp> [config-database_x7f5pa] Validating node instance after deletion: nothing to do 2019-08-08 07:14:19.206 CFY <gcp> [config-wordpress_ksizxg] Stop: instance already uninitialized 2019-08-08 07:14:19.387 CFY <gcp> [firewall_0l8474] Validating node instance after deletion: nothing to do 2019-08-08 07:14:19.549 CFY <gcp> [config-database_x7f5pa] Stop: instance already uninitialized 2019-08-08 07:14:20.061 CFY <gcp> [firewall_0l8474] Stopped node instance: nothing to do 2019-08-08 07:14:20.564 CFY <gcp> [config-wordpress_ksizxg] Delete: instance already uninitialized 2019-08-08 07:14:20.801 CFY <gcp> [config-database_x7f5pa->vm-database_8ncghy|unlink] Task succeeded 'cloudify_ansible.tasks.ansible_remove_host' 2019-08-08 07:14:21.116 CFY <gcp> [config-database_x7f5pa] Delete: instance already uninitialized 2019-08-08 07:14:21.810 CFY <gcp> [config-wordpress_ksizxg] Deleted node instance 2019-08-08 07:14:21.954 CFY <gcp> [firewall_0l8474] Unlinking relationships 2019-08-08 07:14:22.451 CFY <gcp> [config-database_x7f5pa] Deleted node instance 2019-08-08 07:14:22.535 CFY <gcp> [firewall_0l8474] Relationships unlinked 2019-08-08 07:14:22.967 CFY <gcp> [firewall_0l8474] Deleting node instance 2019-08-08 07:14:23.059 CFY <gcp> [config-wordpress_ksizxg->vm-app2_ctjfzs|unlink] Task succeeded 'cloudify_ansible.tasks.ansible_remove_host' 2019-08-08 07:14:23.149 CFY <gcp> [firewall_0l8474.delete] Sending task 'cloudify_gcp.compute.firewall.delete' 2019-08-08 07:14:24.117 CFY <gcp> [config-wordpress_ksizxg->vm-app1_ea9mug|unlink] Sending task 'cloudify_ansible.tasks.ansible_remove_host' 2019-08-08 07:14:25.642 LOG <gcp> [firewall_0l8474.delete] INFO: Delete firewall rule firewall-0l8474 from network https://www.googleapis.com/compute/v1/projects/node2faas-248113/global/networks/network-wqj7rr 2019-08-08 07:14:27.177 CFY <gcp> [config-wordpress_ksizxg->vm-app1_ea9mug|unlink] Task succeeded 'cloudify_ansible.tasks.ansible_remove_host' 2019-08-08 07:14:27.774 CFY <gcp> [vm-app2_ctjfzs] Validating node instance after deletion: nothing to do 2019-08-08 07:14:27.993 CFY <gcp> [firewall_0l8474.delete] Task succeeded 'cloudify_gcp.compute.firewall.delete' 2019-08-08 07:14:28.018 CFY <gcp> [vm-app1_ea9mug] Validating node instance after deletion: nothing to do 2019-08-08 07:14:28.109 CFY <gcp> [vm-app2_ctjfzs] Stop: instance already uninitialized 2019-08-08 07:14:28.164 CFY <gcp> [firewall_0l8474] Deleted node instance 2019-08-08 07:14:28.228 CFY <gcp> [vm-app1_ea9mug] Stop: instance already uninitialized 2019-08-08 07:14:29.038 CFY <gcp> [vm-app2_ctjfzs] Delete: instance already uninitialized 2019-08-08 07:14:29.104 CFY <gcp> [vm-app1_ea9mug] Delete: instance already uninitialized 2019-08-08 07:14:29.193 CFY <gcp> [vm-app1_ea9mug] Deleted node instance 2019-08-08 07:14:29.763 CFY <gcp> [vm-app2_ctjfzs] Deleted node instance 2019-08-08 07:14:30.078 CFY <gcp> [vm-database_8ncghy] Stopping node instance 2019-08-08 07:14:30.406 CFY <gcp> [vm-database_8ncghy] Validating node instance after deletion: nothing to do 2019-08-08 07:14:30.730 CFY <gcp> [vm-database_8ncghy] Stopped node instance: nothing to do 2019-08-08 07:14:30.994 CFY <gcp> [vm-database_8ncghy] Unlinking relationships 2019-08-08 07:14:31.266 CFY <gcp> [vm-database_8ncghy] Relationships unlinked 2019-08-08 07:14:31.352 CFY <gcp> [vm-database_8ncghy] Deleting node instance 2019-08-08 07:14:31.712 CFY <gcp> [vm-database_8ncghy.delete] Sending task 'cloudify_gcp.compute.instance.delete' 2019-08-08 07:14:33.787 LOG <gcp> [vm-database_8ncghy.delete] INFO: Delete instance wordpressdatabase 2019-08-08 07:14:35.326 LOG <gcp> [vm-database_8ncghy.delete] ERROR: Error traceback Traceback (most recent call last): File "/opt/mgmtworker/env/plugins/default_tenant/cloudify-gcp-plugin-1.4.4/lib/python2.7/site-packages/cloudify_gcp/utils.py", line 262, in _decorator return func(*args, **kwargs) File "/opt/mgmtworker/env/plugins/default_tenant/cloudify-gcp-plugin-1.4.4/lib/python2.7/site-packages/cloudify_gcp/compute/instance.py", line 457, in delete utils.delete_if_not_external(instance) File "/opt/mgmtworker/env/plugins/default_tenant/cloudify-gcp-plugin-1.4.4/lib/python2.7/site-packages/cloudify_gcp/utils.py", line 175, in delete_if_not_external return resource.delete() File "/opt/mgmtworker/env/plugins/default_tenant/cloudify-gcp-plugin-1.4.4/lib/python2.7/site-packages/cloudify_gcp/utils.py", line 233, in wrapper response = func(self, *args, **kwargs) File "/opt/mgmtworker/env/plugins/default_tenant/cloudify-gcp-plugin-1.4.4/lib/python2.7/site-packages/cloudify_gcp/gcp.py", line 34, in _decorator response = func(self, *args, **kwargs) File "/opt/mgmtworker/env/plugins/default_tenant/cloudify-gcp-plugin-1.4.4/lib/python2.7/site-packages/cloudify_gcp/compute/instance.py", line 133, in delete instance=self.name).execute() File "/opt/mgmtworker/env/plugins/default_tenant/cloudify-gcp-plugin-1.4.4/lib/python2.7/site-packages/oauth2client/util.py", line 137, in positional_wrapper return wrapped(*args, **kwargs) File "/opt/mgmtworker/env/plugins/default_tenant/cloudify-gcp-plugin-1.4.4/lib/python2.7/site-packages/googleapiclient/http.py", line 832, in execute raise HttpError(resp, content, uri=self.uri) HttpError: <HttpError 404 when requesting https://www.googleapis.com/compute/v1/projects/node2faas-248113/zones/us-east4-a/instances/wordpressdatabase?alt=json returned "The resource 'projects/node2faas-248113/zones/us-east4-a/instances/wordpressdatabase' was not found"> with message <HttpError 404 when requesting https://www.googleapis.com/compute/v1/projects/node2faas-248113/zones/us-east4-a/instances/wordpressdatabase?alt=json returned "The resource 'projects/node2faas-248113/zones/us-east4-a/instances/wordpressdatabase' was not found"> 2019-08-08 07:14:35.327 LOG <gcp> [vm-database_8ncghy.delete] ERROR: Error Message 2019-08-08 07:14:36.169 CFY <gcp> [vm-database_8ncghy.delete] Task failed 'cloudify_gcp.compute.instance.delete' Traceback (most recent call last): File "/opt/mgmtworker/env/lib/python2.7/site-packages/cloudify/dispatch.py", line 813, in main payload = handler.handle() File "/opt/mgmtworker/env/lib/python2.7/site-packages/cloudify/dispatch.py", line 461, in handle result = self._run_operation_func(ctx, kwargs) File "/opt/mgmtworker/env/lib/python2.7/site-packages/cloudify/dispatch.py", line 519, in _run_operation_func return self.func(*self.args, **kwargs) File "/opt/mgmtworker/env/plugins/default_tenant/cloudify-gcp-plugin-1.4.4/lib/python2.7/site-packages/cloudify_gcp/utils.py", line 277, in _decorator raise NonRecoverableError(error.message) NonRecoverableError 2019-08-08 07:14:36.205 CFY <gcp> [vm-database_8ncghy] Deleted node instance 2019-08-08 07:14:36.852 CFY <gcp> [subnet_2wjr4z] Stopping node instance 2019-08-08 07:14:36.966 CFY <gcp> [subnet_2wjr4z] Validating node instance after deletion: nothing to do 2019-08-08 07:14:37.091 CFY <gcp> [subnet_2wjr4z] Stopped node instance: nothing to do 2019-08-08 07:14:37.369 CFY <gcp> [subnet_2wjr4z] Unlinking relationships 2019-08-08 07:14:37.649 CFY <gcp> [subnet_2wjr4z] Relationships unlinked 2019-08-08 07:14:37.879 CFY <gcp> [subnet_2wjr4z] Deleting node instance 2019-08-08 07:14:38.169 CFY <gcp> [subnet_2wjr4z.delete] Sending task 'cloudify_gcp.compute.subnetwork.delete' 2019-08-08 07:14:40.279 LOG <gcp> [subnet_2wjr4z.delete] INFO: Delete subnetwork subnet-2wjr4z 2019-08-08 07:14:43.478 CFY <gcp> [subnet_2wjr4z.delete] Task rescheduled 'cloudify_gcp.compute.subnetwork.delete' -> Operation started Traceback (most recent call last): File "/opt/mgmtworker/env/lib/python2.7/site-packages/cloudify/dispatch.py", line 813, in main payload = handler.handle() File "/opt/mgmtworker/env/lib/python2.7/site-packages/cloudify/dispatch.py", line 464, in handle raise ctx.operation._operation_retry OperationRetry: Operation started 2019-08-08 07:14:58.552 CFY <gcp> [subnet_2wjr4z.delete] Sending task 'cloudify_gcp.compute.subnetwork.delete' [retry 1/60] 2019-08-08 07:15:02.465 CFY <gcp> [subnet_2wjr4z.delete] Task rescheduled 'cloudify_gcp.compute.subnetwork.delete' -> Operation not completed yet: RUNNING [retry_after=30] [retry 1/60] Traceback (most recent call last): File "/opt/mgmtworker/env/lib/python2.7/site-packages/cloudify/dispatch.py", line 813, in main payload = handler.handle() File "/opt/mgmtworker/env/lib/python2.7/site-packages/cloudify/dispatch.py", line 464, in handle raise ctx.operation._operation_retry OperationRetry: Operation not completed yet: RUNNING [retry_after=30] 2019-08-08 07:15:32.537 CFY <gcp> [subnet_2wjr4z.delete] Sending task 'cloudify_gcp.compute.subnetwork.delete' [retry 2/60] 2019-08-08 07:15:36.199 CFY <gcp> [subnet_2wjr4z.delete] Task succeeded 'cloudify_gcp.compute.subnetwork.delete' [retry 2/60] 2019-08-08 07:15:36.281 CFY <gcp> [subnet_2wjr4z] Deleted node instance 2019-08-08 07:15:37.109 CFY <gcp> [network_wqj7rr] Stopping node instance 2019-08-08 07:15:37.274 CFY <gcp> [network_wqj7rr] Validating node instance after deletion: nothing to do 2019-08-08 07:15:37.350 CFY <gcp> [network_wqj7rr] Stopped node instance: nothing to do 2019-08-08 07:15:37.655 CFY <gcp> [network_wqj7rr] Unlinking relationships 2019-08-08 07:15:37.926 CFY <gcp> [network_wqj7rr] Relationships unlinked 2019-08-08 07:15:38.009 CFY <gcp> [network_wqj7rr] Deleting node instance 2019-08-08 07:15:38.364 CFY <gcp> [network_wqj7rr.delete] Sending task 'cloudify_gcp.compute.network.delete' 2019-08-08 07:15:40.390 LOG <gcp> [network_wqj7rr.delete] INFO: Delete network network-wqj7rr 2019-08-08 07:15:42.674 CFY <gcp> [network_wqj7rr.delete] Task rescheduled 'cloudify_gcp.compute.network.delete' -> Operation started Traceback (most recent call last): File "/opt/mgmtworker/env/lib/python2.7/site-packages/cloudify/dispatch.py", line 813, in main payload = handler.handle() File "/opt/mgmtworker/env/lib/python2.7/site-packages/cloudify/dispatch.py", line 464, in handle raise ctx.operation._operation_retry OperationRetry: Operation started 2019-08-08 07:15:57.743 CFY <gcp> [network_wqj7rr.delete] Sending task 'cloudify_gcp.compute.network.delete' [retry 1/60] 2019-08-08 07:16:01.663 CFY <gcp> [network_wqj7rr.delete] Task rescheduled 'cloudify_gcp.compute.network.delete' -> Operation not completed yet: RUNNING [retry_after=30] [retry 1/60] Traceback (most recent call last): File "/opt/mgmtworker/env/lib/python2.7/site-packages/cloudify/dispatch.py", line 813, in main payload = handler.handle() File "/opt/mgmtworker/env/lib/python2.7/site-packages/cloudify/dispatch.py", line 464, in handle raise ctx.operation._operation_retry OperationRetry: Operation not completed yet: RUNNING [retry_after=30] 2019-08-08 07:16:31.713 CFY <gcp> [network_wqj7rr.delete] Sending task 'cloudify_gcp.compute.network.delete' [retry 2/60] 2019-08-08 07:16:35.418 CFY <gcp> [network_wqj7rr.delete] Task succeeded 'cloudify_gcp.compute.network.delete' [retry 2/60] 2019-08-08 07:16:35.467 CFY <gcp> [network_wqj7rr] Deleted node instance 2019-08-08 07:16:35.909 CFY <gcp> 'uninstall' workflow execution succeeded Finished executing workflow uninstall on deployment gcp cloudify common logs monitors play_test.sh README.md reset_test.sh results stop_test.sh temp_count temp_cpu_amount temp_io_amount temp_mem_amount temp_mem_initial temp_mem_total temp_monitor_pid temp_net_amount terraform Run 'cfy events list 0f66015a-9d67-4f76-9648-a26333504fee' to retrieve the execution's events/logs Trying to delete deployment gcp... Deployment deleted Deleting blueprint cloudify-wordpress-blueprint-gcp... Blueprint deleted Trying to delete deployment gcp... An error occurred on the server: 404: Requested `Deployment` with ID `gcp` was not found Deleting blueprint cloudify-wordpress-blueprint-gcp... An error occurred on the server: 404: Requested `Blueprint` with ID `cloudify-wordpress-blueprint-gcp` was not found'
