Uploading blueprint cloudify/gcp.yaml...
 gcp.yaml |############################################################| 100.0%
Blueprint uploaded. The blueprint's id is cloudify-wordpress-blueprint-gcp
Creating new deployment from blueprint cloudify-wordpress-blueprint-gcp...
Deployment created. The deployment's id is gcp
Executing workflow `install` on deployment `gcp` [timeout=900 seconds]
Deployment environment creation is pending...
2019-08-08 14:00:34.855  CFY <gcp> Starting 'create_deployment_environment' workflow execution
2019-08-08 14:00:34.859  CFY <gcp> Installing deployment and workflow plugins
2019-08-08 14:00:34.960  CFY <gcp> Sending task 'cloudify_agent.operations.install_plugins'
2019-08-08 14:00:34.976  CFY <gcp> Task started 'cloudify_agent.operations.install_plugins'
2019-08-08 14:00:35.358  LOG <gcp> INFO: Installing plugin: gcp_plugin
2019-08-08 14:00:36.303  LOG <gcp> INFO: Using existing installation of managed plugin: e0a99ba4-54d6-4741-a773-4ec378dc8634 [package_name: cloudify-gcp-plugin, package_version: 1.4.4, supported_platform: linux_x86_64, distribution: centos, distribution_release: core]
2019-08-08 14:00:36.303  LOG <gcp> INFO: Installing plugin: ansible
2019-08-08 14:00:37.467  LOG <gcp> INFO: Using existing installation of managed plugin: 7142c593-6e52-429a-8a71-55266c022e02 [package_name: cloudify-ansible-plugin, package_version: 2.4.0, supported_platform: linux_x86_64, distribution: centos, distribution_release: core]
2019-08-08 14:00:37.468  LOG <gcp> INFO: Installing plugin: suspend
2019-08-08 14:00:38.398  LOG <gcp> INFO: Using existing installation of managed plugin: 62c3cd35-5a18-49fd-a670-48f9ad207b05 [package_name: cloudify-utilities-plugin, package_version: 1.14.0, supported_platform: linux_x86_64, distribution: centos, distribution_release: core]
2019-08-08 14:00:38.398  LOG <gcp> INFO: Installing plugin: scalelist
2019-08-08 14:00:39.227  LOG <gcp> INFO: Using existing installation of managed plugin: 62c3cd35-5a18-49fd-a670-48f9ad207b05 [package_name: cloudify-utilities-plugin, package_version: 1.14.0, supported_platform: linux_x86_64, distribution: centos, distribution_release: core]
2019-08-08 14:00:39.227  LOG <gcp> INFO: Installing plugin: configuration
2019-08-08 14:00:40.198  CFY <gcp> Task succeeded 'cloudify_agent.operations.install_plugins'
2019-08-08 14:00:40.198  LOG <gcp> INFO: Using existing installation of managed plugin: 62c3cd35-5a18-49fd-a670-48f9ad207b05 [package_name: cloudify-utilities-plugin, package_version: 1.14.0, supported_platform: linux_x86_64, distribution: centos, distribution_release: core]
2019-08-08 14:00:40.319  CFY <gcp> Creating deployment work directory
2019-08-08 14:00:40.698  CFY <gcp> 'create_deployment_environment' workflow execution succeeded
2019-08-08 14:00:45.923  CFY <gcp> Starting 'install' workflow execution
2019-08-08 14:00:47.636  CFY <gcp> [network_g0z9fr] Validating node instance before creation: nothing to do
2019-08-08 14:00:47.710  CFY <gcp> [network_g0z9fr] Precreating node instance: nothing to do
2019-08-08 14:00:48.009  CFY <gcp> [network_g0z9fr] Creating node instance
2019-08-08 14:00:48.183  CFY <gcp> [network_g0z9fr.create] Sending task 'cloudify_gcp.compute.network.create'
2019-08-08 14:00:50.175  LOG <gcp> [network_g0z9fr.create] INFO: Create network network-g0z9fr
2019-08-08 14:00:52.881  CFY <gcp> [network_g0z9fr.create] Task rescheduled 'cloudify_gcp.compute.network.create' -> Operation started
Traceback (most recent call last):
  File "/opt/mgmtworker/env/lib/python2.7/site-packages/cloudify/dispatch.py", line 813, in main
    payload = handler.handle()
  File "/opt/mgmtworker/env/lib/python2.7/site-packages/cloudify/dispatch.py", line 464, in handle
    raise ctx.operation._operation_retry
OperationRetry: Operation started

2019-08-08 14:01:08.101  CFY <gcp> [network_g0z9fr.create] Sending task 'cloudify_gcp.compute.network.create' [retry 1/60]
2019-08-08 14:01:12.246  CFY <gcp> [network_g0z9fr.create] Task rescheduled 'cloudify_gcp.compute.network.create' -> Operation not completed yet: RUNNING [retry_after=30] [retry 1/60]
Traceback (most recent call last):
  File "/opt/mgmtworker/env/lib/python2.7/site-packages/cloudify/dispatch.py", line 813, in main
    payload = handler.handle()
  File "/opt/mgmtworker/env/lib/python2.7/site-packages/cloudify/dispatch.py", line 464, in handle
    raise ctx.operation._operation_retry
OperationRetry: Operation not completed yet: RUNNING [retry_after=30]

2019-08-08 14:01:42.397  CFY <gcp> [network_g0z9fr.create] Sending task 'cloudify_gcp.compute.network.create' [retry 2/60]
2019-08-08 14:01:46.029  LOG <gcp> [network_g0z9fr.create] INFO: Get network network-g0z9fr details
2019-08-08 14:01:47.881  CFY <gcp> [network_g0z9fr.create] Task succeeded 'cloudify_gcp.compute.network.create' [retry 2/60]
2019-08-08 14:01:48.013  CFY <gcp> [network_g0z9fr] Node instance created
2019-08-08 14:01:48.280  CFY <gcp> [network_g0z9fr] Configuring node instance: nothing to do
2019-08-08 14:01:48.409  CFY <gcp> [network_g0z9fr] Starting node instance: nothing to do
2019-08-08 14:01:48.481  CFY <gcp> [network_g0z9fr] Poststarting node instance: nothing to do
2019-08-08 14:01:48.774  CFY <gcp> [network_g0z9fr] Node instance started
2019-08-08 14:01:49.564  CFY <gcp> [firewall_4gncjn] Validating node instance before creation: nothing to do
2019-08-08 14:01:49.616  CFY <gcp> [subnet_x8ho56] Validating node instance before creation
2019-08-08 14:01:49.758  CFY <gcp> [subnet_x8ho56.create] Sending task 'cloudify_gcp.compute.subnetwork.creation_validation'
2019-08-08 14:01:50.650  CFY <gcp> [firewall_4gncjn] Precreating node instance: nothing to do
2019-08-08 14:01:51.077  CFY <gcp> [firewall_4gncjn] Creating node instance
2019-08-08 14:01:51.326  CFY <gcp> [firewall_4gncjn.create] Sending task 'cloudify_gcp.compute.firewall.create'
2019-08-08 14:01:53.040  CFY <gcp> [subnet_x8ho56.create] Task succeeded 'cloudify_gcp.compute.subnetwork.creation_validation'
2019-08-08 14:01:53.077  CFY <gcp> [subnet_x8ho56] Node instance validated before creation
2019-08-08 14:01:53.291  CFY <gcp> [subnet_x8ho56] Precreating node instance: nothing to do
2019-08-08 14:01:53.894  CFY <gcp> [subnet_x8ho56] Creating node instance
2019-08-08 14:01:54.395  CFY <gcp> [subnet_x8ho56.create] Sending task 'cloudify_gcp.compute.subnetwork.create'
2019-08-08 14:01:54.549  LOG <gcp> [firewall_4gncjn.create] INFO: Create firewall rule firewall-4gncjn in network https://www.googleapis.com/compute/v1/projects/node2faas-248113/global/networks/network-g0z9fr
2019-08-08 14:01:56.498  LOG <gcp> [subnet_x8ho56.create] INFO: Create subnetwork subnet-x8ho56
2019-08-08 14:01:57.667  CFY <gcp> [firewall_4gncjn.create] Task succeeded 'cloudify_gcp.compute.firewall.create'
2019-08-08 14:01:57.705  CFY <gcp> [firewall_4gncjn] Node instance created
2019-08-08 14:01:57.996  CFY <gcp> [firewall_4gncjn] Configuring node instance: nothing to do
2019-08-08 14:01:58.088  CFY <gcp> [firewall_4gncjn] Starting node instance: nothing to do
2019-08-08 14:01:58.219  CFY <gcp> [firewall_4gncjn] Poststarting node instance: nothing to do
2019-08-08 14:01:58.480  CFY <gcp> [firewall_4gncjn] Node instance started
2019-08-08 14:01:59.574  CFY <gcp> [subnet_x8ho56.create] Task rescheduled 'cloudify_gcp.compute.subnetwork.create' -> Operation started
Traceback (most recent call last):
  File "/opt/mgmtworker/env/lib/python2.7/site-packages/cloudify/dispatch.py", line 813, in main
    payload = handler.handle()
  File "/opt/mgmtworker/env/lib/python2.7/site-packages/cloudify/dispatch.py", line 464, in handle
    raise ctx.operation._operation_retry
OperationRetry: Operation started

2019-08-08 14:02:14.696  CFY <gcp> [subnet_x8ho56.create] Sending task 'cloudify_gcp.compute.subnetwork.create' [retry 1/60]
2019-08-08 14:02:18.574  LOG <gcp> [subnet_x8ho56.create] INFO: Get subnetwork subnet-x8ho56 details
2019-08-08 14:02:20.981  CFY <gcp> [subnet_x8ho56.create] Task succeeded 'cloudify_gcp.compute.subnetwork.create' [retry 1/60]
2019-08-08 14:02:21.233  CFY <gcp> [subnet_x8ho56] Node instance created
2019-08-08 14:02:21.426  CFY <gcp> [subnet_x8ho56] Configuring node instance: nothing to do
2019-08-08 14:02:21.506  CFY <gcp> [subnet_x8ho56] Starting node instance: nothing to do
2019-08-08 14:02:21.632  CFY <gcp> [subnet_x8ho56] Poststarting node instance: nothing to do
2019-08-08 14:02:21.887  CFY <gcp> [subnet_x8ho56] Node instance started
2019-08-08 14:02:22.385  CFY <gcp> [vm-database_iz9dpw] Validating node instance before creation: nothing to do
2019-08-08 14:02:22.514  CFY <gcp> [vm-database_iz9dpw] Precreating node instance: nothing to do
2019-08-08 14:02:22.588  CFY <gcp> [vm-database_iz9dpw] Creating node instance
2019-08-08 14:02:22.948  CFY <gcp> [vm-database_iz9dpw.create] Sending task 'script_runner.tasks.run'
2019-08-08 14:02:25.036  LOG <gcp> [vm-database_iz9dpw.create] INFO: Downloaded scripts/gcp/key.py to /tmp/BRNRY/key.py
2019-08-08 14:02:25.629  CFY <gcp> [vm-database_iz9dpw.create] Task succeeded 'script_runner.tasks.run'
2019-08-08 14:02:26.015  CFY <gcp> [vm-database_iz9dpw] Node instance created
2019-08-08 14:02:26.196  CFY <gcp> [vm-database_iz9dpw] Configuring node instance
2019-08-08 14:02:26.716  CFY <gcp> [vm-database_iz9dpw.configure] Sending task 'cloudify_gcp.compute.instance.create'
2019-08-08 14:02:28.697  LOG <gcp> [vm-database_iz9dpw.configure] INFO: The script is 
2019-08-08 14:02:28.989  LOG <gcp> [vm-database_iz9dpw.configure] INFO: Adding bucket to metadata
2019-08-08 14:02:28.989  LOG <gcp> [vm-database_iz9dpw.configure] INFO: Adding sshKeys to metadata
2019-08-08 14:02:30.373  LOG <gcp> [vm-database_iz9dpw.configure] ERROR: Error traceback Traceback (most recent call last):
  File "/opt/mgmtworker/env/plugins/default_tenant/cloudify-gcp-plugin-1.4.4/lib/python2.7/site-packages/cloudify_gcp/utils.py", line 262, in _decorator
    return func(*args, **kwargs)
  File "/opt/mgmtworker/env/plugins/default_tenant/cloudify-gcp-plugin-1.4.4/lib/python2.7/site-packages/cloudify_gcp/compute/instance.py", line 422, in create
    utils.create(instance)
  File "/opt/mgmtworker/env/plugins/default_tenant/cloudify-gcp-plugin-1.4.4/lib/python2.7/site-packages/cloudify_gcp/utils.py", line 163, in _decorator
    return func(resource, *args, **kwargs)
  File "/opt/mgmtworker/env/plugins/default_tenant/cloudify-gcp-plugin-1.4.4/lib/python2.7/site-packages/cloudify_gcp/utils.py", line 170, in create
    return resource.create()
  File "/opt/mgmtworker/env/plugins/default_tenant/cloudify-gcp-plugin-1.4.4/lib/python2.7/site-packages/cloudify_gcp/utils.py", line 233, in wrapper
    response = func(self, *args, **kwargs)
  File "/opt/mgmtworker/env/plugins/default_tenant/cloudify-gcp-plugin-1.4.4/lib/python2.7/site-packages/cloudify_gcp/gcp.py", line 34, in _decorator
    response = func(self, *args, **kwargs)
  File "/opt/mgmtworker/env/plugins/default_tenant/cloudify-gcp-plugin-1.4.4/lib/python2.7/site-packages/cloudify_gcp/compute/instance.py", line 117, in create
    body=self.to_dict()).execute()
  File "/opt/mgmtworker/env/plugins/default_tenant/cloudify-gcp-plugin-1.4.4/lib/python2.7/site-packages/oauth2client/util.py", line 137, in positional_wrapper
    return wrapped(*args, **kwargs)
  File "/opt/mgmtworker/env/plugins/default_tenant/cloudify-gcp-plugin-1.4.4/lib/python2.7/site-packages/googleapiclient/http.py", line 832, in execute
    raise HttpError(resp, content, uri=self.uri)
HttpError: <HttpError 400 when requesting https://www.googleapis.com/compute/v1/projects/node2faas-248113/zones/us-east4-a/instances?alt=json returned "Invalid value for field 'resource.networkInterfaces[0].subnetwork': 'https://www.googleapis.com/compute/v1/projects/node2faas-248113/regions/europe-west2/subnetworks/subnet-x8ho56'. Instance must be in the same region as the subnetwork.">
 with message <HttpError 400 when requesting https://www.googleapis.com/compute/v1/projects/node2faas-248113/zones/us-east4-a/instances?alt=json returned "Invalid value for field 'resource.networkInterfaces[0].subnetwork': 'https://www.googleapis.com/compute/v1/projects/node2faas-248113/regions/europe-west2/subnetworks/subnet-x8ho56'. Instance must be in the same region as the subnetwork.">
2019-08-08 14:02:30.373  LOG <gcp> [vm-database_iz9dpw.configure] ERROR: Error Message 
2019-08-08 14:02:30.859  CFY <gcp> [vm-database_iz9dpw.configure] Task failed 'cloudify_gcp.compute.instance.create'
Traceback (most recent call last):
  File "/opt/mgmtworker/env/lib/python2.7/site-packages/cloudify/dispatch.py", line 813, in main
    payload = handler.handle()
  File "/opt/mgmtworker/env/lib/python2.7/site-packages/cloudify/dispatch.py", line 461, in handle
    result = self._run_operation_func(ctx, kwargs)
  File "/opt/mgmtworker/env/lib/python2.7/site-packages/cloudify/dispatch.py", line 519, in _run_operation_func
    return self.func(*self.args, **kwargs)
  File "/opt/mgmtworker/env/plugins/default_tenant/cloudify-gcp-plugin-1.4.4/lib/python2.7/site-packages/cloudify_gcp/utils.py", line 277, in _decorator
    raise NonRecoverableError(error.message)
NonRecoverableError

2019-08-08 14:02:31.219  CFY <gcp> 'install' workflow execution failed: RuntimeError: Workflow failed: Task failed 'cloudify_gcp.compute.instance.create'
Execution of workflow install for deployment gcp failed. [error=Traceback (most recent call last):
  File "/opt/mgmtworker/env/lib/python2.7/site-packages/cloudify/dispatch.py", line 664, in _remote_workflow_child_thread
    workflow_result = self._execute_workflow_function()
  File "/opt/mgmtworker/env/lib/python2.7/site-packages/cloudify/dispatch.py", line 693, in _execute_workflow_function
    result = self.func(*self.args, **self.kwargs)
  File "/opt/mgmtworker/env/lib/python2.7/site-packages/cloudify/plugins/workflows.py", line 31, in install
    node_instances=set(ctx.node_instances))
  File "/opt/mgmtworker/env/lib/python2.7/site-packages/cloudify/plugins/lifecycle.py", line 29, in install_node_instances
    processor.install()
  File "/opt/mgmtworker/env/lib/python2.7/site-packages/cloudify/plugins/lifecycle.py", line 102, in install
    graph.execute()
  File "/opt/mgmtworker/env/lib/python2.7/site-packages/cloudify/workflows/tasks_graph.py", line 237, in execute
    raise self._error
RuntimeError: Workflow failed: Task failed 'cloudify_gcp.compute.instance.create'
]
* Run 'cfy events list 15f6535b-4d8e-49d0-a90f-4138e70d2c45' to retrieve the execution's events/logs
