Executing workflow `uninstall` on deployment `gcp` [timeout=900 seconds]
2019-08-10 16:11:53.669  CFY <gcp> Starting 'uninstall' workflow execution
2019-08-10 16:11:54.753  CFY <gcp> [config-database_zl1nir->vm-database_mbg9k8|unlink] Sending task 'cloudify_ansible.tasks.ansible_remove_host'
2019-08-10 16:11:54.888  CFY <gcp> [config-database_zl1nir] Validating node instance after deletion: nothing to do
2019-08-10 16:11:55.998  CFY <gcp> [config-wordpress_31fqc8] Validating node instance after deletion: nothing to do
2019-08-10 16:11:56.258  CFY <gcp> [firewall_pwyeau] Stopping node instance
2019-08-10 16:11:56.675  CFY <gcp> [config-wordpress_31fqc8->vm-app2_i7jpl9|unlink] Sending task 'cloudify_ansible.tasks.ansible_remove_host'
2019-08-10 16:11:57.893  CFY <gcp> [config-database_zl1nir] Stop: instance already uninitialized
2019-08-10 16:11:58.111  CFY <gcp> [config-wordpress_31fqc8] Stop: instance already uninitialized
2019-08-10 16:11:58.252  CFY <gcp> [firewall_pwyeau] Validating node instance after deletion: nothing to do
2019-08-10 16:11:59.794  CFY <gcp> [firewall_pwyeau] Stopped node instance: nothing to do
2019-08-10 16:12:00.024  CFY <gcp> [config-database_zl1nir] Delete: instance already uninitialized
2019-08-10 16:12:00.343  CFY <gcp> [config-wordpress_31fqc8] Delete: instance already uninitialized
2019-08-10 16:12:00.821  CFY <gcp> [config-database_zl1nir->vm-database_mbg9k8|unlink] Task succeeded 'cloudify_ansible.tasks.ansible_remove_host'
2019-08-10 16:12:01.978  CFY <gcp> [config-database_zl1nir] Deleted node instance
2019-08-10 16:12:02.214  CFY <gcp> [config-wordpress_31fqc8] Deleted node instance
2019-08-10 16:12:03.325  CFY <gcp> [firewall_pwyeau] Unlinking relationships
2019-08-10 16:12:03.400  CFY <gcp> Task failed '_SetNodeInstanceStateTask' -> 409: Node instance update conflict [current version=3, update version=2]
Traceback (most recent call last):
  File "/opt/mgmtworker/env/lib/python2.7/site-packages/cloudify/workflows/tasks.py", line 709, in local_task_wrapper
    result = self.local_task(**self.kwargs)
  File "/opt/mgmtworker/env/lib/python2.7/site-packages/cloudify/workflows/tasks.py", line 1019, in __call__
    return self.remote()
  File "/opt/mgmtworker/env/lib/python2.7/site-packages/cloudify/workflows/tasks.py", line 1055, in remote
    update_node_instance(node_instance)
  File "/opt/mgmtworker/env/lib/python2.7/site-packages/cloudify/manager.py", line 389, in update_node_instance
    version=node_instance.version)
  File "/opt/mgmtworker/env/lib/python2.7/site-packages/cloudify_rest_client/node_instances.py", line 141, in update
    response = self.api.patch(uri, data=data)
  File "/opt/mgmtworker/env/lib/python2.7/site-packages/cloudify_rest_client/client.py", line 311, in patch
    timeout=timeout)
  File "/opt/mgmtworker/env/lib/python2.7/site-packages/cloudify/cluster.py", line 57, in do_request
    **kwargs)
  File "/opt/mgmtworker/env/lib/python2.7/site-packages/cloudify_rest_client/client.py", line 257, in do_request
    verify=self.get_request_verify(), timeout=timeout)
  File "/opt/mgmtworker/env/lib/python2.7/site-packages/cloudify_rest_client/client.py", line 191, in _do_request
    self._raise_client_error(response, request_url)
  File "/opt/mgmtworker/env/lib/python2.7/site-packages/cloudify_rest_client/client.py", line 144, in _raise_client_error
    response=response)
  File "/opt/mgmtworker/env/lib/python2.7/site-packages/cloudify_rest_client/client.py", line 156, in _prepare_and_raise_exception
    status_code, error_code=error_code, response=response)
CloudifyClientError: 409: Node instance update conflict [current version=3, update version=2]

2019-08-10 16:12:03.810  CFY <gcp> [firewall_pwyeau] Relationships unlinked
2019-08-10 16:12:03.910  CFY <gcp> [config-wordpress_31fqc8->vm-app2_i7jpl9|unlink] Task succeeded 'cloudify_ansible.tasks.ansible_remove_host'
2019-08-10 16:12:04.196  CFY <gcp> [config-wordpress_31fqc8->vm-app1_nrib3e|unlink] Sending task 'cloudify_ansible.tasks.ansible_remove_host'
2019-08-10 16:12:06.055  CFY <gcp> [firewall_pwyeau] Deleting node instance
2019-08-10 16:12:06.484  CFY <gcp> [firewall_pwyeau.delete] Sending task 'cloudify_gcp.compute.firewall.delete'
2019-08-10 16:12:10.534  CFY <gcp> [config-wordpress_31fqc8->vm-app1_nrib3e|unlink] Task succeeded 'cloudify_ansible.tasks.ansible_remove_host'
2019-08-10 16:12:11.492  CFY <gcp> [vm-app2_i7jpl9] Validating node instance after deletion: nothing to do
2019-08-10 16:12:11.702  CFY <gcp> [vm-app1_nrib3e] Validating node instance after deletion: nothing to do
2019-08-10 16:12:11.927  CFY <gcp> [vm-app2_i7jpl9] Stop: instance already uninitialized
2019-08-10 16:12:12.075  CFY <gcp> [vm-app1_nrib3e] Stop: instance already uninitialized
2019-08-10 16:12:12.846  LOG <gcp> [firewall_pwyeau.delete] INFO: Delete firewall rule firewall-pwyeau from network https://www.googleapis.com/compute/v1/projects/node2faas-248113/global/networks/network-lmbmjk
2019-08-10 16:12:13.703  CFY <gcp> [vm-app2_i7jpl9] Delete: instance already uninitialized
2019-08-10 16:12:13.888  CFY <gcp> [vm-app1_nrib3e] Delete: instance already uninitialized
2019-08-10 16:12:14.248  CFY <gcp> [vm-app2_i7jpl9] Deleted node instance
2019-08-10 16:12:14.709  CFY <gcp> [vm-app1_nrib3e] Deleted node instance
2019-08-10 16:12:15.094  CFY <gcp> [vm-database_mbg9k8] Stopping node instance
2019-08-10 16:12:15.573  CFY <gcp> [vm-database_mbg9k8] Validating node instance after deletion: nothing to do
2019-08-10 16:12:15.870  CFY <gcp> [vm-database_mbg9k8] Stopped node instance: nothing to do
2019-08-10 16:12:16.465  CFY <gcp> [vm-database_mbg9k8] Unlinking relationships
2019-08-10 16:12:16.827  CFY <gcp> [vm-database_mbg9k8] Relationships unlinked
2019-08-10 16:12:16.838  CFY <gcp> [firewall_pwyeau.delete] Task succeeded 'cloudify_gcp.compute.firewall.delete'
2019-08-10 16:12:17.432  CFY <gcp> [firewall_pwyeau] Deleted node instance
2019-08-10 16:12:17.701  CFY <gcp> [vm-database_mbg9k8] Deleting node instance
2019-08-10 16:12:18.448  CFY <gcp> [vm-database_mbg9k8.delete] Sending task 'cloudify_gcp.compute.instance.delete'
2019-08-10 16:12:21.016  LOG <gcp> [vm-database_mbg9k8.delete] INFO: Delete instance wordpressdatabase
2019-08-10 16:12:23.024  LOG <gcp> [vm-database_mbg9k8.delete] ERROR: Error traceback Traceback (most recent call last):
  File "/opt/mgmtworker/env/plugins/default_tenant/cloudify-gcp-plugin-1.4.4/lib/python2.7/site-packages/cloudify_gcp/utils.py", line 262, in _decorator
    return func(*args, **kwargs)
  File "/opt/mgmtworker/env/plugins/default_tenant/cloudify-gcp-plugin-1.4.4/lib/python2.7/site-packages/cloudify_gcp/compute/instance.py", line 457, in delete
    utils.delete_if_not_external(instance)
  File "/opt/mgmtworker/env/plugins/default_tenant/cloudify-gcp-plugin-1.4.4/lib/python2.7/site-packages/cloudify_gcp/utils.py", line 175, in delete_if_not_external
    return resource.delete()
  File "/opt/mgmtworker/env/plugins/default_tenant/cloudify-gcp-plugin-1.4.4/lib/python2.7/site-packages/cloudify_gcp/utils.py", line 233, in wrapper
    response = func(self, *args, **kwargs)
  File "/opt/mgmtworker/env/plugins/default_tenant/cloudify-gcp-plugin-1.4.4/lib/python2.7/site-packages/cloudify_gcp/gcp.py", line 34, in _decorator
    response = func(self, *args, **kwargs)
  File "/opt/mgmtworker/env/plugins/default_tenant/cloudify-gcp-plugin-1.4.4/lib/python2.7/site-packages/cloudify_gcp/compute/instance.py", line 133, in delete
    instance=self.name).execute()
  File "/opt/mgmtworker/env/plugins/default_tenant/cloudify-gcp-plugin-1.4.4/lib/python2.7/site-packages/oauth2client/util.py", line 137, in positional_wrapper
    return wrapped(*args, **kwargs)
  File "/opt/mgmtworker/env/plugins/default_tenant/cloudify-gcp-plugin-1.4.4/lib/python2.7/site-packages/googleapiclient/http.py", line 832, in execute
    raise HttpError(resp, content, uri=self.uri)
HttpError: <HttpError 404 when requesting https://www.googleapis.com/compute/v1/projects/node2faas-248113/zones/southamerica-east1-c/instances/wordpressdatabase?alt=json returned "The resource 'projects/node2faas-248113/zones/southamerica-east1-c/instances/wordpressdatabase' was not found">
 with message <HttpError 404 when requesting https://www.googleapis.com/compute/v1/projects/node2faas-248113/zones/southamerica-east1-c/instances/wordpressdatabase?alt=json returned "The resource 'projects/node2faas-248113/zones/southamerica-east1-c/instances/wordpressdatabase' was not found">
2019-08-10 16:12:23.025  LOG <gcp> [vm-database_mbg9k8.delete] ERROR: Error Message 
2019-08-10 16:12:23.694  CFY <gcp> [vm-database_mbg9k8.delete] Task failed 'cloudify_gcp.compute.instance.delete'
Traceback (most recent call last):
  File "/opt/mgmtworker/env/lib/python2.7/site-packages/cloudify/dispatch.py", line 813, in main
    payload = handler.handle()
  File "/opt/mgmtworker/env/lib/python2.7/site-packages/cloudify/dispatch.py", line 461, in handle
    result = self._run_operation_func(ctx, kwargs)
  File "/opt/mgmtworker/env/lib/python2.7/site-packages/cloudify/dispatch.py", line 519, in _run_operation_func
    return self.func(*self.args, **kwargs)
  File "/opt/mgmtworker/env/plugins/default_tenant/cloudify-gcp-plugin-1.4.4/lib/python2.7/site-packages/cloudify_gcp/utils.py", line 277, in _decorator
    raise NonRecoverableError(error.message)
NonRecoverableError

2019-08-10 16:12:24.134  CFY <gcp> [vm-database_mbg9k8] Deleted node instance
2019-08-10 16:12:24.764  CFY <gcp> [subnet_o6u6tz] Stopping node instance
2019-08-10 16:12:24.955  CFY <gcp> [subnet_o6u6tz] Validating node instance after deletion: nothing to do
2019-08-10 16:12:25.223  CFY <gcp> [subnet_o6u6tz] Stopped node instance: nothing to do
2019-08-10 16:12:25.886  CFY <gcp> [subnet_o6u6tz] Unlinking relationships
2019-08-10 16:12:26.297  CFY <gcp> [subnet_o6u6tz] Relationships unlinked
2019-08-10 16:12:26.508  CFY <gcp> [subnet_o6u6tz] Deleting node instance
2019-08-10 16:12:26.962  CFY <gcp> [subnet_o6u6tz.delete] Sending task 'cloudify_gcp.compute.subnetwork.delete'
2019-08-10 16:12:29.213  LOG <gcp> [subnet_o6u6tz.delete] INFO: Delete subnetwork subnet-o6u6tz
2019-08-10 16:12:31.988  CFY <gcp> [subnet_o6u6tz.delete] Task rescheduled 'cloudify_gcp.compute.subnetwork.delete' -> Operation started
Traceback (most recent call last):
  File "/opt/mgmtworker/env/lib/python2.7/site-packages/cloudify/dispatch.py", line 813, in main
    payload = handler.handle()
  File "/opt/mgmtworker/env/lib/python2.7/site-packages/cloudify/dispatch.py", line 464, in handle
    raise ctx.operation._operation_retry
OperationRetry: Operation started

2019-08-10 16:12:47.208  CFY <gcp> [subnet_o6u6tz.delete] Sending task 'cloudify_gcp.compute.subnetwork.delete' [retry 1/60]
2019-08-10 16:12:51.690  CFY <gcp> [subnet_o6u6tz.delete] Task succeeded 'cloudify_gcp.compute.subnetwork.delete' [retry 1/60]
2019-08-10 16:12:52.010  CFY <gcp> [subnet_o6u6tz] Deleted node instance
2019-08-10 16:12:52.677  CFY <gcp> [network_lmbmjk] Stopping node instance
2019-08-10 16:12:52.860  CFY <gcp> [network_lmbmjk] Validating node instance after deletion: nothing to do
2019-08-10 16:12:53.059  CFY <gcp> [network_lmbmjk] Stopped node instance: nothing to do
2019-08-10 16:12:53.472  CFY <gcp> [network_lmbmjk] Unlinking relationships
2019-08-10 16:12:53.756  CFY <gcp> [network_lmbmjk] Relationships unlinked
2019-08-10 16:12:53.945  CFY <gcp> [network_lmbmjk] Deleting node instance
2019-08-10 16:12:54.597  CFY <gcp> [network_lmbmjk.delete] Sending task 'cloudify_gcp.compute.network.delete'
2019-08-10 16:12:56.742  LOG <gcp> [network_lmbmjk.delete] INFO: Delete network network-lmbmjk
2019-08-10 16:12:59.311  CFY <gcp> [network_lmbmjk.delete] Task rescheduled 'cloudify_gcp.compute.network.delete' -> Operation started
Traceback (most recent call last):
  File "/opt/mgmtworker/env/lib/python2.7/site-packages/cloudify/dispatch.py", line 813, in main
    payload = handler.handle()
  File "/opt/mgmtworker/env/lib/python2.7/site-packages/cloudify/dispatch.py", line 464, in handle
    raise ctx.operation._operation_retry
OperationRetry: Operation started

2019-08-10 16:13:14.498  CFY <gcp> [network_lmbmjk.delete] Sending task 'cloudify_gcp.compute.network.delete' [retry 1/60]
2019-08-10 16:13:18.836  CFY <gcp> [network_lmbmjk.delete] Task rescheduled 'cloudify_gcp.compute.network.delete' -> Operation not completed yet: RUNNING [retry_after=30] [retry 1/60]
Traceback (most recent call last):
  File "/opt/mgmtworker/env/lib/python2.7/site-packages/cloudify/dispatch.py", line 813, in main
    payload = handler.handle()
  File "/opt/mgmtworker/env/lib/python2.7/site-packages/cloudify/dispatch.py", line 464, in handle
    raise ctx.operation._operation_retry
OperationRetry: Operation not completed yet: RUNNING [retry_after=30]

2019-08-10 16:13:49.114  CFY <gcp> [network_lmbmjk.delete] Sending task 'cloudify_gcp.compute.network.delete' [retry 2/60]
2019-08-10 16:13:53.535  CFY <gcp> [network_lmbmjk.delete] Task succeeded 'cloudify_gcp.compute.network.delete' [retry 2/60]
2019-08-10 16:13:53.925  CFY <gcp> [network_lmbmjk] Deleted node instance
2019-08-10 16:13:54.432  CFY <gcp> 'uninstall' workflow execution succeeded
Finished executing workflow uninstall on deployment gcp
* Run 'cfy events list 516c2022-56b6-449e-86f7-559508a5dd97' to retrieve the execution's events/logs
Trying to delete deployment gcp...
Deployment deleted
Deleting blueprint cloudify-wordpress-blueprint-gcp...
Blueprint deleted
