Uploading blueprint cloudify/gcp.yaml...
 gcp.yaml |############################################################| 100.0%
Blueprint uploaded. The blueprint's id is cloudify-wordpress-blueprint-gcp
Creating new deployment from blueprint cloudify-wordpress-blueprint-gcp...
Deployment created. The deployment's id is gcp
Executing workflow `install` on deployment `gcp` [timeout=900 seconds]
Deployment environment creation is pending...
2019-08-10 17:04:20.421  CFY <gcp> Starting 'create_deployment_environment' workflow execution
2019-08-10 17:04:20.424  CFY <gcp> Installing deployment and workflow plugins
2019-08-10 17:04:20.525  CFY <gcp> Sending task 'cloudify_agent.operations.install_plugins'
2019-08-10 17:04:20.542  CFY <gcp> Task started 'cloudify_agent.operations.install_plugins'
2019-08-10 17:04:20.873  LOG <gcp> INFO: Installing plugin: gcp_plugin
2019-08-10 17:04:21.676  LOG <gcp> INFO: Using existing installation of managed plugin: e0a99ba4-54d6-4741-a773-4ec378dc8634 [package_name: cloudify-gcp-plugin, package_version: 1.4.4, supported_platform: linux_x86_64, distribution: centos, distribution_release: core]
2019-08-10 17:04:21.676  LOG <gcp> INFO: Installing plugin: ansible
2019-08-10 17:04:22.653  LOG <gcp> INFO: Using existing installation of managed plugin: 7142c593-6e52-429a-8a71-55266c022e02 [package_name: cloudify-ansible-plugin, package_version: 2.4.0, supported_platform: linux_x86_64, distribution: centos, distribution_release: core]
2019-08-10 17:04:22.653  LOG <gcp> INFO: Installing plugin: suspend
2019-08-10 17:04:23.960  LOG <gcp> INFO: Using existing installation of managed plugin: 62c3cd35-5a18-49fd-a670-48f9ad207b05 [package_name: cloudify-utilities-plugin, package_version: 1.14.0, supported_platform: linux_x86_64, distribution: centos, distribution_release: core]
2019-08-10 17:04:23.960  LOG <gcp> INFO: Installing plugin: scalelist
2019-08-10 17:04:25.607  LOG <gcp> INFO: Using existing installation of managed plugin: 62c3cd35-5a18-49fd-a670-48f9ad207b05 [package_name: cloudify-utilities-plugin, package_version: 1.14.0, supported_platform: linux_x86_64, distribution: centos, distribution_release: core]
2019-08-10 17:04:25.607  LOG <gcp> INFO: Installing plugin: configuration
2019-08-10 17:04:27.745  LOG <gcp> INFO: Using existing installation of managed plugin: 62c3cd35-5a18-49fd-a670-48f9ad207b05 [package_name: cloudify-utilities-plugin, package_version: 1.14.0, supported_platform: linux_x86_64, distribution: centos, distribution_release: core]
2019-08-10 17:04:27.746  CFY <gcp> Task succeeded 'cloudify_agent.operations.install_plugins'
2019-08-10 17:04:27.801  CFY <gcp> Creating deployment work directory
2019-08-10 17:04:28.256  CFY <gcp> 'create_deployment_environment' workflow execution succeeded
2019-08-10 17:04:32.687  CFY <gcp> Starting 'install' workflow execution
2019-08-10 17:04:34.680  CFY <gcp> [network_wci470] Validating node instance before creation: nothing to do
2019-08-10 17:04:34.891  CFY <gcp> [network_wci470] Precreating node instance: nothing to do
2019-08-10 17:04:35.163  CFY <gcp> [network_wci470] Creating node instance
2019-08-10 17:04:35.345  CFY <gcp> [network_wci470.create] Sending task 'cloudify_gcp.compute.network.create'
2019-08-10 17:04:37.471  LOG <gcp> [network_wci470.create] INFO: Create network network-wci470
2019-08-10 17:04:45.245  CFY <gcp> [network_wci470.create] Task rescheduled 'cloudify_gcp.compute.network.create' -> Operation started
Traceback (most recent call last):
  File "/opt/mgmtworker/env/lib/python2.7/site-packages/cloudify/dispatch.py", line 813, in main
    payload = handler.handle()
  File "/opt/mgmtworker/env/lib/python2.7/site-packages/cloudify/dispatch.py", line 464, in handle
    raise ctx.operation._operation_retry
OperationRetry: Operation started

2019-08-10 17:05:00.494  CFY <gcp> [network_wci470.create] Sending task 'cloudify_gcp.compute.network.create' [retry 1/60]
2019-08-10 17:05:06.150  LOG <gcp> [network_wci470.create] INFO: Get network network-wci470 details
2019-08-10 17:05:07.842  CFY <gcp> [network_wci470.create] Task succeeded 'cloudify_gcp.compute.network.create' [retry 1/60]
2019-08-10 17:05:08.321  CFY <gcp> [network_wci470] Node instance created
2019-08-10 17:05:08.510  CFY <gcp> [network_wci470] Configuring node instance: nothing to do
2019-08-10 17:05:08.711  CFY <gcp> [network_wci470] Starting node instance: nothing to do
2019-08-10 17:05:08.943  CFY <gcp> [network_wci470] Poststarting node instance: nothing to do
2019-08-10 17:05:09.143  CFY <gcp> [network_wci470] Node instance started
2019-08-10 17:05:10.424  CFY <gcp> [subnet_vks902] Validating node instance before creation
2019-08-10 17:05:10.487  CFY <gcp> [firewall_09hzzw] Validating node instance before creation: nothing to do
2019-08-10 17:05:10.631  CFY <gcp> [subnet_vks902.create] Sending task 'cloudify_gcp.compute.subnetwork.creation_validation'
2019-08-10 17:05:11.524  CFY <gcp> [firewall_09hzzw] Precreating node instance: nothing to do
2019-08-10 17:05:12.360  CFY <gcp> [firewall_09hzzw] Creating node instance
2019-08-10 17:05:12.771  CFY <gcp> [firewall_09hzzw.create] Sending task 'cloudify_gcp.compute.firewall.create'
2019-08-10 17:05:15.295  CFY <gcp> [subnet_vks902.create] Task succeeded 'cloudify_gcp.compute.subnetwork.creation_validation'
2019-08-10 17:05:15.343  CFY <gcp> [subnet_vks902] Node instance validated before creation
2019-08-10 17:05:15.668  CFY <gcp> [subnet_vks902] Precreating node instance: nothing to do
2019-08-10 17:05:15.867  CFY <gcp> [subnet_vks902] Creating node instance
2019-08-10 17:05:16.735  CFY <gcp> [subnet_vks902.create] Sending task 'cloudify_gcp.compute.subnetwork.create'
2019-08-10 17:05:17.168  LOG <gcp> [firewall_09hzzw.create] INFO: Create firewall rule firewall-09hzzw in network https://www.googleapis.com/compute/v1/projects/node2faas-248113/global/networks/network-wci470
2019-08-10 17:05:20.274  CFY <gcp> [firewall_09hzzw.create] Task succeeded 'cloudify_gcp.compute.firewall.create'
2019-08-10 17:05:20.274  CFY <gcp> [firewall_09hzzw.create] Task succeeded 'cloudify_gcp.compute.firewall.create'
2019-08-10 17:05:20.377  CFY <gcp> [firewall_09hzzw] Node instance created
2019-08-10 17:05:20.884  CFY <gcp> [firewall_09hzzw] Configuring node instance: nothing to do
2019-08-10 17:05:20.983  CFY <gcp> [firewall_09hzzw] Starting node instance: nothing to do
2019-08-10 17:05:21.095  CFY <gcp> [firewall_09hzzw] Poststarting node instance: nothing to do
2019-08-10 17:05:21.188  CFY <gcp> [firewall_09hzzw] Node instance started
2019-08-10 17:05:24.157  CFY <gcp> [subnet_vks902.create] Task rescheduled 'cloudify_gcp.compute.subnetwork.create' -> Operation started
Traceback (most recent call last):
  File "/opt/mgmtworker/env/lib/python2.7/site-packages/cloudify/dispatch.py", line 813, in main
    payload = handler.handle()
  File "/opt/mgmtworker/env/lib/python2.7/site-packages/cloudify/dispatch.py", line 464, in handle
    raise ctx.operation._operation_retry
OperationRetry: Operation started

2019-08-10 17:05:39.300  CFY <gcp> [subnet_vks902.create] Sending task 'cloudify_gcp.compute.subnetwork.create' [retry 1/60]
2019-08-10 17:05:43.576  LOG <gcp> [subnet_vks902.create] INFO: Get subnetwork subnet-vks902 details
2019-08-10 17:05:45.778  CFY <gcp> [subnet_vks902.create] Task succeeded 'cloudify_gcp.compute.subnetwork.create' [retry 1/60]
2019-08-10 17:05:46.043  CFY <gcp> [subnet_vks902] Node instance created
2019-08-10 17:05:46.112  CFY <gcp> [subnet_vks902] Configuring node instance: nothing to do
2019-08-10 17:05:46.241  CFY <gcp> [subnet_vks902] Starting node instance: nothing to do
2019-08-10 17:05:46.435  CFY <gcp> [subnet_vks902] Poststarting node instance: nothing to do
2019-08-10 17:05:46.738  CFY <gcp> [subnet_vks902] Node instance started
2019-08-10 17:05:47.383  CFY <gcp> [vm-database_1rl74o] Validating node instance before creation: nothing to do
2019-08-10 17:05:47.598  CFY <gcp> [vm-database_1rl74o] Precreating node instance: nothing to do
2019-08-10 17:05:48.211  CFY <gcp> [vm-database_1rl74o] Creating node instance
2019-08-10 17:05:48.410  CFY <gcp> [vm-database_1rl74o.create] Sending task 'script_runner.tasks.run'
2019-08-10 17:05:50.356  LOG <gcp> [vm-database_1rl74o.create] INFO: Downloaded scripts/gcp/key.py to /tmp/NOCLX/key.py
2019-08-10 17:05:51.076  CFY <gcp> [vm-database_1rl74o.create] Task succeeded 'script_runner.tasks.run'
2019-08-10 17:05:51.583  CFY <gcp> [vm-database_1rl74o] Node instance created
2019-08-10 17:05:51.870  CFY <gcp> [vm-database_1rl74o] Configuring node instance
2019-08-10 17:05:52.034  CFY <gcp> [vm-database_1rl74o.configure] Sending task 'cloudify_gcp.compute.instance.create'
2019-08-10 17:05:55.314  LOG <gcp> [vm-database_1rl74o.configure] INFO: The script is 
2019-08-10 17:05:55.626  LOG <gcp> [vm-database_1rl74o.configure] INFO: Adding bucket to metadata
2019-08-10 17:05:55.626  LOG <gcp> [vm-database_1rl74o.configure] INFO: Adding sshKeys to metadata
2019-08-10 17:05:58.137  CFY <gcp> [vm-database_1rl74o.configure] Task rescheduled 'cloudify_gcp.compute.instance.create' -> Operation started
Traceback (most recent call last):
  File "/opt/mgmtworker/env/lib/python2.7/site-packages/cloudify/dispatch.py", line 813, in main
    payload = handler.handle()
  File "/opt/mgmtworker/env/lib/python2.7/site-packages/cloudify/dispatch.py", line 464, in handle
    raise ctx.operation._operation_retry
OperationRetry: Operation started

2019-08-10 17:06:13.350  CFY <gcp> [vm-database_1rl74o.configure] Sending task 'cloudify_gcp.compute.instance.create' [retry 1/60]
2019-08-10 17:06:15.991  LOG <gcp> [vm-database_1rl74o.configure] INFO: The script is 
2019-08-10 17:06:17.595  LOG <gcp> [vm-database_1rl74o.configure] ERROR: Response with error {u'errors': [{u'message': u"The resource '482761649285-compute@developer.gserviceaccount.com' of type 'serviceAccount' was not found.", u'code': u'EXTERNAL_RESOURCE_NOT_FOUND'}]}
2019-08-10 17:06:17.596  LOG <gcp> [vm-database_1rl74o.configure] ERROR: Error Message {u'errors': [{u'message': u"The resource '482761649285-compute@developer.gserviceaccount.com' of type 'serviceAccount' was not found.", u'code': u'EXTERNAL_RESOURCE_NOT_FOUND'}]}
2019-08-10 17:06:18.210  CFY <gcp> [vm-database_1rl74o.configure] Task failed 'cloudify_gcp.compute.instance.create' -> {u'errors': [{u'message': u"The resource '482761649285-compute@developer.gserviceaccount.com' of type 'serviceAccount' was not found.", u'code': u'EXTERNAL_RESOURCE_NOT_FOUND'}]} [retry 1/60]
Traceback (most recent call last):
  File "/opt/mgmtworker/env/lib/python2.7/site-packages/cloudify/dispatch.py", line 813, in main
    payload = handler.handle()
  File "/opt/mgmtworker/env/lib/python2.7/site-packages/cloudify/dispatch.py", line 461, in handle
    result = self._run_operation_func(ctx, kwargs)
  File "/opt/mgmtworker/env/lib/python2.7/site-packages/cloudify/dispatch.py", line 519, in _run_operation_func
    return self.func(*self.args, **kwargs)
  File "/opt/mgmtworker/env/plugins/default_tenant/cloudify-gcp-plugin-1.4.4/lib/python2.7/site-packages/cloudify_gcp/utils.py", line 267, in _decorator
    raise NonRecoverableError(e.message)
NonRecoverableError: {u'errors': [{u'message': u"The resource '482761649285-compute@developer.gserviceaccount.com' of type 'serviceAccount' was not found.", u'code': u'EXTERNAL_RESOURCE_NOT_FOUND'}]}

2019-08-10 17:06:18.812  CFY <gcp> 'install' workflow execution failed: RuntimeError: Workflow failed: Task failed 'cloudify_gcp.compute.instance.create' -> {u'errors': [{u'message': u"The resource '482761649285-compute@developer.gserviceaccount.com' of type 'serviceAccount' was not found.", u'code': u'EXTERNAL_RESOURCE_NOT_FOUND'}]}
Execution of workflow install for deployment gcp failed. [error=Traceback (most recent call last):
  File "/opt/mgmtworker/env/lib/python2.7/site-packages/cloudify/dispatch.py", line 664, in _remote_workflow_child_thread
    workflow_result = self._execute_workflow_function()
  File "/opt/mgmtworker/env/lib/python2.7/site-packages/cloudify/dispatch.py", line 693, in _execute_workflow_function
    result = self.func(*self.args, **self.kwargs)
  File "/opt/mgmtworker/env/lib/python2.7/site-packages/cloudify/plugins/workflows.py", line 31, in install
    node_instances=set(ctx.node_instances))
  File "/opt/mgmtworker/env/lib/python2.7/site-packages/cloudify/plugins/lifecycle.py", line 29, in install_node_instances
    processor.install()
  File "/opt/mgmtworker/env/lib/python2.7/site-packages/cloudify/plugins/lifecycle.py", line 102, in install
    graph.execute()
  File "/opt/mgmtworker/env/lib/python2.7/site-packages/cloudify/workflows/tasks_graph.py", line 237, in execute
    raise self._error
RuntimeError: Workflow failed: Task failed 'cloudify_gcp.compute.instance.create' -> {u'errors': [{u'message': u"The resource '482761649285-compute@developer.gserviceaccount.com' of type 'serviceAccount' was not found.", u'code': u'EXTERNAL_RESOURCE_NOT_FOUND'}]}
]
* Run 'cfy events list ae4f9caa-10ea-44fa-aa43-d7e6e6f55d4d' to retrieve the execution's events/logs
