Executing workflow `uninstall` on deployment `gcp` [timeout=900 seconds]
2019-08-09 04:31:12.766  CFY <gcp> Starting 'uninstall' workflow execution
2019-08-09 04:31:13.766  CFY <gcp> [firewall_828ne9] Validating node instance after deletion: nothing to do
2019-08-09 04:31:13.832  CFY <gcp> [config-wordpress_36f7oj->vm-app2_cmp2yp|unlink] Sending task 'cloudify_ansible.tasks.ansible_remove_host'
2019-08-09 04:31:13.873  CFY <gcp> [config-wordpress_36f7oj] Validating node instance after deletion: nothing to do
2019-08-09 04:31:15.325  CFY <gcp> [config-database_v9nfkd->vm-database_10s5lq|unlink] Sending task 'cloudify_ansible.tasks.ansible_remove_host'
2019-08-09 04:31:16.444  CFY <gcp> [config-database_v9nfkd] Validating node instance after deletion: nothing to do
2019-08-09 04:31:16.579  CFY <gcp> [firewall_828ne9] Stop: instance already uninitialized
2019-08-09 04:31:16.768  CFY <gcp> [config-wordpress_36f7oj] Stop: instance already uninitialized
2019-08-09 04:31:16.879  CFY <gcp> [config-database_v9nfkd] Stop: instance already uninitialized
2019-08-09 04:31:17.056  CFY <gcp> [config-wordpress_36f7oj->vm-app2_cmp2yp|unlink] Task succeeded 'cloudify_ansible.tasks.ansible_remove_host'
2019-08-09 04:31:17.270  CFY <gcp> [config-wordpress_36f7oj->vm-app1_tgi41s|unlink] Sending task 'cloudify_ansible.tasks.ansible_remove_host'
2019-08-09 04:31:18.272  CFY <gcp> [firewall_828ne9] Delete: instance already uninitialized
2019-08-09 04:31:18.407  CFY <gcp> [config-database_v9nfkd] Delete: instance already uninitialized
2019-08-09 04:31:18.583  CFY <gcp> [config-wordpress_36f7oj] Delete: instance already uninitialized
2019-08-09 04:31:19.406  CFY <gcp> [firewall_828ne9] Deleted node instance
2019-08-09 04:31:19.590  CFY <gcp> [config-database_v9nfkd] Deleted node instance
2019-08-09 04:31:20.360  CFY <gcp> [config-wordpress_36f7oj] Deleted node instance
2019-08-09 04:31:21.032  CFY <gcp> [config-database_v9nfkd->vm-database_10s5lq|unlink] Task failed 'cloudify_ansible.tasks.ansible_remove_host' -> 409: Node instance update conflict [current version=3, update version=2]
Traceback (most recent call last):
  File "/opt/mgmtworker/env/lib/python2.7/site-packages/cloudify/dispatch.py", line 813, in main
    payload = handler.handle()
  File "/opt/mgmtworker/env/lib/python2.7/site-packages/cloudify/dispatch.py", line 461, in handle
    result = self._run_operation_func(ctx, kwargs)
  File "/opt/mgmtworker/env/lib/python2.7/site-packages/cloudify/dispatch.py", line 524, in _run_operation_func
    ctx.source.instance.update()
  File "/opt/mgmtworker/env/lib/python2.7/site-packages/cloudify/context.py", line 414, in update
    self._endpoint.update_node_instance(self._node_instance)
  File "/opt/mgmtworker/env/lib/python2.7/site-packages/cloudify/endpoint.py", line 177, in update_node_instance
    return manager.update_node_instance(node_instance)
  File "/opt/mgmtworker/env/lib/python2.7/site-packages/cloudify/manager.py", line 389, in update_node_instance
    version=node_instance.version)
  File "/opt/mgmtworker/env/lib/python2.7/site-packages/cloudify_rest_client/node_instances.py", line 141, in update
    response = self.api.patch(uri, data=data)
  File "/opt/mgmtworker/env/lib/python2.7/site-packages/cloudify_rest_client/client.py", line 311, in patch
    timeout=timeout)
  File "/opt/mgmtworker/env/lib/python2.7/site-packages/cloudify/cluster.py", line 57, in do_request
    **kwargs)
  File "/opt/mgmtworker/env/lib/python2.7/site-packages/cloudify_rest_client/client.py", line 257, in do_request
    verify=self.get_request_verify(), timeout=timeout)
  File "/opt/mgmtworker/env/lib/python2.7/site-packages/cloudify_rest_client/client.py", line 191, in _do_request
    self._raise_client_error(response, request_url)
  File "/opt/mgmtworker/env/lib/python2.7/site-packages/cloudify_rest_client/client.py", line 144, in _raise_client_error
    response=response)
  File "/opt/mgmtworker/env/lib/python2.7/site-packages/cloudify_rest_client/client.py", line 156, in _prepare_and_raise_exception
    status_code, error_code=error_code, response=response)
CloudifyClientError: 409: Node instance update conflict [current version=3, update version=2]

2019-08-09 04:31:22.604  CFY <gcp> [config-wordpress_36f7oj->vm-app1_tgi41s|unlink] Task succeeded 'cloudify_ansible.tasks.ansible_remove_host'
2019-08-09 04:31:23.135  CFY <gcp> [vm-app2_cmp2yp] Validating node instance after deletion: nothing to do
2019-08-09 04:31:23.269  CFY <gcp> [vm-app1_tgi41s] Validating node instance after deletion: nothing to do
2019-08-09 04:31:23.736  CFY <gcp> [vm-app1_tgi41s] Stop: instance already uninitialized
2019-08-09 04:31:23.810  CFY <gcp> [vm-app2_cmp2yp] Stop: instance already uninitialized
2019-08-09 04:31:24.412  CFY <gcp> [vm-app1_tgi41s] Delete: instance already uninitialized
2019-08-09 04:31:24.464  CFY <gcp> [vm-app2_cmp2yp] Delete: instance already uninitialized
2019-08-09 04:31:24.521  CFY <gcp> [vm-app2_cmp2yp] Deleted node instance
2019-08-09 04:31:24.741  CFY <gcp> [vm-app1_tgi41s] Deleted node instance
2019-08-09 04:31:25.083  CFY <gcp> [vm-database_10s5lq] Validating node instance after deletion: nothing to do
2019-08-09 04:31:25.374  CFY <gcp> [vm-database_10s5lq] Stop: instance already uninitialized
2019-08-09 04:31:25.675  CFY <gcp> [vm-database_10s5lq] Delete: instance already uninitialized
2019-08-09 04:31:26.023  CFY <gcp> [vm-database_10s5lq] Deleted node instance
2019-08-09 04:31:26.535  CFY <gcp> [subnet_lhlbzy] Validating node instance after deletion: nothing to do
2019-08-09 04:31:26.745  CFY <gcp> [subnet_lhlbzy] Stop: instance already uninitialized
2019-08-09 04:31:27.157  CFY <gcp> [subnet_lhlbzy] Delete: instance already uninitialized
2019-08-09 04:31:27.423  CFY <gcp> [subnet_lhlbzy] Deleted node instance
2019-08-09 04:31:27.749  CFY <gcp> [network_wzarpk] Stopping node instance
2019-08-09 04:31:28.160  CFY <gcp> [network_wzarpk] Validating node instance after deletion: nothing to do
2019-08-09 04:31:28.278  CFY <gcp> [network_wzarpk] Stopped node instance: nothing to do
2019-08-09 04:31:28.586  CFY <gcp> [network_wzarpk] Unlinking relationships
2019-08-09 04:31:28.864  CFY <gcp> [network_wzarpk] Relationships unlinked
2019-08-09 04:31:28.924  CFY <gcp> [network_wzarpk] Deleting node instance
2019-08-09 04:31:29.286  CFY <gcp> [network_wzarpk.delete] Sending task 'cloudify_gcp.compute.network.delete'
2019-08-09 04:31:31.136  LOG <gcp> [network_wzarpk.delete] INFO: Delete network network-wzarpk
2019-08-09 04:31:34.758  LOG <gcp> [network_wzarpk.delete] ERROR: Error traceback Traceback (most recent call last):
  File "/opt/mgmtworker/env/plugins/default_tenant/cloudify-gcp-plugin-1.4.4/lib/python2.7/site-packages/cloudify_gcp/utils.py", line 262, in _decorator
    return func(*args, **kwargs)
  File "/opt/mgmtworker/env/plugins/default_tenant/cloudify-gcp-plugin-1.4.4/lib/python2.7/site-packages/cloudify_gcp/compute/network.py", line 215, in delete
    utils.delete_if_not_external(network)
  File "/opt/mgmtworker/env/plugins/default_tenant/cloudify-gcp-plugin-1.4.4/lib/python2.7/site-packages/cloudify_gcp/utils.py", line 175, in delete_if_not_external
    return resource.delete()
  File "/opt/mgmtworker/env/plugins/default_tenant/cloudify-gcp-plugin-1.4.4/lib/python2.7/site-packages/cloudify_gcp/utils.py", line 233, in wrapper
    response = func(self, *args, **kwargs)
  File "/opt/mgmtworker/env/plugins/default_tenant/cloudify-gcp-plugin-1.4.4/lib/python2.7/site-packages/cloudify_gcp/gcp.py", line 34, in _decorator
    response = func(self, *args, **kwargs)
  File "/opt/mgmtworker/env/plugins/default_tenant/cloudify-gcp-plugin-1.4.4/lib/python2.7/site-packages/cloudify_gcp/compute/network.py", line 80, in delete
    network=self.name).execute()
  File "/opt/mgmtworker/env/plugins/default_tenant/cloudify-gcp-plugin-1.4.4/lib/python2.7/site-packages/oauth2client/util.py", line 137, in positional_wrapper
    return wrapped(*args, **kwargs)
  File "/opt/mgmtworker/env/plugins/default_tenant/cloudify-gcp-plugin-1.4.4/lib/python2.7/site-packages/googleapiclient/http.py", line 832, in execute
    raise HttpError(resp, content, uri=self.uri)
HttpError: <HttpError 404 when requesting https://www.googleapis.com/compute/v1/projects/node2faas-248113/global/networks/network-wzarpk?alt=json returned "The resource 'projects/node2faas-248113/global/networks/network-wzarpk' was not found">
 with message <HttpError 404 when requesting https://www.googleapis.com/compute/v1/projects/node2faas-248113/global/networks/network-wzarpk?alt=json returned "The resource 'projects/node2faas-248113/global/networks/network-wzarpk' was not found">
2019-08-09 04:31:34.758  LOG <gcp> [network_wzarpk.delete] ERROR: Error Message 
2019-08-09 04:31:35.255  CFY <gcp> [network_wzarpk.delete] Task failed 'cloudify_gcp.compute.network.delete'
Traceback (most recent call last):
  File "/opt/mgmtworker/env/lib/python2.7/site-packages/cloudify/dispatch.py", line 813, in main
    payload = handler.handle()
  File "/opt/mgmtworker/env/lib/python2.7/site-packages/cloudify/dispatch.py", line 461, in handle
    result = self._run_operation_func(ctx, kwargs)
  File "/opt/mgmtworker/env/lib/python2.7/site-packages/cloudify/dispatch.py", line 519, in _run_operation_func
    return self.func(*self.args, **kwargs)
  File "/opt/mgmtworker/env/plugins/default_tenant/cloudify-gcp-plugin-1.4.4/lib/python2.7/site-packages/cloudify_gcp/utils.py", line 277, in _decorator
    raise NonRecoverableError(error.message)
NonRecoverableError

2019-08-09 04:31:35.270  CFY <gcp> [network_wzarpk] Deleted node instance
2019-08-09 04:31:35.709  CFY <gcp> 'uninstall' workflow execution succeeded
Finished executing workflow uninstall on deployment gcp
* Run 'cfy events list 0b019b17-3e54-4fad-b27c-fc7402c08b6e' to retrieve the execution's events/logs
Trying to delete deployment gcp...
Deployment deleted
Deleting blueprint cloudify-wordpress-blueprint-gcp...
Blueprint deleted
