Uploading blueprint cloudify/gcp.yaml...
 gcp.yaml |############################################################| 100.0%
Blueprint uploaded. The blueprint's id is cloudify-wordpress-blueprint-gcp
Creating new deployment from blueprint cloudify-wordpress-blueprint-gcp...
Deployment created. The deployment's id is gcp
Executing workflow `install` on deployment `gcp` [timeout=900 seconds]
Deployment environment creation is pending...
2019-08-10 15:49:35.904  CFY <gcp> Starting 'create_deployment_environment' workflow execution
2019-08-10 15:49:35.907  CFY <gcp> Installing deployment and workflow plugins
2019-08-10 15:49:36.007  CFY <gcp> Sending task 'cloudify_agent.operations.install_plugins'
2019-08-10 15:49:36.022  CFY <gcp> Task started 'cloudify_agent.operations.install_plugins'
2019-08-10 15:49:36.353  LOG <gcp> INFO: Installing plugin: gcp_plugin
2019-08-10 15:49:37.416  LOG <gcp> INFO: Using existing installation of managed plugin: e0a99ba4-54d6-4741-a773-4ec378dc8634 [package_name: cloudify-gcp-plugin, package_version: 1.4.4, supported_platform: linux_x86_64, distribution: centos, distribution_release: core]
2019-08-10 15:49:37.416  LOG <gcp> INFO: Installing plugin: ansible
2019-08-10 15:49:38.240  LOG <gcp> INFO: Using existing installation of managed plugin: 7142c593-6e52-429a-8a71-55266c022e02 [package_name: cloudify-ansible-plugin, package_version: 2.4.0, supported_platform: linux_x86_64, distribution: centos, distribution_release: core]
2019-08-10 15:49:38.240  LOG <gcp> INFO: Installing plugin: suspend
2019-08-10 15:49:39.437  LOG <gcp> INFO: Using existing installation of managed plugin: 62c3cd35-5a18-49fd-a670-48f9ad207b05 [package_name: cloudify-utilities-plugin, package_version: 1.14.0, supported_platform: linux_x86_64, distribution: centos, distribution_release: core]
2019-08-10 15:49:39.437  LOG <gcp> INFO: Installing plugin: scalelist
2019-08-10 15:49:40.297  LOG <gcp> INFO: Using existing installation of managed plugin: 62c3cd35-5a18-49fd-a670-48f9ad207b05 [package_name: cloudify-utilities-plugin, package_version: 1.14.0, supported_platform: linux_x86_64, distribution: centos, distribution_release: core]
2019-08-10 15:49:40.297  LOG <gcp> INFO: Installing plugin: configuration
2019-08-10 15:49:41.121  LOG <gcp> INFO: Using existing installation of managed plugin: 62c3cd35-5a18-49fd-a670-48f9ad207b05 [package_name: cloudify-utilities-plugin, package_version: 1.14.0, supported_platform: linux_x86_64, distribution: centos, distribution_release: core]
2019-08-10 15:49:41.122  CFY <gcp> Task succeeded 'cloudify_agent.operations.install_plugins'
2019-08-10 15:49:41.188  CFY <gcp> Creating deployment work directory
2019-08-10 15:49:41.614  CFY <gcp> 'create_deployment_environment' workflow execution succeeded
2019-08-10 15:49:46.905  CFY <gcp> Starting 'install' workflow execution
2019-08-10 15:49:48.441  CFY <gcp> [network_rdckr0] Validating node instance before creation: nothing to do
2019-08-10 15:49:48.538  CFY <gcp> [network_rdckr0] Precreating node instance: nothing to do
2019-08-10 15:49:48.812  CFY <gcp> [network_rdckr0] Creating node instance
2019-08-10 15:49:48.989  CFY <gcp> [network_rdckr0.create] Sending task 'cloudify_gcp.compute.network.create'
2019-08-10 15:49:50.905  LOG <gcp> [network_rdckr0.create] INFO: Create network network-rdckr0
2019-08-10 15:49:53.306  CFY <gcp> [network_rdckr0.create] Task rescheduled 'cloudify_gcp.compute.network.create' -> Operation started
Traceback (most recent call last):
  File "/opt/mgmtworker/env/lib/python2.7/site-packages/cloudify/dispatch.py", line 813, in main
    payload = handler.handle()
  File "/opt/mgmtworker/env/lib/python2.7/site-packages/cloudify/dispatch.py", line 464, in handle
    raise ctx.operation._operation_retry
OperationRetry: Operation started

2019-08-10 15:50:08.409  CFY <gcp> [network_rdckr0.create] Sending task 'cloudify_gcp.compute.network.create' [retry 1/60]
2019-08-10 15:50:12.573  CFY <gcp> [network_rdckr0.create] Task rescheduled 'cloudify_gcp.compute.network.create' -> Operation not completed yet: RUNNING [retry_after=30] [retry 1/60]
Traceback (most recent call last):
  File "/opt/mgmtworker/env/lib/python2.7/site-packages/cloudify/dispatch.py", line 813, in main
    payload = handler.handle()
  File "/opt/mgmtworker/env/lib/python2.7/site-packages/cloudify/dispatch.py", line 464, in handle
    raise ctx.operation._operation_retry
OperationRetry: Operation not completed yet: RUNNING [retry_after=30]

2019-08-10 15:50:42.660  CFY <gcp> [network_rdckr0.create] Sending task 'cloudify_gcp.compute.network.create' [retry 2/60]
2019-08-10 15:50:45.806  LOG <gcp> [network_rdckr0.create] INFO: Get network network-rdckr0 details
2019-08-10 15:50:47.363  CFY <gcp> [network_rdckr0.create] Task succeeded 'cloudify_gcp.compute.network.create' [retry 2/60]
2019-08-10 15:50:47.494  CFY <gcp> [network_rdckr0] Node instance created
2019-08-10 15:50:47.776  CFY <gcp> [network_rdckr0] Configuring node instance: nothing to do
2019-08-10 15:50:47.893  CFY <gcp> [network_rdckr0] Starting node instance: nothing to do
2019-08-10 15:50:47.978  CFY <gcp> [network_rdckr0] Poststarting node instance: nothing to do
2019-08-10 15:50:48.236  CFY <gcp> [network_rdckr0] Node instance started
2019-08-10 15:50:48.850  CFY <gcp> [subnet_8tgvdv] Validating node instance before creation
2019-08-10 15:50:49.006  CFY <gcp> [subnet_8tgvdv.create] Sending task 'cloudify_gcp.compute.subnetwork.creation_validation'
2019-08-10 15:50:49.892  CFY <gcp> [firewall_vg4p7u] Validating node instance before creation: nothing to do
2019-08-10 15:50:50.060  CFY <gcp> [firewall_vg4p7u] Precreating node instance: nothing to do
2019-08-10 15:50:50.176  CFY <gcp> [firewall_vg4p7u] Creating node instance
2019-08-10 15:50:50.714  CFY <gcp> [firewall_vg4p7u.create] Sending task 'cloudify_gcp.compute.firewall.create'
2019-08-10 15:50:52.405  CFY <gcp> [subnet_8tgvdv.create] Task succeeded 'cloudify_gcp.compute.subnetwork.creation_validation'
2019-08-10 15:50:52.511  CFY <gcp> [subnet_8tgvdv] Node instance validated before creation
2019-08-10 15:50:52.678  CFY <gcp> [subnet_8tgvdv] Precreating node instance: nothing to do
2019-08-10 15:50:53.027  CFY <gcp> [subnet_8tgvdv] Creating node instance
2019-08-10 15:50:53.360  LOG <gcp> [firewall_vg4p7u.create] INFO: Create firewall rule firewall-vg4p7u in network https://www.googleapis.com/compute/v1/projects/node2faas-248113/global/networks/network-rdckr0
2019-08-10 15:50:53.388  CFY <gcp> [subnet_8tgvdv.create] Sending task 'cloudify_gcp.compute.subnetwork.create'
2019-08-10 15:50:56.065  CFY <gcp> [firewall_vg4p7u.create] Task succeeded 'cloudify_gcp.compute.firewall.create'
2019-08-10 15:50:56.081  LOG <gcp> [subnet_8tgvdv.create] INFO: Create subnetwork subnet-8tgvdv
2019-08-10 15:50:56.468  CFY <gcp> [firewall_vg4p7u] Node instance created
2019-08-10 15:50:56.578  CFY <gcp> [firewall_vg4p7u] Configuring node instance: nothing to do
2019-08-10 15:50:56.677  CFY <gcp> [firewall_vg4p7u] Starting node instance: nothing to do
2019-08-10 15:50:56.795  CFY <gcp> [firewall_vg4p7u] Poststarting node instance: nothing to do
2019-08-10 15:50:56.868  CFY <gcp> [firewall_vg4p7u] Node instance started
2019-08-10 15:50:59.196  CFY <gcp> [subnet_8tgvdv.create] Task rescheduled 'cloudify_gcp.compute.subnetwork.create' -> Operation started
Traceback (most recent call last):
  File "/opt/mgmtworker/env/lib/python2.7/site-packages/cloudify/dispatch.py", line 813, in main
    payload = handler.handle()
  File "/opt/mgmtworker/env/lib/python2.7/site-packages/cloudify/dispatch.py", line 464, in handle
    raise ctx.operation._operation_retry
OperationRetry: Operation started

2019-08-10 15:51:14.294  CFY <gcp> [subnet_8tgvdv.create] Sending task 'cloudify_gcp.compute.subnetwork.create' [retry 1/60]
2019-08-10 15:51:17.451  LOG <gcp> [subnet_8tgvdv.create] INFO: Get subnetwork subnet-8tgvdv details
2019-08-10 15:51:19.367  CFY <gcp> [subnet_8tgvdv.create] Task succeeded 'cloudify_gcp.compute.subnetwork.create' [retry 1/60]
2019-08-10 15:51:19.550  CFY <gcp> [subnet_8tgvdv] Node instance created
2019-08-10 15:51:19.720  CFY <gcp> [subnet_8tgvdv] Configuring node instance: nothing to do
2019-08-10 15:51:19.785  CFY <gcp> [subnet_8tgvdv] Starting node instance: nothing to do
2019-08-10 15:51:19.899  CFY <gcp> [subnet_8tgvdv] Poststarting node instance: nothing to do
2019-08-10 15:51:20.232  CFY <gcp> [subnet_8tgvdv] Node instance started
2019-08-10 15:51:20.790  CFY <gcp> [vm-database_aej7hb] Validating node instance before creation: nothing to do
2019-08-10 15:51:20.906  CFY <gcp> [vm-database_aej7hb] Precreating node instance: nothing to do
2019-08-10 15:51:21.140  CFY <gcp> [vm-database_aej7hb] Creating node instance
2019-08-10 15:51:21.339  CFY <gcp> [vm-database_aej7hb.create] Sending task 'script_runner.tasks.run'
2019-08-10 15:51:23.108  LOG <gcp> [vm-database_aej7hb.create] INFO: Downloaded scripts/gcp/key.py to /tmp/NJ7UP/key.py
2019-08-10 15:51:23.798  CFY <gcp> [vm-database_aej7hb.create] Task succeeded 'script_runner.tasks.run'
2019-08-10 15:51:24.028  CFY <gcp> [vm-database_aej7hb] Node instance created
2019-08-10 15:51:24.200  CFY <gcp> [vm-database_aej7hb] Configuring node instance
2019-08-10 15:51:24.509  CFY <gcp> [vm-database_aej7hb.configure] Sending task 'cloudify_gcp.compute.instance.create'
2019-08-10 15:51:26.391  LOG <gcp> [vm-database_aej7hb.configure] INFO: The script is 
2019-08-10 15:51:26.911  LOG <gcp> [vm-database_aej7hb.configure] INFO: Adding bucket to metadata
2019-08-10 15:51:26.911  LOG <gcp> [vm-database_aej7hb.configure] INFO: Adding sshKeys to metadata
2019-08-10 15:51:30.084  CFY <gcp> [vm-database_aej7hb.configure] Task rescheduled 'cloudify_gcp.compute.instance.create' -> Operation started
Traceback (most recent call last):
  File "/opt/mgmtworker/env/lib/python2.7/site-packages/cloudify/dispatch.py", line 813, in main
    payload = handler.handle()
  File "/opt/mgmtworker/env/lib/python2.7/site-packages/cloudify/dispatch.py", line 464, in handle
    raise ctx.operation._operation_retry
OperationRetry: Operation started

2019-08-10 15:51:45.159  CFY <gcp> [vm-database_aej7hb.configure] Sending task 'cloudify_gcp.compute.instance.create' [retry 1/60]
2019-08-10 15:51:47.262  LOG <gcp> [vm-database_aej7hb.configure] INFO: The script is 
2019-08-10 15:51:48.581  LOG <gcp> [vm-database_aej7hb.configure] ERROR: Response with error {u'errors': [{u'message': u"The resource '482761649285-compute@developer.gserviceaccount.com' of type 'serviceAccount' was not found.", u'code': u'EXTERNAL_RESOURCE_NOT_FOUND'}]}
2019-08-10 15:51:48.581  LOG <gcp> [vm-database_aej7hb.configure] ERROR: Error Message {u'errors': [{u'message': u"The resource '482761649285-compute@developer.gserviceaccount.com' of type 'serviceAccount' was not found.", u'code': u'EXTERNAL_RESOURCE_NOT_FOUND'}]}
Execution ended, waiting 3 seconds for additional log messages
2019-08-10 15:51:49.285  CFY <gcp> [vm-database_aej7hb.configure] Task failed 'cloudify_gcp.compute.instance.create' -> {u'errors': [{u'message': u"The resource '482761649285-compute@developer.gserviceaccount.com' of type 'serviceAccount' was not found.", u'code': u'EXTERNAL_RESOURCE_NOT_FOUND'}]} [retry 1/60]
Traceback (most recent call last):
  File "/opt/mgmtworker/env/lib/python2.7/site-packages/cloudify/dispatch.py", line 813, in main
    payload = handler.handle()
  File "/opt/mgmtworker/env/lib/python2.7/site-packages/cloudify/dispatch.py", line 461, in handle
    result = self._run_operation_func(ctx, kwargs)
  File "/opt/mgmtworker/env/lib/python2.7/site-packages/cloudify/dispatch.py", line 519, in _run_operation_func
    return self.func(*self.args, **kwargs)
  File "/opt/mgmtworker/env/plugins/default_tenant/cloudify-gcp-plugin-1.4.4/lib/python2.7/site-packages/cloudify_gcp/utils.py", line 267, in _decorator
    raise NonRecoverableError(e.message)
NonRecoverableError: {u'errors': [{u'message': u"The resource '482761649285-compute@developer.gserviceaccount.com' of type 'serviceAccount' was not found.", u'code': u'EXTERNAL_RESOURCE_NOT_FOUND'}]}

2019-08-10 15:51:49.509  CFY <gcp> 'install' workflow execution failed: RuntimeError: Workflow failed: Task failed 'cloudify_gcp.compute.instance.create' -> {u'errors': [{u'message': u"The resource '482761649285-compute@developer.gserviceaccount.com' of type 'serviceAccount' was not found.", u'code': u'EXTERNAL_RESOURCE_NOT_FOUND'}]}
Execution of workflow install for deployment gcp failed. [error=Traceback (most recent call last):
  File "/opt/mgmtworker/env/lib/python2.7/site-packages/cloudify/dispatch.py", line 664, in _remote_workflow_child_thread
    workflow_result = self._execute_workflow_function()
  File "/opt/mgmtworker/env/lib/python2.7/site-packages/cloudify/dispatch.py", line 693, in _execute_workflow_function
    result = self.func(*self.args, **self.kwargs)
  File "/opt/mgmtworker/env/lib/python2.7/site-packages/cloudify/plugins/workflows.py", line 31, in install
    node_instances=set(ctx.node_instances))
  File "/opt/mgmtworker/env/lib/python2.7/site-packages/cloudify/plugins/lifecycle.py", line 29, in install_node_instances
    processor.install()
  File "/opt/mgmtworker/env/lib/python2.7/site-packages/cloudify/plugins/lifecycle.py", line 102, in install
    graph.execute()
  File "/opt/mgmtworker/env/lib/python2.7/site-packages/cloudify/workflows/tasks_graph.py", line 237, in execute
    raise self._error
RuntimeError: Workflow failed: Task failed 'cloudify_gcp.compute.instance.create' -> {u'errors': [{u'message': u"The resource '482761649285-compute@developer.gserviceaccount.com' of type 'serviceAccount' was not found.", u'code': u'EXTERNAL_RESOURCE_NOT_FOUND'}]}
]
* Run 'cfy events list bde87da7-b61a-4adb-b0fa-9a09db1e2b13' to retrieve the execution's events/logs
