Uploading blueprint cloudify/gcp.yaml...
 gcp.yaml |############################################################| 100.0%
Blueprint uploaded. The blueprint's id is cloudify-wordpress-blueprint-gcp
Creating new deployment from blueprint cloudify-wordpress-blueprint-gcp...
Deployment created. The deployment's id is gcp
Executing workflow `install` on deployment `gcp` [timeout=900 seconds]
Deployment environment creation is pending...
2019-08-10 16:14:33.243  CFY <gcp> Starting 'create_deployment_environment' workflow execution
2019-08-10 16:14:33.248  CFY <gcp> Installing deployment and workflow plugins
2019-08-10 16:14:33.356  CFY <gcp> Sending task 'cloudify_agent.operations.install_plugins'
2019-08-10 16:14:33.364  CFY <gcp> Task started 'cloudify_agent.operations.install_plugins'
2019-08-10 16:14:33.846  LOG <gcp> INFO: Installing plugin: gcp_plugin
2019-08-10 16:14:34.915  LOG <gcp> INFO: Using existing installation of managed plugin: e0a99ba4-54d6-4741-a773-4ec378dc8634 [package_name: cloudify-gcp-plugin, package_version: 1.4.4, supported_platform: linux_x86_64, distribution: centos, distribution_release: core]
2019-08-10 16:14:34.916  LOG <gcp> INFO: Installing plugin: ansible
2019-08-10 16:14:36.184  LOG <gcp> INFO: Using existing installation of managed plugin: 7142c593-6e52-429a-8a71-55266c022e02 [package_name: cloudify-ansible-plugin, package_version: 2.4.0, supported_platform: linux_x86_64, distribution: centos, distribution_release: core]
2019-08-10 16:14:36.184  LOG <gcp> INFO: Installing plugin: suspend
2019-08-10 16:14:37.168  LOG <gcp> INFO: Using existing installation of managed plugin: 62c3cd35-5a18-49fd-a670-48f9ad207b05 [package_name: cloudify-utilities-plugin, package_version: 1.14.0, supported_platform: linux_x86_64, distribution: centos, distribution_release: core]
2019-08-10 16:14:37.168  LOG <gcp> INFO: Installing plugin: configuration
2019-08-10 16:14:38.212  LOG <gcp> INFO: Using existing installation of managed plugin: 62c3cd35-5a18-49fd-a670-48f9ad207b05 [package_name: cloudify-utilities-plugin, package_version: 1.14.0, supported_platform: linux_x86_64, distribution: centos, distribution_release: core]
2019-08-10 16:14:38.214  LOG <gcp> INFO: Installing plugin: scalelist
2019-08-10 16:14:39.632  LOG <gcp> INFO: Using existing installation of managed plugin: 62c3cd35-5a18-49fd-a670-48f9ad207b05 [package_name: cloudify-utilities-plugin, package_version: 1.14.0, supported_platform: linux_x86_64, distribution: centos, distribution_release: core]
2019-08-10 16:14:39.633  CFY <gcp> Task succeeded 'cloudify_agent.operations.install_plugins'
2019-08-10 16:14:39.700  CFY <gcp> Creating deployment work directory
2019-08-10 16:14:40.024  CFY <gcp> 'create_deployment_environment' workflow execution succeeded
2019-08-10 16:14:49.789  CFY <gcp> Starting 'install' workflow execution
2019-08-10 16:14:51.984  CFY <gcp> [network_nps0zb] Validating node instance before creation: nothing to do
2019-08-10 16:14:52.070  CFY <gcp> [network_nps0zb] Precreating node instance: nothing to do
2019-08-10 16:14:52.170  CFY <gcp> [network_nps0zb] Creating node instance
2019-08-10 16:14:52.812  CFY <gcp> [network_nps0zb.create] Sending task 'cloudify_gcp.compute.network.create'
2019-08-10 16:14:56.669  LOG <gcp> [network_nps0zb.create] INFO: Create network network-nps0zb
2019-08-10 16:15:00.024  CFY <gcp> [network_nps0zb.create] Task rescheduled 'cloudify_gcp.compute.network.create' -> Operation started
Traceback (most recent call last):
  File "/opt/mgmtworker/env/lib/python2.7/site-packages/cloudify/dispatch.py", line 813, in main
    payload = handler.handle()
  File "/opt/mgmtworker/env/lib/python2.7/site-packages/cloudify/dispatch.py", line 464, in handle
    raise ctx.operation._operation_retry
OperationRetry: Operation started

2019-08-10 16:15:15.142  CFY <gcp> [network_nps0zb.create] Sending task 'cloudify_gcp.compute.network.create' [retry 1/60]
2019-08-10 16:15:19.389  LOG <gcp> [network_nps0zb.create] INFO: Get network network-nps0zb details
2019-08-10 16:15:21.460  CFY <gcp> [network_nps0zb.create] Task succeeded 'cloudify_gcp.compute.network.create' [retry 1/60]
2019-08-10 16:15:21.743  CFY <gcp> [network_nps0zb] Node instance created
2019-08-10 16:15:21.961  CFY <gcp> [network_nps0zb] Configuring node instance: nothing to do
2019-08-10 16:15:22.243  CFY <gcp> [network_nps0zb] Starting node instance: nothing to do
2019-08-10 16:15:22.488  CFY <gcp> [network_nps0zb] Poststarting node instance: nothing to do
2019-08-10 16:15:22.675  CFY <gcp> [network_nps0zb] Node instance started
2019-08-10 16:15:23.681  CFY <gcp> [subnet_x2jntq] Validating node instance before creation
2019-08-10 16:15:23.789  CFY <gcp> [firewall_kbvt07] Validating node instance before creation: nothing to do
2019-08-10 16:15:23.925  CFY <gcp> [subnet_x2jntq.create] Sending task 'cloudify_gcp.compute.subnetwork.creation_validation'
2019-08-10 16:15:24.903  CFY <gcp> [firewall_kbvt07] Precreating node instance: nothing to do
2019-08-10 16:15:25.120  CFY <gcp> [firewall_kbvt07] Creating node instance
2019-08-10 16:15:25.960  CFY <gcp> [firewall_kbvt07.create] Sending task 'cloudify_gcp.compute.firewall.create'
2019-08-10 16:15:28.256  CFY <gcp> [subnet_x2jntq.create] Task succeeded 'cloudify_gcp.compute.subnetwork.creation_validation'
2019-08-10 16:15:28.315  CFY <gcp> [subnet_x2jntq] Node instance validated before creation
2019-08-10 16:15:28.605  CFY <gcp> [subnet_x2jntq] Precreating node instance: nothing to do
2019-08-10 16:15:28.848  CFY <gcp> [subnet_x2jntq] Creating node instance
2019-08-10 16:15:29.502  CFY <gcp> [subnet_x2jntq.create] Sending task 'cloudify_gcp.compute.subnetwork.create'
2019-08-10 16:15:29.836  LOG <gcp> [firewall_kbvt07.create] INFO: Create firewall rule firewall-kbvt07 in network https://www.googleapis.com/compute/v1/projects/node2faas-248113/global/networks/network-nps0zb
2019-08-10 16:15:33.000  CFY <gcp> [firewall_kbvt07.create] Task succeeded 'cloudify_gcp.compute.firewall.create'
2019-08-10 16:15:33.615  CFY <gcp> [firewall_kbvt07] Node instance created
2019-08-10 16:15:33.735  LOG <gcp> [subnet_x2jntq.create] INFO: Create subnetwork subnet-x2jntq
2019-08-10 16:15:33.925  CFY <gcp> [firewall_kbvt07] Configuring node instance: nothing to do
2019-08-10 16:15:34.142  CFY <gcp> [firewall_kbvt07] Starting node instance: nothing to do
2019-08-10 16:15:34.544  CFY <gcp> [firewall_kbvt07] Poststarting node instance: nothing to do
2019-08-10 16:15:34.650  CFY <gcp> [firewall_kbvt07] Node instance started
2019-08-10 16:15:37.312  CFY <gcp> [subnet_x2jntq.create] Task rescheduled 'cloudify_gcp.compute.subnetwork.create' -> Operation started
Traceback (most recent call last):
  File "/opt/mgmtworker/env/lib/python2.7/site-packages/cloudify/dispatch.py", line 813, in main
    payload = handler.handle()
  File "/opt/mgmtworker/env/lib/python2.7/site-packages/cloudify/dispatch.py", line 464, in handle
    raise ctx.operation._operation_retry
OperationRetry: Operation started

2019-08-10 16:15:52.452  CFY <gcp> [subnet_x2jntq.create] Sending task 'cloudify_gcp.compute.subnetwork.create' [retry 1/60]
2019-08-10 16:15:56.995  CFY <gcp> [subnet_x2jntq.create] Task rescheduled 'cloudify_gcp.compute.subnetwork.create' -> Operation not completed yet: RUNNING [retry_after=30] [retry 1/60]
Traceback (most recent call last):
  File "/opt/mgmtworker/env/lib/python2.7/site-packages/cloudify/dispatch.py", line 813, in main
    payload = handler.handle()
  File "/opt/mgmtworker/env/lib/python2.7/site-packages/cloudify/dispatch.py", line 464, in handle
    raise ctx.operation._operation_retry
OperationRetry: Operation not completed yet: RUNNING [retry_after=30]

2019-08-10 16:16:27.112  CFY <gcp> [subnet_x2jntq.create] Sending task 'cloudify_gcp.compute.subnetwork.create' [retry 2/60]
2019-08-10 16:16:31.197  LOG <gcp> [subnet_x2jntq.create] INFO: Get subnetwork subnet-x2jntq details
2019-08-10 16:16:32.817  CFY <gcp> [subnet_x2jntq.create] Task succeeded 'cloudify_gcp.compute.subnetwork.create' [retry 2/60]
2019-08-10 16:16:32.849  CFY <gcp> [subnet_x2jntq] Node instance created
2019-08-10 16:16:33.175  CFY <gcp> [subnet_x2jntq] Configuring node instance: nothing to do
2019-08-10 16:16:33.251  CFY <gcp> [subnet_x2jntq] Starting node instance: nothing to do
2019-08-10 16:16:33.378  CFY <gcp> [subnet_x2jntq] Poststarting node instance: nothing to do
2019-08-10 16:16:33.655  CFY <gcp> [subnet_x2jntq] Node instance started
2019-08-10 16:16:34.379  CFY <gcp> [vm-database_6vdfwh] Validating node instance before creation: nothing to do
2019-08-10 16:16:34.481  CFY <gcp> [vm-database_6vdfwh] Precreating node instance: nothing to do
2019-08-10 16:16:34.584  CFY <gcp> [vm-database_6vdfwh] Creating node instance
2019-08-10 16:16:35.041  CFY <gcp> [vm-database_6vdfwh.create] Sending task 'script_runner.tasks.run'
2019-08-10 16:16:37.391  LOG <gcp> [vm-database_6vdfwh.create] INFO: Downloaded scripts/gcp/key.py to /tmp/7ZMG2/key.py
2019-08-10 16:16:38.127  CFY <gcp> [vm-database_6vdfwh.create] Task succeeded 'script_runner.tasks.run'
2019-08-10 16:16:38.236  CFY <gcp> [vm-database_6vdfwh] Node instance created
2019-08-10 16:16:38.933  CFY <gcp> [vm-database_6vdfwh] Configuring node instance
2019-08-10 16:16:39.250  CFY <gcp> [vm-database_6vdfwh.configure] Sending task 'cloudify_gcp.compute.instance.create'
2019-08-10 16:16:41.320  LOG <gcp> [vm-database_6vdfwh.configure] INFO: The script is 
2019-08-10 16:16:41.694  LOG <gcp> [vm-database_6vdfwh.configure] INFO: Adding bucket to metadata
2019-08-10 16:16:41.694  LOG <gcp> [vm-database_6vdfwh.configure] INFO: Adding sshKeys to metadata
2019-08-10 16:16:45.761  CFY <gcp> [vm-database_6vdfwh.configure] Task rescheduled 'cloudify_gcp.compute.instance.create' -> Operation started
Traceback (most recent call last):
  File "/opt/mgmtworker/env/lib/python2.7/site-packages/cloudify/dispatch.py", line 813, in main
    payload = handler.handle()
  File "/opt/mgmtworker/env/lib/python2.7/site-packages/cloudify/dispatch.py", line 464, in handle
    raise ctx.operation._operation_retry
OperationRetry: Operation started

2019-08-10 16:17:00.856  CFY <gcp> [vm-database_6vdfwh.configure] Sending task 'cloudify_gcp.compute.instance.create' [retry 1/60]
2019-08-10 16:17:03.125  LOG <gcp> [vm-database_6vdfwh.configure] INFO: The script is 
2019-08-10 16:17:04.496  LOG <gcp> [vm-database_6vdfwh.configure] ERROR: Response with error {u'errors': [{u'message': u"The resource '482761649285-compute@developer.gserviceaccount.com' of type 'serviceAccount' was not found.", u'code': u'EXTERNAL_RESOURCE_NOT_FOUND'}]}
2019-08-10 16:17:04.497  LOG <gcp> [vm-database_6vdfwh.configure] ERROR: Error Message {u'errors': [{u'message': u"The resource '482761649285-compute@developer.gserviceaccount.com' of type 'serviceAccount' was not found.", u'code': u'EXTERNAL_RESOURCE_NOT_FOUND'}]}
2019-08-10 16:17:05.520  CFY <gcp> [vm-database_6vdfwh.configure] Task failed 'cloudify_gcp.compute.instance.create' -> {u'errors': [{u'message': u"The resource '482761649285-compute@developer.gserviceaccount.com' of type 'serviceAccount' was not found.", u'code': u'EXTERNAL_RESOURCE_NOT_FOUND'}]} [retry 1/60]
Traceback (most recent call last):
  File "/opt/mgmtworker/env/lib/python2.7/site-packages/cloudify/dispatch.py", line 813, in main
    payload = handler.handle()
  File "/opt/mgmtworker/env/lib/python2.7/site-packages/cloudify/dispatch.py", line 461, in handle
    result = self._run_operation_func(ctx, kwargs)
  File "/opt/mgmtworker/env/lib/python2.7/site-packages/cloudify/dispatch.py", line 519, in _run_operation_func
    return self.func(*self.args, **kwargs)
  File "/opt/mgmtworker/env/plugins/default_tenant/cloudify-gcp-plugin-1.4.4/lib/python2.7/site-packages/cloudify_gcp/utils.py", line 267, in _decorator
    raise NonRecoverableError(e.message)
NonRecoverableError: {u'errors': [{u'message': u"The resource '482761649285-compute@developer.gserviceaccount.com' of type 'serviceAccount' was not found.", u'code': u'EXTERNAL_RESOURCE_NOT_FOUND'}]}

2019-08-10 16:17:05.937  CFY <gcp> 'install' workflow execution failed: RuntimeError: Workflow failed: Task failed 'cloudify_gcp.compute.instance.create' -> {u'errors': [{u'message': u"The resource '482761649285-compute@developer.gserviceaccount.com' of type 'serviceAccount' was not found.", u'code': u'EXTERNAL_RESOURCE_NOT_FOUND'}]}
Execution of workflow install for deployment gcp failed. [error=Traceback (most recent call last):
  File "/opt/mgmtworker/env/lib/python2.7/site-packages/cloudify/dispatch.py", line 664, in _remote_workflow_child_thread
    workflow_result = self._execute_workflow_function()
  File "/opt/mgmtworker/env/lib/python2.7/site-packages/cloudify/dispatch.py", line 693, in _execute_workflow_function
    result = self.func(*self.args, **self.kwargs)
  File "/opt/mgmtworker/env/lib/python2.7/site-packages/cloudify/plugins/workflows.py", line 31, in install
    node_instances=set(ctx.node_instances))
  File "/opt/mgmtworker/env/lib/python2.7/site-packages/cloudify/plugins/lifecycle.py", line 29, in install_node_instances
    processor.install()
  File "/opt/mgmtworker/env/lib/python2.7/site-packages/cloudify/plugins/lifecycle.py", line 102, in install
    graph.execute()
  File "/opt/mgmtworker/env/lib/python2.7/site-packages/cloudify/workflows/tasks_graph.py", line 237, in execute
    raise self._error
RuntimeError: Workflow failed: Task failed 'cloudify_gcp.compute.instance.create' -> {u'errors': [{u'message': u"The resource '482761649285-compute@developer.gserviceaccount.com' of type 'serviceAccount' was not found.", u'code': u'EXTERNAL_RESOURCE_NOT_FOUND'}]}
]
* Run 'cfy events list e97f707f-3d39-408f-9874-d4f91a5dd47a' to retrieve the execution's events/logs
