Uploading blueprint cloudify/gcp.yaml...
 gcp.yaml |############################################################| 100.0%
Blueprint uploaded. The blueprint's id is cloudify-wordpress-blueprint-gcp
Creating new deployment from blueprint cloudify-wordpress-blueprint-gcp...
Deployment created. The deployment's id is gcp
Executing workflow `install` on deployment `gcp` [timeout=900 seconds]
Deployment environment creation is pending...
2019-08-08 13:55:42.794  CFY <gcp> Starting 'create_deployment_environment' workflow execution
2019-08-08 13:55:42.798  CFY <gcp> Installing deployment and workflow plugins
2019-08-08 13:55:42.900  CFY <gcp> Sending task 'cloudify_agent.operations.install_plugins'
2019-08-08 13:55:42.915  CFY <gcp> Task started 'cloudify_agent.operations.install_plugins'
2019-08-08 13:55:43.339  LOG <gcp> INFO: Installing plugin: gcp_plugin
2019-08-08 13:55:44.474  LOG <gcp> INFO: Using existing installation of managed plugin: e0a99ba4-54d6-4741-a773-4ec378dc8634 [package_name: cloudify-gcp-plugin, package_version: 1.4.4, supported_platform: linux_x86_64, distribution: centos, distribution_release: core]
2019-08-08 13:55:44.474  LOG <gcp> INFO: Installing plugin: ansible
2019-08-08 13:55:45.505  LOG <gcp> INFO: Using existing installation of managed plugin: 7142c593-6e52-429a-8a71-55266c022e02 [package_name: cloudify-ansible-plugin, package_version: 2.4.0, supported_platform: linux_x86_64, distribution: centos, distribution_release: core]
2019-08-08 13:55:45.505  LOG <gcp> INFO: Installing plugin: suspend
2019-08-08 13:55:46.560  LOG <gcp> INFO: Using existing installation of managed plugin: 62c3cd35-5a18-49fd-a670-48f9ad207b05 [package_name: cloudify-utilities-plugin, package_version: 1.14.0, supported_platform: linux_x86_64, distribution: centos, distribution_release: core]
2019-08-08 13:55:46.560  LOG <gcp> INFO: Installing plugin: configuration
2019-08-08 13:55:47.452  LOG <gcp> INFO: Using existing installation of managed plugin: 62c3cd35-5a18-49fd-a670-48f9ad207b05 [package_name: cloudify-utilities-plugin, package_version: 1.14.0, supported_platform: linux_x86_64, distribution: centos, distribution_release: core]
2019-08-08 13:55:47.452  LOG <gcp> INFO: Installing plugin: scalelist
2019-08-08 13:55:49.184  LOG <gcp> INFO: Using existing installation of managed plugin: 62c3cd35-5a18-49fd-a670-48f9ad207b05 [package_name: cloudify-utilities-plugin, package_version: 1.14.0, supported_platform: linux_x86_64, distribution: centos, distribution_release: core]
2019-08-08 13:55:49.185  CFY <gcp> Task succeeded 'cloudify_agent.operations.install_plugins'
2019-08-08 13:55:49.186  CFY <gcp> Creating deployment work directory
2019-08-08 13:55:49.494  CFY <gcp> 'create_deployment_environment' workflow execution succeeded
2019-08-08 13:55:54.253  CFY <gcp> Starting 'install' workflow execution
2019-08-08 13:55:56.196  CFY <gcp> [network_9f3z8m] Validating node instance before creation: nothing to do
2019-08-08 13:55:56.417  CFY <gcp> [network_9f3z8m] Precreating node instance: nothing to do
2019-08-08 13:55:56.717  CFY <gcp> [network_9f3z8m] Creating node instance
2019-08-08 13:55:57.288  CFY <gcp> [network_9f3z8m.create] Sending task 'cloudify_gcp.compute.network.create'
2019-08-08 13:55:59.410  LOG <gcp> [network_9f3z8m.create] INFO: Create network network-9f3z8m
2019-08-08 13:56:02.045  CFY <gcp> [network_9f3z8m.create] Task rescheduled 'cloudify_gcp.compute.network.create' -> Operation started
Traceback (most recent call last):
  File "/opt/mgmtworker/env/lib/python2.7/site-packages/cloudify/dispatch.py", line 813, in main
    payload = handler.handle()
  File "/opt/mgmtworker/env/lib/python2.7/site-packages/cloudify/dispatch.py", line 464, in handle
    raise ctx.operation._operation_retry
OperationRetry: Operation started

2019-08-08 13:56:17.164  CFY <gcp> [network_9f3z8m.create] Sending task 'cloudify_gcp.compute.network.create' [retry 1/60]
2019-08-08 13:56:21.512  LOG <gcp> [network_9f3z8m.create] INFO: Get network network-9f3z8m details
2019-08-08 13:56:23.407  CFY <gcp> [network_9f3z8m.create] Task succeeded 'cloudify_gcp.compute.network.create' [retry 1/60]
2019-08-08 13:56:23.482  CFY <gcp> [network_9f3z8m] Node instance created
2019-08-08 13:56:23.779  CFY <gcp> [network_9f3z8m] Configuring node instance: nothing to do
2019-08-08 13:56:23.896  CFY <gcp> [network_9f3z8m] Starting node instance: nothing to do
2019-08-08 13:56:23.990  CFY <gcp> [network_9f3z8m] Poststarting node instance: nothing to do
2019-08-08 13:56:24.086  CFY <gcp> [network_9f3z8m] Node instance started
2019-08-08 13:56:25.038  CFY <gcp> [subnet_lflue4] Validating node instance before creation
2019-08-08 13:56:25.167  CFY <gcp> [firewall_59yh63] Validating node instance before creation: nothing to do
2019-08-08 13:56:25.239  CFY <gcp> [subnet_lflue4.create] Sending task 'cloudify_gcp.compute.subnetwork.creation_validation'
2019-08-08 13:56:26.211  CFY <gcp> [firewall_59yh63] Precreating node instance: nothing to do
2019-08-08 13:56:26.908  CFY <gcp> [firewall_59yh63] Creating node instance
2019-08-08 13:56:27.297  CFY <gcp> [firewall_59yh63.create] Sending task 'cloudify_gcp.compute.firewall.create'
2019-08-08 13:56:29.170  CFY <gcp> [subnet_lflue4.create] Task succeeded 'cloudify_gcp.compute.subnetwork.creation_validation'
2019-08-08 13:56:29.227  CFY <gcp> [subnet_lflue4] Node instance validated before creation
2019-08-08 13:56:29.457  CFY <gcp> [subnet_lflue4] Precreating node instance: nothing to do
2019-08-08 13:56:30.095  CFY <gcp> [subnet_lflue4] Creating node instance
2019-08-08 13:56:30.391  LOG <gcp> [firewall_59yh63.create] INFO: Create firewall rule firewall-59yh63 in network https://www.googleapis.com/compute/v1/projects/node2faas-248113/global/networks/network-9f3z8m
2019-08-08 13:56:30.518  CFY <gcp> [subnet_lflue4.create] Sending task 'cloudify_gcp.compute.subnetwork.create'
2019-08-08 13:56:32.810  LOG <gcp> [subnet_lflue4.create] INFO: Create subnetwork subnet-lflue4
2019-08-08 13:56:33.190  CFY <gcp> [firewall_59yh63.create] Task succeeded 'cloudify_gcp.compute.firewall.create'
2019-08-08 13:56:33.257  CFY <gcp> [firewall_59yh63] Node instance created
2019-08-08 13:56:33.616  CFY <gcp> [firewall_59yh63] Configuring node instance: nothing to do
2019-08-08 13:56:33.784  CFY <gcp> [firewall_59yh63] Starting node instance: nothing to do
2019-08-08 13:56:34.014  CFY <gcp> [firewall_59yh63] Poststarting node instance: nothing to do
2019-08-08 13:56:34.357  CFY <gcp> [firewall_59yh63] Node instance started
2019-08-08 13:56:35.686  CFY <gcp> [subnet_lflue4.create] Task rescheduled 'cloudify_gcp.compute.subnetwork.create' -> Operation started
Traceback (most recent call last):
  File "/opt/mgmtworker/env/lib/python2.7/site-packages/cloudify/dispatch.py", line 813, in main
    payload = handler.handle()
  File "/opt/mgmtworker/env/lib/python2.7/site-packages/cloudify/dispatch.py", line 464, in handle
    raise ctx.operation._operation_retry
OperationRetry: Operation started

2019-08-08 13:56:50.834  CFY <gcp> [subnet_lflue4.create] Sending task 'cloudify_gcp.compute.subnetwork.create' [retry 1/60]
2019-08-08 13:56:54.309  LOG <gcp> [subnet_lflue4.create] INFO: Get subnetwork subnet-lflue4 details
2019-08-08 13:56:55.910  CFY <gcp> [subnet_lflue4.create] Task succeeded 'cloudify_gcp.compute.subnetwork.create' [retry 1/60]
2019-08-08 13:56:56.120  CFY <gcp> [subnet_lflue4] Node instance created
2019-08-08 13:56:56.240  CFY <gcp> [subnet_lflue4] Configuring node instance: nothing to do
2019-08-08 13:56:56.328  CFY <gcp> [subnet_lflue4] Starting node instance: nothing to do
2019-08-08 13:56:56.454  CFY <gcp> [subnet_lflue4] Poststarting node instance: nothing to do
2019-08-08 13:56:56.961  CFY <gcp> [subnet_lflue4] Node instance started
2019-08-08 13:56:57.461  CFY <gcp> [vm-database_na3da3] Validating node instance before creation: nothing to do
2019-08-08 13:56:57.720  CFY <gcp> [vm-database_na3da3] Precreating node instance: nothing to do
2019-08-08 13:56:57.842  CFY <gcp> [vm-database_na3da3] Creating node instance
2019-08-08 13:56:58.175  CFY <gcp> [vm-database_na3da3.create] Sending task 'script_runner.tasks.run'
2019-08-08 13:57:00.245  LOG <gcp> [vm-database_na3da3.create] INFO: Downloaded scripts/gcp/key.py to /tmp/4225F/key.py
2019-08-08 13:57:00.887  CFY <gcp> [vm-database_na3da3.create] Task succeeded 'script_runner.tasks.run'
2019-08-08 13:57:01.132  CFY <gcp> [vm-database_na3da3] Node instance created
2019-08-08 13:57:01.255  CFY <gcp> [vm-database_na3da3] Configuring node instance
2019-08-08 13:57:01.615  CFY <gcp> [vm-database_na3da3.configure] Sending task 'cloudify_gcp.compute.instance.create'
2019-08-08 13:57:03.951  LOG <gcp> [vm-database_na3da3.configure] INFO: The script is 
2019-08-08 13:57:04.235  LOG <gcp> [vm-database_na3da3.configure] INFO: Adding bucket to metadata
2019-08-08 13:57:04.235  LOG <gcp> [vm-database_na3da3.configure] INFO: Adding sshKeys to metadata
2019-08-08 13:57:06.574  CFY <gcp> [vm-database_na3da3.configure] Task rescheduled 'cloudify_gcp.compute.instance.create' -> Operation started
Traceback (most recent call last):
  File "/opt/mgmtworker/env/lib/python2.7/site-packages/cloudify/dispatch.py", line 813, in main
    payload = handler.handle()
  File "/opt/mgmtworker/env/lib/python2.7/site-packages/cloudify/dispatch.py", line 464, in handle
    raise ctx.operation._operation_retry
OperationRetry: Operation started

2019-08-08 13:57:21.701  CFY <gcp> [vm-database_na3da3.configure] Sending task 'cloudify_gcp.compute.instance.create' [retry 1/60]
2019-08-08 13:57:24.246  LOG <gcp> [vm-database_na3da3.configure] INFO: The script is 
2019-08-08 13:57:25.537  LOG <gcp> [vm-database_na3da3.configure] ERROR: Response with error {u'errors': [{u'message': u"The resource '482761649285-compute@developer.gserviceaccount.com' of type 'serviceAccount' was not found.", u'code': u'EXTERNAL_RESOURCE_NOT_FOUND'}]}
2019-08-08 13:57:25.537  LOG <gcp> [vm-database_na3da3.configure] ERROR: Error Message {u'errors': [{u'message': u"The resource '482761649285-compute@developer.gserviceaccount.com' of type 'serviceAccount' was not found.", u'code': u'EXTERNAL_RESOURCE_NOT_FOUND'}]}
2019-08-08 13:57:26.217  CFY <gcp> [vm-database_na3da3.configure] Task failed 'cloudify_gcp.compute.instance.create' -> {u'errors': [{u'message': u"The resource '482761649285-compute@developer.gserviceaccount.com' of type 'serviceAccount' was not found.", u'code': u'EXTERNAL_RESOURCE_NOT_FOUND'}]} [retry 1/60]
Traceback (most recent call last):
  File "/opt/mgmtworker/env/lib/python2.7/site-packages/cloudify/dispatch.py", line 813, in main
    payload = handler.handle()
  File "/opt/mgmtworker/env/lib/python2.7/site-packages/cloudify/dispatch.py", line 461, in handle
    result = self._run_operation_func(ctx, kwargs)
  File "/opt/mgmtworker/env/lib/python2.7/site-packages/cloudify/dispatch.py", line 519, in _run_operation_func
    return self.func(*self.args, **kwargs)
  File "/opt/mgmtworker/env/plugins/default_tenant/cloudify-gcp-plugin-1.4.4/lib/python2.7/site-packages/cloudify_gcp/utils.py", line 267, in _decorator
    raise NonRecoverableError(e.message)
NonRecoverableError: {u'errors': [{u'message': u"The resource '482761649285-compute@developer.gserviceaccount.com' of type 'serviceAccount' was not found.", u'code': u'EXTERNAL_RESOURCE_NOT_FOUND'}]}

Execution ended, waiting 3 seconds for additional log messages
2019-08-08 13:57:26.596  CFY <gcp> 'install' workflow execution failed: RuntimeError: Workflow failed: Task failed 'cloudify_gcp.compute.instance.create' -> {u'errors': [{u'message': u"The resource '482761649285-compute@developer.gserviceaccount.com' of type 'serviceAccount' was not found.", u'code': u'EXTERNAL_RESOURCE_NOT_FOUND'}]}
Execution of workflow install for deployment gcp failed. [error=Traceback (most recent call last):
  File "/opt/mgmtworker/env/lib/python2.7/site-packages/cloudify/dispatch.py", line 664, in _remote_workflow_child_thread
    workflow_result = self._execute_workflow_function()
  File "/opt/mgmtworker/env/lib/python2.7/site-packages/cloudify/dispatch.py", line 693, in _execute_workflow_function
    result = self.func(*self.args, **self.kwargs)
  File "/opt/mgmtworker/env/lib/python2.7/site-packages/cloudify/plugins/workflows.py", line 31, in install
    node_instances=set(ctx.node_instances))
  File "/opt/mgmtworker/env/lib/python2.7/site-packages/cloudify/plugins/lifecycle.py", line 29, in install_node_instances
    processor.install()
  File "/opt/mgmtworker/env/lib/python2.7/site-packages/cloudify/plugins/lifecycle.py", line 102, in install
    graph.execute()
  File "/opt/mgmtworker/env/lib/python2.7/site-packages/cloudify/workflows/tasks_graph.py", line 237, in execute
    raise self._error
RuntimeError: Workflow failed: Task failed 'cloudify_gcp.compute.instance.create' -> {u'errors': [{u'message': u"The resource '482761649285-compute@developer.gserviceaccount.com' of type 'serviceAccount' was not found.", u'code': u'EXTERNAL_RESOURCE_NOT_FOUND'}]}
]
* Run 'cfy events list b58cc21f-976b-4ac3-9e51-d50e682cc912' to retrieve the execution's events/logs
