Uploading blueprint cloudify/gcp.yaml...
 gcp.yaml |############################################################| 100.0%
Blueprint uploaded. The blueprint's id is cloudify-wordpress-blueprint-gcp
Creating new deployment from blueprint cloudify-wordpress-blueprint-gcp...
Deployment created. The deployment's id is gcp
Executing workflow `install` on deployment `gcp` [timeout=900 seconds]
Deployment environment creation is pending...
2019-08-10 16:20:53.829  CFY <gcp> Starting 'create_deployment_environment' workflow execution
2019-08-10 16:20:53.833  CFY <gcp> Installing deployment and workflow plugins
2019-08-10 16:20:53.934  CFY <gcp> Sending task 'cloudify_agent.operations.install_plugins'
2019-08-10 16:20:53.950  CFY <gcp> Task started 'cloudify_agent.operations.install_plugins'
2019-08-10 16:20:54.348  LOG <gcp> INFO: Installing plugin: gcp_plugin
2019-08-10 16:20:55.630  LOG <gcp> INFO: Using existing installation of managed plugin: e0a99ba4-54d6-4741-a773-4ec378dc8634 [package_name: cloudify-gcp-plugin, package_version: 1.4.4, supported_platform: linux_x86_64, distribution: centos, distribution_release: core]
2019-08-10 16:20:55.631  LOG <gcp> INFO: Installing plugin: ansible
2019-08-10 16:20:57.093  LOG <gcp> INFO: Using existing installation of managed plugin: 7142c593-6e52-429a-8a71-55266c022e02 [package_name: cloudify-ansible-plugin, package_version: 2.4.0, supported_platform: linux_x86_64, distribution: centos, distribution_release: core]
2019-08-10 16:20:57.094  LOG <gcp> INFO: Installing plugin: suspend
2019-08-10 16:20:58.491  LOG <gcp> INFO: Using existing installation of managed plugin: 62c3cd35-5a18-49fd-a670-48f9ad207b05 [package_name: cloudify-utilities-plugin, package_version: 1.14.0, supported_platform: linux_x86_64, distribution: centos, distribution_release: core]
2019-08-10 16:20:58.491  LOG <gcp> INFO: Installing plugin: configuration
2019-08-10 16:20:59.576  LOG <gcp> INFO: Using existing installation of managed plugin: 62c3cd35-5a18-49fd-a670-48f9ad207b05 [package_name: cloudify-utilities-plugin, package_version: 1.14.0, supported_platform: linux_x86_64, distribution: centos, distribution_release: core]
2019-08-10 16:20:59.576  LOG <gcp> INFO: Installing plugin: scalelist
2019-08-10 16:21:00.881  LOG <gcp> INFO: Using existing installation of managed plugin: 62c3cd35-5a18-49fd-a670-48f9ad207b05 [package_name: cloudify-utilities-plugin, package_version: 1.14.0, supported_platform: linux_x86_64, distribution: centos, distribution_release: core]
2019-08-10 16:21:00.882  CFY <gcp> Task succeeded 'cloudify_agent.operations.install_plugins'
2019-08-10 16:21:00.951  CFY <gcp> Creating deployment work directory
2019-08-10 16:21:01.299  CFY <gcp> 'create_deployment_environment' workflow execution succeeded
2019-08-10 16:21:05.256  CFY <gcp> Starting 'install' workflow execution
2019-08-10 16:21:07.143  CFY <gcp> [network_2xywku] Validating node instance before creation: nothing to do
2019-08-10 16:21:07.381  CFY <gcp> [network_2xywku] Precreating node instance: nothing to do
2019-08-10 16:21:07.790  CFY <gcp> [network_2xywku] Creating node instance
2019-08-10 16:21:08.031  CFY <gcp> [network_2xywku.create] Sending task 'cloudify_gcp.compute.network.create'
2019-08-10 16:21:10.013  LOG <gcp> [network_2xywku.create] INFO: Create network network-2xywku
2019-08-10 16:21:12.503  CFY <gcp> [network_2xywku.create] Task rescheduled 'cloudify_gcp.compute.network.create' -> Operation started
Traceback (most recent call last):
  File "/opt/mgmtworker/env/lib/python2.7/site-packages/cloudify/dispatch.py", line 813, in main
    payload = handler.handle()
  File "/opt/mgmtworker/env/lib/python2.7/site-packages/cloudify/dispatch.py", line 464, in handle
    raise ctx.operation._operation_retry
OperationRetry: Operation started

2019-08-10 16:21:27.773  CFY <gcp> [network_2xywku.create] Sending task 'cloudify_gcp.compute.network.create' [retry 1/60]
2019-08-10 16:21:31.553  LOG <gcp> [network_2xywku.create] INFO: Get network network-2xywku details
2019-08-10 16:21:33.427  CFY <gcp> [network_2xywku.create] Task succeeded 'cloudify_gcp.compute.network.create' [retry 1/60]
2019-08-10 16:21:33.448  CFY <gcp> [network_2xywku] Node instance created
2019-08-10 16:21:33.881  CFY <gcp> [network_2xywku] Configuring node instance: nothing to do
2019-08-10 16:21:33.963  CFY <gcp> [network_2xywku] Starting node instance: nothing to do
2019-08-10 16:21:34.073  CFY <gcp> [network_2xywku] Poststarting node instance: nothing to do
2019-08-10 16:21:34.389  CFY <gcp> [network_2xywku] Node instance started
2019-08-10 16:21:35.347  CFY <gcp> [firewall_wbampi] Validating node instance before creation: nothing to do
2019-08-10 16:21:35.410  CFY <gcp> [subnet_zi6qnx] Validating node instance before creation
2019-08-10 16:21:35.473  CFY <gcp> [firewall_wbampi] Precreating node instance: nothing to do
2019-08-10 16:21:35.650  CFY <gcp> [subnet_zi6qnx.create] Sending task 'cloudify_gcp.compute.subnetwork.creation_validation'
2019-08-10 16:21:36.874  CFY <gcp> [firewall_wbampi] Creating node instance
2019-08-10 16:21:37.083  CFY <gcp> [firewall_wbampi.create] Sending task 'cloudify_gcp.compute.firewall.create'
2019-08-10 16:21:40.416  CFY <gcp> [subnet_zi6qnx.create] Task succeeded 'cloudify_gcp.compute.subnetwork.creation_validation'
2019-08-10 16:21:40.502  CFY <gcp> [subnet_zi6qnx] Node instance validated before creation
2019-08-10 16:21:40.696  CFY <gcp> [subnet_zi6qnx] Precreating node instance: nothing to do
2019-08-10 16:21:41.569  CFY <gcp> [subnet_zi6qnx] Creating node instance
2019-08-10 16:21:41.718  LOG <gcp> [firewall_wbampi.create] INFO: Create firewall rule firewall-wbampi in network https://www.googleapis.com/compute/v1/projects/node2faas-248113/global/networks/network-2xywku
2019-08-10 16:21:42.061  CFY <gcp> [subnet_zi6qnx.create] Sending task 'cloudify_gcp.compute.subnetwork.create'
2019-08-10 16:21:44.878  LOG <gcp> [subnet_zi6qnx.create] INFO: Create subnetwork subnet-zi6qnx
2019-08-10 16:21:45.322  CFY <gcp> [firewall_wbampi.create] Task succeeded 'cloudify_gcp.compute.firewall.create'
2019-08-10 16:21:45.985  CFY <gcp> [firewall_wbampi] Node instance created
2019-08-10 16:21:46.187  CFY <gcp> [firewall_wbampi] Configuring node instance: nothing to do
2019-08-10 16:21:46.388  CFY <gcp> [firewall_wbampi] Starting node instance: nothing to do
2019-08-10 16:21:46.568  CFY <gcp> [firewall_wbampi] Poststarting node instance: nothing to do
2019-08-10 16:21:46.670  CFY <gcp> [firewall_wbampi] Node instance started
2019-08-10 16:21:48.061  CFY <gcp> [subnet_zi6qnx.create] Task rescheduled 'cloudify_gcp.compute.subnetwork.create' -> Operation started
Traceback (most recent call last):
  File "/opt/mgmtworker/env/lib/python2.7/site-packages/cloudify/dispatch.py", line 813, in main
    payload = handler.handle()
  File "/opt/mgmtworker/env/lib/python2.7/site-packages/cloudify/dispatch.py", line 464, in handle
    raise ctx.operation._operation_retry
OperationRetry: Operation started

2019-08-10 16:22:03.212  CFY <gcp> [subnet_zi6qnx.create] Sending task 'cloudify_gcp.compute.subnetwork.create' [retry 1/60]
2019-08-10 16:22:06.953  LOG <gcp> [subnet_zi6qnx.create] INFO: Get subnetwork subnet-zi6qnx details
2019-08-10 16:22:09.486  CFY <gcp> [subnet_zi6qnx.create] Task succeeded 'cloudify_gcp.compute.subnetwork.create' [retry 1/60]
2019-08-10 16:22:09.577  CFY <gcp> [subnet_zi6qnx] Node instance created
2019-08-10 16:22:09.996  CFY <gcp> [subnet_zi6qnx] Configuring node instance: nothing to do
2019-08-10 16:22:10.176  CFY <gcp> [subnet_zi6qnx] Starting node instance: nothing to do
2019-08-10 16:22:10.259  CFY <gcp> [subnet_zi6qnx] Poststarting node instance: nothing to do
2019-08-10 16:22:10.364  CFY <gcp> [subnet_zi6qnx] Node instance started
2019-08-10 16:22:11.160  CFY <gcp> [vm-database_g0zbrf] Validating node instance before creation: nothing to do
2019-08-10 16:22:11.342  CFY <gcp> [vm-database_g0zbrf] Precreating node instance: nothing to do
2019-08-10 16:22:11.414  CFY <gcp> [vm-database_g0zbrf] Creating node instance
2019-08-10 16:22:11.806  CFY <gcp> [vm-database_g0zbrf.create] Sending task 'script_runner.tasks.run'
2019-08-10 16:22:13.816  LOG <gcp> [vm-database_g0zbrf.create] INFO: Downloaded scripts/gcp/key.py to /tmp/RF2RM/key.py
2019-08-10 16:22:14.691  CFY <gcp> [vm-database_g0zbrf.create] Task succeeded 'script_runner.tasks.run'
2019-08-10 16:22:14.808  CFY <gcp> [vm-database_g0zbrf] Node instance created
2019-08-10 16:22:15.177  CFY <gcp> [vm-database_g0zbrf] Configuring node instance
2019-08-10 16:22:15.544  CFY <gcp> [vm-database_g0zbrf.configure] Sending task 'cloudify_gcp.compute.instance.create'
2019-08-10 16:22:17.895  LOG <gcp> [vm-database_g0zbrf.configure] INFO: The script is 
2019-08-10 16:22:18.617  LOG <gcp> [vm-database_g0zbrf.configure] INFO: Adding bucket to metadata
2019-08-10 16:22:18.619  LOG <gcp> [vm-database_g0zbrf.configure] INFO: Adding sshKeys to metadata
2019-08-10 16:22:21.652  CFY <gcp> [vm-database_g0zbrf.configure] Task rescheduled 'cloudify_gcp.compute.instance.create' -> Operation started
Traceback (most recent call last):
  File "/opt/mgmtworker/env/lib/python2.7/site-packages/cloudify/dispatch.py", line 813, in main
    payload = handler.handle()
  File "/opt/mgmtworker/env/lib/python2.7/site-packages/cloudify/dispatch.py", line 464, in handle
    raise ctx.operation._operation_retry
OperationRetry: Operation started

2019-08-10 16:22:36.787  CFY <gcp> [vm-database_g0zbrf.configure] Sending task 'cloudify_gcp.compute.instance.create' [retry 1/60]
2019-08-10 16:22:39.777  LOG <gcp> [vm-database_g0zbrf.configure] INFO: The script is 
2019-08-10 16:22:41.283  LOG <gcp> [vm-database_g0zbrf.configure] ERROR: Response with error {u'errors': [{u'message': u"The resource '482761649285-compute@developer.gserviceaccount.com' of type 'serviceAccount' was not found.", u'code': u'EXTERNAL_RESOURCE_NOT_FOUND'}]}
2019-08-10 16:22:41.284  LOG <gcp> [vm-database_g0zbrf.configure] ERROR: Error Message {u'errors': [{u'message': u"The resource '482761649285-compute@developer.gserviceaccount.com' of type 'serviceAccount' was not found.", u'code': u'EXTERNAL_RESOURCE_NOT_FOUND'}]}
2019-08-10 16:22:41.966  CFY <gcp> [vm-database_g0zbrf.configure] Task failed 'cloudify_gcp.compute.instance.create' -> {u'errors': [{u'message': u"The resource '482761649285-compute@developer.gserviceaccount.com' of type 'serviceAccount' was not found.", u'code': u'EXTERNAL_RESOURCE_NOT_FOUND'}]} [retry 1/60]
Traceback (most recent call last):
  File "/opt/mgmtworker/env/lib/python2.7/site-packages/cloudify/dispatch.py", line 813, in main
    payload = handler.handle()
  File "/opt/mgmtworker/env/lib/python2.7/site-packages/cloudify/dispatch.py", line 461, in handle
    result = self._run_operation_func(ctx, kwargs)
  File "/opt/mgmtworker/env/lib/python2.7/site-packages/cloudify/dispatch.py", line 519, in _run_operation_func
    return self.func(*self.args, **kwargs)
  File "/opt/mgmtworker/env/plugins/default_tenant/cloudify-gcp-plugin-1.4.4/lib/python2.7/site-packages/cloudify_gcp/utils.py", line 267, in _decorator
    raise NonRecoverableError(e.message)
NonRecoverableError: {u'errors': [{u'message': u"The resource '482761649285-compute@developer.gserviceaccount.com' of type 'serviceAccount' was not found.", u'code': u'EXTERNAL_RESOURCE_NOT_FOUND'}]}

2019-08-10 16:22:42.406  CFY <gcp> 'install' workflow execution failed: RuntimeError: Workflow failed: Task failed 'cloudify_gcp.compute.instance.create' -> {u'errors': [{u'message': u"The resource '482761649285-compute@developer.gserviceaccount.com' of type 'serviceAccount' was not found.", u'code': u'EXTERNAL_RESOURCE_NOT_FOUND'}]}
Execution of workflow install for deployment gcp failed. [error=Traceback (most recent call last):
  File "/opt/mgmtworker/env/lib/python2.7/site-packages/cloudify/dispatch.py", line 664, in _remote_workflow_child_thread
    workflow_result = self._execute_workflow_function()
  File "/opt/mgmtworker/env/lib/python2.7/site-packages/cloudify/dispatch.py", line 693, in _execute_workflow_function
    result = self.func(*self.args, **self.kwargs)
  File "/opt/mgmtworker/env/lib/python2.7/site-packages/cloudify/plugins/workflows.py", line 31, in install
    node_instances=set(ctx.node_instances))
  File "/opt/mgmtworker/env/lib/python2.7/site-packages/cloudify/plugins/lifecycle.py", line 29, in install_node_instances
    processor.install()
  File "/opt/mgmtworker/env/lib/python2.7/site-packages/cloudify/plugins/lifecycle.py", line 102, in install
    graph.execute()
  File "/opt/mgmtworker/env/lib/python2.7/site-packages/cloudify/workflows/tasks_graph.py", line 237, in execute
    raise self._error
RuntimeError: Workflow failed: Task failed 'cloudify_gcp.compute.instance.create' -> {u'errors': [{u'message': u"The resource '482761649285-compute@developer.gserviceaccount.com' of type 'serviceAccount' was not found.", u'code': u'EXTERNAL_RESOURCE_NOT_FOUND'}]}
]
* Run 'cfy events list cf66ef28-bfe7-4559-8153-5007eddc1a88' to retrieve the execution's events/logs
