Executing workflow `uninstall` on deployment `gcp` [timeout=900 seconds]
2019-08-10 22:28:08.185  CFY <gcp> Starting 'uninstall' workflow execution
2019-08-10 22:28:09.080  CFY <gcp> [firewall_e0oodb] Validating node instance after deletion: nothing to do
2019-08-10 22:28:09.168  CFY <gcp> [config-wordpress_jwga7y->vm-app2_84eyh8|unlink] Sending task 'cloudify_ansible.tasks.ansible_remove_host'
2019-08-10 22:28:10.171  CFY <gcp> [config-database_8wn13l->vm-database_6s8tjx|unlink] Sending task 'cloudify_ansible.tasks.ansible_remove_host'
2019-08-10 22:28:11.126  CFY <gcp> [config-database_8wn13l] Validating node instance after deletion: nothing to do
2019-08-10 22:28:11.610  CFY <gcp> [config-wordpress_jwga7y] Validating node instance after deletion: nothing to do
2019-08-10 22:28:11.894  CFY <gcp> [config-wordpress_jwga7y] Stop: instance already uninitialized
2019-08-10 22:28:12.031  CFY <gcp> [config-database_8wn13l] Stop: instance already uninitialized
2019-08-10 22:28:12.201  CFY <gcp> [firewall_e0oodb] Stop: instance already uninitialized
2019-08-10 22:28:14.260  CFY <gcp> [config-wordpress_jwga7y->vm-app2_84eyh8|unlink] Task failed 'cloudify_ansible.tasks.ansible_remove_host' -> 409: Node instance update conflict [current version=2, update version=1]
Traceback (most recent call last):
  File "/opt/mgmtworker/env/lib/python2.7/site-packages/cloudify/dispatch.py", line 813, in main
    payload = handler.handle()
  File "/opt/mgmtworker/env/lib/python2.7/site-packages/cloudify/dispatch.py", line 461, in handle
    result = self._run_operation_func(ctx, kwargs)
  File "/opt/mgmtworker/env/lib/python2.7/site-packages/cloudify/dispatch.py", line 524, in _run_operation_func
    ctx.source.instance.update()
  File "/opt/mgmtworker/env/lib/python2.7/site-packages/cloudify/context.py", line 414, in update
    self._endpoint.update_node_instance(self._node_instance)
  File "/opt/mgmtworker/env/lib/python2.7/site-packages/cloudify/endpoint.py", line 177, in update_node_instance
    return manager.update_node_instance(node_instance)
  File "/opt/mgmtworker/env/lib/python2.7/site-packages/cloudify/manager.py", line 389, in update_node_instance
    version=node_instance.version)
  File "/opt/mgmtworker/env/lib/python2.7/site-packages/cloudify_rest_client/node_instances.py", line 141, in update
    response = self.api.patch(uri, data=data)
  File "/opt/mgmtworker/env/lib/python2.7/site-packages/cloudify_rest_client/client.py", line 311, in patch
    timeout=timeout)
  File "/opt/mgmtworker/env/lib/python2.7/site-packages/cloudify/cluster.py", line 57, in do_request
    **kwargs)
  File "/opt/mgmtworker/env/lib/python2.7/site-packages/cloudify_rest_client/client.py", line 257, in do_request
    verify=self.get_request_verify(), timeout=timeout)
  File "/opt/mgmtworker/env/lib/python2.7/site-packages/cloudify_rest_client/client.py", line 191, in _do_request
    self._raise_client_error(response, request_url)
  File "/opt/mgmtworker/env/lib/python2.7/site-packages/cloudify_rest_client/client.py", line 144, in _raise_client_error
    response=response)
  File "/opt/mgmtworker/env/lib/python2.7/site-packages/cloudify_rest_client/client.py", line 156, in _prepare_and_raise_exception
    status_code, error_code=error_code, response=response)
CloudifyClientError: 409: Node instance update conflict [current version=2, update version=1]

2019-08-10 22:28:14.335  CFY <gcp> [config-wordpress_jwga7y] Delete: instance already uninitialized
2019-08-10 22:28:14.441  CFY <gcp> [config-database_8wn13l] Delete: instance already uninitialized
2019-08-10 22:28:14.561  CFY <gcp> [config-wordpress_jwga7y->vm-app1_0p3gg4|unlink] Sending task 'cloudify_ansible.tasks.ansible_remove_host'
2019-08-10 22:28:15.614  CFY <gcp> [config-database_8wn13l->vm-database_6s8tjx|unlink] Task succeeded 'cloudify_ansible.tasks.ansible_remove_host'
2019-08-10 22:28:16.123  CFY <gcp> [firewall_e0oodb] Delete: instance already uninitialized
2019-08-10 22:28:16.199  CFY <gcp> [config-database_8wn13l] Deleted node instance
2019-08-10 22:28:16.642  CFY <gcp> [config-wordpress_jwga7y] Deleted node instance
2019-08-10 22:28:17.032  CFY <gcp> [firewall_e0oodb] Deleted node instance
2019-08-10 22:28:18.864  CFY <gcp> [config-wordpress_jwga7y->vm-app1_0p3gg4|unlink] Task succeeded 'cloudify_ansible.tasks.ansible_remove_host'
2019-08-10 22:28:19.275  CFY <gcp> [vm-app2_84eyh8] Validating node instance after deletion: nothing to do
2019-08-10 22:28:19.401  CFY <gcp> [vm-app1_0p3gg4] Validating node instance after deletion: nothing to do
2019-08-10 22:28:19.638  CFY <gcp> [vm-app2_84eyh8] Stop: instance already uninitialized
2019-08-10 22:28:19.701  CFY <gcp> [vm-app1_0p3gg4] Stop: instance already uninitialized
2019-08-10 22:28:20.090  CFY <gcp> [vm-app2_84eyh8] Delete: instance already uninitialized
2019-08-10 22:28:20.147  CFY <gcp> [vm-app1_0p3gg4] Delete: instance already uninitialized
2019-08-10 22:28:20.269  CFY <gcp> [vm-app2_84eyh8] Deleted node instance
2019-08-10 22:28:20.475  CFY <gcp> [vm-app1_0p3gg4] Deleted node instance
2019-08-10 22:28:20.812  CFY <gcp> [vm-database_6s8tjx] Validating node instance after deletion: nothing to do
2019-08-10 22:28:21.112  CFY <gcp> [vm-database_6s8tjx] Stop: instance already uninitialized
2019-08-10 22:28:21.621  CFY <gcp> [vm-database_6s8tjx] Delete: instance already uninitialized
2019-08-10 22:28:21.856  CFY <gcp> [vm-database_6s8tjx] Deleted node instance
2019-08-10 22:28:22.339  CFY <gcp> [subnet_xq30nh] Validating node instance after deletion: nothing to do
2019-08-10 22:28:22.541  CFY <gcp> [subnet_xq30nh] Stop: instance already uninitialized
2019-08-10 22:28:23.048  CFY <gcp> [subnet_xq30nh] Delete: instance already uninitialized
2019-08-10 22:28:23.147  CFY <gcp> [subnet_xq30nh] Deleted node instance
2019-08-10 22:28:23.890  CFY <gcp> [network_2zl0vd] Stopping node instance
2019-08-10 22:28:24.190  CFY <gcp> [network_2zl0vd] Validating node instance after deletion: nothing to do
2019-08-10 22:28:24.389  CFY <gcp> [network_2zl0vd] Stopped node instance: nothing to do
2019-08-10 22:28:24.815  CFY <gcp> [network_2zl0vd] Unlinking relationships
2019-08-10 22:28:25.213  CFY <gcp> [network_2zl0vd] Relationships unlinked
2019-08-10 22:28:25.495  CFY <gcp> [network_2zl0vd] Deleting node instance
2019-08-10 22:28:25.657  CFY <gcp> [network_2zl0vd.delete] Sending task 'cloudify_gcp.compute.network.delete'
2019-08-10 22:28:27.765  LOG <gcp> [network_2zl0vd.delete] INFO: Delete network network-2zl0vd
2019-08-10 22:28:29.540  LOG <gcp> [network_2zl0vd.delete] ERROR: Error traceback Traceback (most recent call last):
  File "/opt/mgmtworker/env/plugins/default_tenant/cloudify-gcp-plugin-1.4.4/lib/python2.7/site-packages/cloudify_gcp/utils.py", line 262, in _decorator
    return func(*args, **kwargs)
  File "/opt/mgmtworker/env/plugins/default_tenant/cloudify-gcp-plugin-1.4.4/lib/python2.7/site-packages/cloudify_gcp/compute/network.py", line 215, in delete
    utils.delete_if_not_external(network)
  File "/opt/mgmtworker/env/plugins/default_tenant/cloudify-gcp-plugin-1.4.4/lib/python2.7/site-packages/cloudify_gcp/utils.py", line 175, in delete_if_not_external
    return resource.delete()
  File "/opt/mgmtworker/env/plugins/default_tenant/cloudify-gcp-plugin-1.4.4/lib/python2.7/site-packages/cloudify_gcp/utils.py", line 233, in wrapper
    response = func(self, *args, **kwargs)
  File "/opt/mgmtworker/env/plugins/default_tenant/cloudify-gcp-plugin-1.4.4/lib/python2.7/site-packages/cloudify_gcp/gcp.py", line 34, in _decorator
    response = func(self, *args, **kwargs)
  File "/opt/mgmtworker/env/plugins/default_tenant/cloudify-gcp-plugin-1.4.4/lib/python2.7/site-packages/cloudify_gcp/compute/network.py", line 80, in delete
    network=self.name).execute()
  File "/opt/mgmtworker/env/plugins/default_tenant/cloudify-gcp-plugin-1.4.4/lib/python2.7/site-packages/oauth2client/util.py", line 137, in positional_wrapper
    return wrapped(*args, **kwargs)
  File "/opt/mgmtworker/env/plugins/default_tenant/cloudify-gcp-plugin-1.4.4/lib/python2.7/site-packages/googleapiclient/http.py", line 832, in execute
    raise HttpError(resp, content, uri=self.uri)
HttpError: <HttpError 404 when requesting https://www.googleapis.com/compute/v1/projects/node2faas-248113/global/networks/network-2zl0vd?alt=json returned "The resource 'projects/node2faas-248113/global/networks/network-2zl0vd' was not found">
 with message <HttpError 404 when requesting https://www.googleapis.com/compute/v1/projects/node2faas-248113/global/networks/network-2zl0vd?alt=json returned "The resource 'projects/node2faas-248113/global/networks/network-2zl0vd' was not found">
2019-08-10 22:28:29.541  LOG <gcp> [network_2zl0vd.delete] ERROR: Error Message 
2019-08-10 22:28:30.005  CFY <gcp> [network_2zl0vd.delete] Task failed 'cloudify_gcp.compute.network.delete'
Traceback (most recent call last):
  File "/opt/mgmtworker/env/lib/python2.7/site-packages/cloudify/dispatch.py", line 813, in main
    payload = handler.handle()
  File "/opt/mgmtworker/env/lib/python2.7/site-packages/cloudify/dispatch.py", line 461, in handle
    result = self._run_operation_func(ctx, kwargs)
  File "/opt/mgmtworker/env/lib/python2.7/site-packages/cloudify/dispatch.py", line 519, in _run_operation_func
    return self.func(*self.args, **kwargs)
  File "/opt/mgmtworker/env/plugins/default_tenant/cloudify-gcp-plugin-1.4.4/lib/python2.7/site-packages/cloudify_gcp/utils.py", line 277, in _decorator
    raise NonRecoverableError(error.message)
NonRecoverableError

2019-08-10 22:28:30.053  CFY <gcp> [network_2zl0vd] Deleted node instance
2019-08-10 22:28:30.832  CFY <gcp> 'uninstall' workflow execution succeeded
Finished executing workflow uninstall on deployment gcp
* Run 'cfy events list 14874592-daea-4438-a492-823ebb044f05' to retrieve the execution's events/logs
Trying to delete deployment gcp...
Deployment deleted
Deleting blueprint cloudify-wordpress-blueprint-gcp...
Blueprint deleted
